<?xml version="1.0" ?>
<!-- =================================================================================== -->
<!-- |    This document was autogenerated by xacro from robotino.urdf.xacro            | -->
<!-- |    EDITING THIS FILE BY HAND IS NOT RECOMMENDED                                 | -->
<!-- =================================================================================== -->
<robot name="robot" xmlns:xacro="http://www.ros.org/wiki/xacro">
  <!-- ****************** -->
  <!-- ***** COMMON ***** -->
  <!-- ****************** -->
  <!-- hokuyo mount positions | relative to base_link -->
  <!-- pan_tilt mount positions | handeye calibration | relative to base_link -->
  <!--property name="pan_tilt_x" value="0.310911"/>
  <property name="pan_tilt_y" value="0.0177173"/>
  <property name="pan_tilt_z" value="0.683637"/>
  <property name="pan_tilt_roll" value="3.0864"/>
  <property name="pan_tilt_pitch" value="3.08658"/>
  <property name="pan_tilt_yaw" value="3.13856"/-->
  <!-- kinect mount positions | handeye calibration | relative to pan_tilt_link -->
  <!--property name="kinect_x" value="0.0162762"/>
  <property name="kinect_y" value="0.0736591"/>
  <property name="kinect_z" value="-0.0649505"/>
  <property name="kinect_roll" value="-1.53"/>
  <property name="kinect_pitch" value="-0.0315698"/>
  <property name="kinect_yaw" value="0.0239961"/-->
  <!-- pan_tilt mount positions | handeye calibration | relative to base_link -->
  <!-- kinect mount positions | handeye calibration | relative to pan_tilt_link -->
  <!-- arm mount positions | handeye calibration | relative to base_link -->
  <!-- arm calibration-->
  <!-- WHEEL -->
  <!-- Wheel transmission   -->
  <!--GAZEBO PLUGIN-->
  <!-- GAZEBO OPENNI PLUGIN -->
  <joint name="origin_joint" type="prismatic">
    <parent link="origin"/>
    <child link="base_link"/>
    <origin rpy="0 0 0" xyz="0 0 0"/>
    <axis xyz="1 0 0"/>
    <limit effort="190" lower="-10" upper="10" velocity="30"/>
  </joint>
  <link name="base_link">
    <inertial>
      <mass value="10"/>
      <origin xyz="0 0 0"/>
      <inertia ixx="75.0" ixy="0.0" ixz="0.0" iyy="75.0" iyz="0.0" izz="75.0"/>
    </inertial>
  </link>
  <joint name="base_jointx" type="prismatic">
    <!--      <parent link="${name}_link"/>-->
    <parent link="origin"/>
    <child link="base_linkx"/>
    <origin rpy="0 0 0" xyz="0 0 0"/>
    <axis xyz="1 0 0"/>
    <limit effort="190" lower="-10" upper="10" velocity="30"/>
  </joint>
  <link name="base_linkx">
    <inertial>
      <mass value="10"/>
      <origin xyz="0 0 0"/>
      <inertia ixx="75.0" ixy="0.0" ixz="0.0" iyy="75.0" iyz="0.0" izz="75.0"/>
    </inertial>
  </link>
  <joint name="base_jointy" type="prismatic">
    <parent link="base_linkx"/>
    <child link="base_linky"/>
    <origin rpy="0 0 0" xyz="0 0 0"/>
    <axis xyz="0 1 0"/>
    <limit effort="190" lower="-10" upper="10" velocity="30"/>
  </joint>
  <link name="base_linky">
    <inertial>
      <mass value="10"/>
      <origin xyz="0 0 0"/>
      <inertia ixx="75.0" ixy="0.0" ixz="0.0" iyy="75.0" iyz="0.0" izz="75.0"/>
    </inertial>
  </link>
  <joint name="base_jointz" type="revolute">
    <parent link="base_linky"/>
    <child link="base_linkz"/>
    <origin rpy="0 0 0" xyz="0 0 0"/>
    <axis xyz="0 0 1"/>
    <limit effort="190" lower="-3.14" upper="3.14" velocity="30"/>
  </joint>
  <link name="base_linkz">
    <inertial>
      <mass value="10"/>
      <origin xyz="0 0 0"/>
      <inertia ixx="75.0" ixy="0.0" ixz="0.0" iyy="75.0" iyz="0.0" izz="75.0"/>
    </inertial>
  </link>
  <joint name="base_body_joint" type="fixed">
    <parent link="base_linkz"/>
    <child link="base_body_link"/>
    <origin rpy="0 0 0" xyz="0 0 0"/>
  </joint>
  <link name="base_body_link">
    <inertial>
      <mass value="10"/>
      <origin xyz="0 0 0"/>
      <inertia ixx="75.0" ixy="0.0" ixz="0.0" iyy="75.0" iyz="0.0" izz="75.0"/>
    </inertial>
    <visual>
      <origin rpy="0 0 0" xyz="0.01 0 0"/>
      <geometry>
        <mesh filename="package://robotino_description/meshes/RobotinoBody.dae"/>
      </geometry>
    </visual>
    <collision>
      <origin rpy="0 0 0" xyz="0.01 0 0"/>
      <geometry>
        <mesh filename="package://robotino_description/meshes/RobotinoBody.stl"/>
      </geometry>
    </collision>
  </link>
  <gazebo reference="base_link">
    <material>Gazebo/Grey</material>
    <gravity>true</gravity>
    <self_collide>false</self_collide>
    <sensor name="base_contact_sensor" type="contact">
      <always_on>true</always_on>
      <update_rate>100.0</update_rate>
      <contact>
        <collision>base_link_collision</collision>
        <topic>base_bumper</topic>
      </contact>
      <plugin filename="libgazebo_ros_bumper.so" name="base_gazebo_ros_bumper_controller">
        <frameName>world</frameName>
        <bumperTopicName>base_bumper</bumperTopicName>
      </plugin>
    </sensor>
  </gazebo>
  <joint name="wheel0_joint" type="continuous">
    <parent link="base_linkz"/>
    <child link="wheel0_link"/>
    <origin rpy="0 0 1.04719666667" xyz="0.095 0.14 0.02"/>
    <axis xyz="-1 0 0"/>
  </joint>
  <link name="wheel0_link">
    <inertial>
      <mass value="0.4"/>
      <origin xyz="0 0 0"/>
      <inertia ixx="0.012411765597" ixy="-0.000711733678" ixz="0.00050272983" iyy="0.015218160428" iyz="-0.000004273467" izz="0.011763977943"/>
    </inertial>
    <visual>
      <origin rpy="0 0 0" xyz="0 0 0"/>
      <geometry>
        <!--cylinder length="0.04" radius="0.04"/-->
        <mesh filename="package://robotino_description/meshes/RobotinoWheel.dae" scale="0.01 0.01 0.01"/>
      </geometry>
    </visual>
    <collision>
      <origin rpy="0 1.570795 0" xyz="0 0 0"/>
      <geometry>
        <!--mesh filename="package://robotino_description/meshes/RobotinoWheel.dae" scale="${M_SCALE} ${M_SCALE} ${M_SCALE}"/-->
        <cylinder length="0.04" radius="0.04"/>
      </geometry>
    </collision>
  </link>
  <transmission name="wheel0_trans">
    <type>transmission_interface/SimpleTransmission</type>
    <joint name="wheel0_joint">
      <hardwareInterface>VelocityJointInterface</hardwareInterface>
    </joint>
    <actuator name="wheel0_motor">
      <hardwareInterface>VelocityJointInterface</hardwareInterface>
      <mechanicalReduction>79.2380952381</mechanicalReduction>
    </actuator>
  </transmission>
  <gravity>true</gravity>
  <self_collide>false</self_collide>
  <!--gazebo reference="${name}_link">
      <mu1 value="100.0" /> 
      <mu2 value="100.0" /> 
      <kp  value="1000000.0" />
      <kd  value="1.0" />
      <fdir1>0 1 0</fdir1>
      <maxContacts>1</maxContacts>
    </gazebo-->
  <joint name="wheel1_joint" type="continuous">
    <parent link="base_linkz"/>
    <child link="wheel1_link"/>
    <origin rpy="0 0 0" xyz="-0.16 0 0.02"/>
    <axis xyz="1 0 0"/>
  </joint>
  <link name="wheel1_link">
    <inertial>
      <mass value="0.4"/>
      <origin xyz="0 0 0"/>
      <inertia ixx="0.012411765597" ixy="-0.000711733678" ixz="0.00050272983" iyy="0.015218160428" iyz="-0.000004273467" izz="0.011763977943"/>
    </inertial>
    <visual>
      <origin rpy="0 0 0" xyz="0 0 0"/>
      <geometry>
        <!--cylinder length="0.04" radius="0.04"/-->
        <mesh filename="package://robotino_description/meshes/RobotinoWheel.dae" scale="0.01 0.01 0.01"/>
      </geometry>
    </visual>
    <collision>
      <origin rpy="0 1.570795 0" xyz="0 0 0"/>
      <geometry>
        <!--mesh filename="package://robotino_description/meshes/RobotinoWheel.dae" scale="${M_SCALE} ${M_SCALE} ${M_SCALE}"/-->
        <cylinder length="0.04" radius="0.04"/>
      </geometry>
    </collision>
  </link>
  <transmission name="wheel1_trans">
    <type>transmission_interface/SimpleTransmission</type>
    <joint name="wheel1_joint">
      <hardwareInterface>VelocityJointInterface</hardwareInterface>
    </joint>
    <actuator name="wheel1_motor">
      <hardwareInterface>VelocityJointInterface</hardwareInterface>
      <mechanicalReduction>79.2380952381</mechanicalReduction>
    </actuator>
  </transmission>
  <gravity>true</gravity>
  <self_collide>false</self_collide>
  <!--gazebo reference="${name}_link">
      <mu1 value="100.0" /> 
      <mu2 value="100.0" /> 
      <kp  value="1000000.0" />
      <kd  value="1.0" />
      <fdir1>0 1 0</fdir1>
      <maxContacts>1</maxContacts>
    </gazebo-->
  <joint name="wheel2_joint" type="continuous">
    <parent link="base_linkz"/>
    <child link="wheel2_link"/>
    <origin rpy="0 0 -1.04719666667" xyz="0.105 -0.15 0.02"/>
    <axis xyz="-1 0 0"/>
  </joint>
  <link name="wheel2_link">
    <inertial>
      <mass value="0.4"/>
      <origin xyz="0 0 0"/>
      <inertia ixx="0.012411765597" ixy="-0.000711733678" ixz="0.00050272983" iyy="0.015218160428" iyz="-0.000004273467" izz="0.011763977943"/>
    </inertial>
    <visual>
      <origin rpy="0 0 0" xyz="0 0 0"/>
      <geometry>
        <!--cylinder length="0.04" radius="0.04"/-->
        <mesh filename="package://robotino_description/meshes/RobotinoWheel.dae" scale="0.01 0.01 0.01"/>
      </geometry>
    </visual>
    <collision>
      <origin rpy="0 1.570795 0" xyz="0 0 0"/>
      <geometry>
        <!--mesh filename="package://robotino_description/meshes/RobotinoWheel.dae" scale="${M_SCALE} ${M_SCALE} ${M_SCALE}"/-->
        <cylinder length="0.04" radius="0.04"/>
      </geometry>
    </collision>
  </link>
  <transmission name="wheel2_trans">
    <type>transmission_interface/SimpleTransmission</type>
    <joint name="wheel2_joint">
      <hardwareInterface>VelocityJointInterface</hardwareInterface>
    </joint>
    <actuator name="wheel2_motor">
      <hardwareInterface>VelocityJointInterface</hardwareInterface>
      <mechanicalReduction>79.2380952381</mechanicalReduction>
    </actuator>
  </transmission>
  <gravity>true</gravity>
  <self_collide>false</self_collide>
  <!--gazebo reference="${name}_link">
      <mu1 value="100.0" /> 
      <mu2 value="100.0" /> 
      <kp  value="1000000.0" />
      <kd  value="1.0" />
      <fdir1>0 1 0</fdir1>
      <maxContacts>1</maxContacts>
    </gazebo-->
  <link name="origin">
    <inertial>
      <mass value="10"/>
      <origin xyz="0 0 0"/>
      <inertia ixx="75.0" ixy="0.0" ixz="0.0" iyy="75.0" iyz="0.0" izz="75.0"/>
    </inertial>
  </link>
  <gazebo>
    <plugin filename="libhwi_switch_gazebo_ros_control.so" name="ros_control">
      <robotNamespace>base_controller</robotNamespace>
      <filterJointsParam>joint_names</filterJointsParam>
    </plugin>
  </gazebo>
  <joint name="hokuyo_joint" type="fixed">
    <origin rpy="0.0 0.0 0.0" xyz="0.208610627 0.0 0.095"/>
    <parent link="base_link"/>
    <child link="hokuyo_link"/>
  </joint>
  <link name="hokuyo_link">
    <inertial>
      <mass value="0.00001"/>
      <origin xyz="0 0 0"/>
      <inertia ixx="1.0" ixy="0.0" ixz="0.0" iyy="1.0" iyz="0.0" izz="1.0"/>
    </inertial>
    <visual>
      <origin rpy="0 0 1.570795" xyz="0 0 -0.05"/>
      <geometry>
        <mesh filename="package://robotino_description/meshes/hokuyo.dae" scale="0.01 0.01 0.01"/>
      </geometry>
    </visual>
    <collision>
      <origin rpy="0 0 0" xyz="0 0 0.035"/>
      <geometry>
        <cylinder length="0.07" radius="0.02"/>
      </geometry>
    </collision>
  </link>
  <!-- gazebo extensions -->
  <gazebo reference="hokuyo_link">
    <sensor name="hokuyo" type="ray">
      <always_on>true</always_on>
      <update_rate>10</update_rate>
      <pose>0 0 0 0 0 0</pose>
      <visualize>false</visualize>
      <ray>
        <scan>
          <horizontal>
            <samples>512</samples>
            <resolution>1.0</resolution>
            <min_angle>-1.570796</min_angle>
            <max_angle>1.570796</max_angle>
          </horizontal>
        </scan>
        <range>
          <min>0.05</min>
          <max>6.0</max>
          <resolution>0.01</resolution>
        </range>
        <noise>
          <type>gaussian</type>
          <mean>0.0</mean>
          <stddev>0.005</stddev>
        </noise>
      </ray>
      <plugin filename="libgazebo_ros_laser.so" name="gazebo_ros_hokuyo_controller">
        <topicName>scan</topicName>
        <frameName>hokuyo_link</frameName>
      </plugin>
    </sensor>
    <material>Gazebo/White</material>
  </gazebo>
  <joint name="arm_base_joint" type="fixed">
    <parent link="base_linkz"/>
    <child link="arm_base_link"/>
    <axis xyz="0 0 1"/>
    <origin rpy="0.0 0.0 -1" xyz="0.0 -0.01591 0.32"/>
  </joint>
  <link name="arm_base_link">
    <inertial>
      <mass value="0.01"/>
      <origin xyz="0 0 0"/>
      <inertia ixx="0.001" ixy="0.0" ixz="0.0" iyy="0.001" iyz="0.0" izz="0.001"/>
    </inertial>
    <visual>
      <geometry>
        <mesh filename="package://robotino_description/meshes/arm/link0.stl"/>
      </geometry>
      <material name="white">
        <color rgba="1 1 1 1"/>
      </material>
      <origin rpy="0 0 0" xyz="0 0 0."/>
    </visual>
    <collision>
      <origin rpy="0 0 0" xyz="0 0 0."/>
      <geometry>
        <mesh filename="package://robotino_description/meshes/arm/link0_collision.stl"/>
      </geometry>
    </collision>
  </link>
  <joint name="arm_joint1" type="revolute">
    <parent link="arm_base_link"/>
    <child link="arm_link1"/>
    <origin rpy="0 0 0" xyz="0.0 0.0 0.0"/>
    <axis xyz="0 1 0"/>
    <limit effort="190" lower="-1.9" upper="1.9" velocity="30"/>
  </joint>
  <link name="arm_link1">
    <inertial>
      <mass value="0.01"/>
      <origin xyz="0 0 0"/>
      <inertia ixx="0.001" ixy="0.0" ixz="0.0" iyy="0.001" iyz="0.0" izz="0.001"/>
    </inertial>
    <visual>
      <geometry>
        <mesh filename="package://robotino_description/meshes/arm/link1.stl"/>
      </geometry>
      <material name="white"/>
      <origin rpy="0 0 0" xyz="0 0 0"/>
    </visual>
    <collision>
      <origin rpy="0 0 0" xyz="0 0 0"/>
      <geometry>
        <mesh filename="package://robotino_description/meshes/arm/link1_collision.stl"/>
      </geometry>
    </collision>
  </link>
  <gazebo reference="arm_link1">
    <material>Gazebo/White</material>
  </gazebo>
  <joint name="arm_joint2" type="revolute">
    <parent link="arm_link1"/>
    <child link="arm_motor2"/>
    <origin rpy="0 0 0" xyz="0.0 0.0 0.25"/>
    <axis xyz="0 1 0"/>
    <limit effort="190" lower="-1.9" upper="1.9" velocity="30"/>
  </joint>
  <link name="arm_motor2">
    <inertial>
      <mass value="0.01"/>
      <origin xyz="0 0 0"/>
      <inertia ixx="0.001" ixy="0.0" ixz="0.0" iyy="0.001" iyz="0.0" izz="0.001"/>
    </inertial>
    <visual>
      <geometry>
        <box size="0 0 0"/>
      </geometry>
      <material name="white"/>
      <origin rpy="0 0 0" xyz="0 0.0625 0."/>
    </visual>
  </link>
  <joint name="fixed_motor2_link2" type="fixed">
    <parent link="arm_motor2"/>
    <child link="arm_link2"/>
    <origin rpy="0 0 0" xyz="0.0 0.098 0.027"/>
  </joint>
  <link name="arm_link2">
    <inertial>
      <mass value="0.01"/>
      <origin xyz="0 0 0"/>
      <inertia ixx="0.001" ixy="0.0" ixz="0.0" iyy="0.001" iyz="0.0" izz="0.001"/>
    </inertial>
    <visual>
      <geometry>
        <mesh filename="package://robotino_description/meshes/arm/link2.stl"/>
      </geometry>
      <material name="white"/>
      <origin rpy="0 0 0" xyz="0 0 0"/>
    </visual>
    <collision>
      <origin rpy="0 0 0" xyz="0 0 0"/>
      <geometry>
        <mesh filename="package://robotino_description/meshes/arm/link2_collision.stl"/>
      </geometry>
    </collision>
  </link>
  <gazebo reference="arm_link2">
    <material>Gazebo/White</material>
  </gazebo>
  <joint name="arm_joint3" type="revolute">
    <parent link="arm_link2"/>
    <child link="arm_link3"/>
    <origin rpy="0 0 0" xyz="0.0 0.0 0.158"/>
    <axis xyz="0 0 1"/>
    <limit effort="190" lower="-1.7" upper="1.7" velocity="30"/>
  </joint>
  <link name="arm_link3">
    <inertial>
      <mass value="0.01"/>
      <origin xyz="0 0 0"/>
      <inertia ixx="0.001" ixy="0.0" ixz="0.0" iyy="0.001" iyz="0.0" izz="0.001"/>
    </inertial>
    <visual>
      <geometry>
        <mesh filename="package://robotino_description/meshes/arm/link3.stl"/>
      </geometry>
      <material name="white"/>
      <origin rpy="0 0 0" xyz="0 0 0"/>
    </visual>
    <collision>
      <origin rpy="0 0 0" xyz="0 0 0"/>
      <geometry>
        <mesh filename="package://robotino_description/meshes/arm/link3_collision.stl"/>
      </geometry>
    </collision>
  </link>
  <gazebo reference="arm_link3">
    <material>Gazebo/White</material>
  </gazebo>
  <joint name="arm_joint4" type="revolute">
    <parent link="arm_link3"/>
    <child link="arm_link4"/>
    <origin rpy="0 0 0" xyz="0.0 -0.057 0.065"/>
    <axis xyz="0 1 0"/>
    <limit effort="160" lower="-1.7" upper="1.7" velocity="30"/>
  </joint>
  <link name="arm_link4">
    <inertial>
      <mass value="0.01"/>
      <origin xyz="0 0 0"/>
      <inertia ixx="0.001" ixy="0.0" ixz="0.0" iyy="0.001" iyz="0.0" izz="0.001"/>
    </inertial>
    <visual>
      <geometry>
        <mesh filename="package://robotino_description/meshes/arm/link4.stl"/>
      </geometry>
      <material name="white"/>
      <origin rpy="0 0 0" xyz="0 0 0"/>
    </visual>
    <collision>
      <origin rpy="0 0 0" xyz="0 0 0"/>
      <geometry>
        <mesh filename="package://robotino_description/meshes/arm/link4_collision.stl"/>
      </geometry>
    </collision>
  </link>
  <gazebo reference="arm_link4">
    <material>Gazebo/White</material>
  </gazebo>
  <joint name="arm_joint5" type="revolute">
    <parent link="arm_link4"/>
    <child link="arm_link5"/>
    <origin rpy="0 0 0" xyz="0.0 -0.027 0.035"/>
    <axis xyz="0 0 1"/>
    <limit effort="160" lower="-1.7" upper="1.7" velocity="30"/>
  </joint>
  <link name="arm_link5">
    <inertial>
      <mass value="0.01"/>
      <origin xyz="0 0 0"/>
      <inertia ixx="0.001" ixy="0.0" ixz="0.0" iyy="0.001" iyz="0.0" izz="0.001"/>
    </inertial>
  </link>
  <gazebo reference="arm_link5">
    <material>Gazebo/White</material>
  </gazebo>
  <transmission name="arm_1_trans">
    <type>transmission_interface/SimpleTransmission</type>
    <joint name="arm_joint1">
      <hardwareInterface>PositionJointInterface</hardwareInterface>
    </joint>
    <actuator name="arm_1_motor">
      <mechanicalReduction>1</mechanicalReduction>
    </actuator>
  </transmission>
  <transmission name="arm_2_trans">
    <type>transmission_interface/SimpleTransmission</type>
    <joint name="arm_joint2">
      <hardwareInterface>PositionJointInterface</hardwareInterface>
    </joint>
    <actuator name="arm_2_motor">
      <mechanicalReduction>1</mechanicalReduction>
    </actuator>
  </transmission>
  <transmission name="arm_3_trans">
    <type>transmission_interface/SimpleTransmission</type>
    <joint name="arm_joint3">
      <hardwareInterface>PositionJointInterface</hardwareInterface>
    </joint>
    <actuator name="arm_3_motor">
      <mechanicalReduction>1</mechanicalReduction>
    </actuator>
  </transmission>
  <transmission name="arm_4_trans">
    <type>transmission_interface/SimpleTransmission</type>
    <joint name="arm_joint4">
      <hardwareInterface>PositionJointInterface</hardwareInterface>
    </joint>
    <actuator name="arm_4_motor">
      <mechanicalReduction>1</mechanicalReduction>
    </actuator>
  </transmission>
  <transmission name="arm_5_trans">
    <type>transmission_interface/SimpleTransmission</type>
    <joint name="arm_joint5">
      <hardwareInterface>PositionJointInterface</hardwareInterface>
    </joint>
    <actuator name="arm_5_motor">
      <mechanicalReduction>1</mechanicalReduction>
    </actuator>
  </transmission>
  <transmission name="arm_base_trans">
    <type>transmission_interface/SimpleTransmission</type>
    <joint name="arm_base_joint">
      <hardwareInterface>PositionJointInterface</hardwareInterface>
    </joint>
    <actuator name="arm_base_motor">
      <mechanicalReduction>1</mechanicalReduction>
    </actuator>
  </transmission>
  <gazebo>
    <plugin filename="libhwi_switch_gazebo_ros_control.so" name="ros_control">
      <robotNamespace>arm_controller</robotNamespace>
      <filterJointsParam>joint_names</filterJointsParam>
    </plugin>
  </gazebo>
  <joint name="hand_wrist_joint" type="fixed">
    <origin rpy="1.5707963 0 0" xyz="0 0 0"/>
    <parent link="arm_link5"/>
    <child link="hand_wrist_link"/>
  </joint>
  <link name="hand_wrist_link">
    <inertial>
      <mass value="0.01"/>
      <origin xyz="0 0 0"/>
      <inertia ixx="0.001" ixy="0.0" ixz="0.0" iyy="0.001" iyz="0.0" izz="0.001"/>
    </inertial>
    <visual>
      <origin rpy="0 0 0" xyz="0 0 0"/>
      <geometry>
        <mesh filename="package://kclhand_description/meshes/wrist.stl"/>
      </geometry>
      <material name="">
        <color rgba="0.79216 0.81961 0.93333 1"/>
      </material>
    </visual>
    <collision>
      <origin rpy="0 0 0" xyz="0 0 0"/>
      <geometry>
        <mesh filename="package://kclhand_description/meshes/wrist.stl"/>
      </geometry>
    </collision>
  </link>
  <joint name="hand_base_joint" type="fixed">
    <origin rpy="0 0.52 0" xyz="-0.02105 0.1485 0"/>
    <parent link="hand_wrist_link"/>
    <child link="hand_base_link"/>
  </joint>
  <link name="hand_base_link">
    <inertial>
      <mass value="0.01"/>
      <origin xyz="0 0 0"/>
      <inertia ixx="0.001" ixy="0.0" ixz="0.0" iyy="0.001" iyz="0.0" izz="0.001"/>
    </inertial>
    <visual>
      <origin rpy="0 0 0" xyz="0 0 0"/>
      <geometry>
        <mesh filename="package://kclhand_description/meshes/base_link.STL"/>
      </geometry>
      <material name="">
        <color rgba="0.79216 0.81961 0.93333 1"/>
      </material>
    </visual>
    <collision>
      <origin rpy="0 0 0" xyz="0 0 0"/>
      <geometry>
        <mesh filename="package://kclhand_description/meshes/base_link.STL"/>
      </geometry>
    </collision>
  </link>
  <joint name="hand_middle_finger_lower_joint" type="continuous">
    <origin rpy="-0.5236 5.5511E-17 1.5708" xyz="0.035507 0.02 0.0205"/>
    <parent link="hand_base_link"/>
    <child link="hand_middle_finger_lower_link"/>
    <axis xyz="0 0 -1"/>
  </joint>
  <link name="hand_middle_finger_lower_link">
    <inertial>
      <mass value="0.01"/>
      <origin xyz="0 0 0"/>
      <inertia ixx="0.001" ixy="0.0" ixz="0.0" iyy="0.001" iyz="0.0" izz="0.001"/>
    </inertial>
    <visual>
      <origin rpy="0 0 0" xyz="0 0 0"/>
      <geometry>
        <mesh filename="package://kclhand_description/meshes/middle_finger_lower_link.STL"/>
      </geometry>
      <material name="">
        <color rgba="0.79216 0.81961 0.93333 1"/>
      </material>
    </visual>
    <collision>
      <origin rpy="0 0 0" xyz="0 0 0"/>
      <geometry>
        <mesh filename="package://kclhand_description/meshes/middle_finger_lower_link.STL"/>
      </geometry>
    </collision>
  </link>
  <joint name="hand_middle_finger_upper_joint" type="continuous">
    <origin rpy="0 0 0.7854" xyz="0.05 0 0"/>
    <parent link="hand_middle_finger_lower_link"/>
    <child link="hand_middle_finger_upper_link"/>
    <axis xyz="0 0 1"/>
  </joint>
  <link name="hand_middle_finger_upper_link">
    <inertial>
      <mass value="0.01"/>
      <origin xyz="0 0 0"/>
      <inertia ixx="0.001" ixy="0.0" ixz="0.0" iyy="0.001" iyz="0.0" izz="0.001"/>
    </inertial>
    <visual>
      <origin rpy="0 0 0" xyz="0 0 0"/>
      <geometry>
        <mesh filename="package://kclhand_description/meshes/middle_finger_upper_link.STL"/>
      </geometry>
      <material name="">
        <color rgba="0.79216 0.81961 0.93333 1"/>
      </material>
    </visual>
    <collision>
      <origin rpy="0 0 0" xyz="0 0 0"/>
      <geometry>
        <mesh filename="package://kclhand_description/meshes/middle_finger_upper_link.STL"/>
      </geometry>
    </collision>
  </link>
  <joint name="hand_left_crank_base_joint" type="continuous">
    <origin rpy="-2.1588 0.44783 -1.8518" xyz="0 0 0"/>
    <parent link="hand_base_link"/>
    <child link="hand_left_crank"/>
    <axis xyz="0 0 1"/>
  </joint>
  <link name="hand_left_crank">
    <inertial>
      <mass value="0.01"/>
      <origin xyz="0 0 0"/>
      <inertia ixx="0.001" ixy="0.0" ixz="0.0" iyy="0.001" iyz="0.0" izz="0.001"/>
    </inertial>
    <visual>
      <origin rpy="0 0 0" xyz="0 0 0"/>
      <geometry>
        <mesh filename="package://kclhand_description/meshes/left_crank.STL"/>
      </geometry>
      <material name="">
        <color rgba="0.79216 0.81961 0.93333 1"/>
      </material>
    </visual>
    <collision>
      <origin rpy="0 0 0" xyz="0 0 0"/>
      <geometry>
        <mesh filename="package://kclhand_description/meshes/left_crank.STL"/>
      </geometry>
    </collision>
  </link>
  <joint name="hand_left_coupler_crank_joint" type="continuous">
    <origin rpy="0.40154 0.63113 0.62376" xyz="0 0 0"/>
    <parent link="hand_left_crank"/>
    <child link="hand_left_coupler"/>
    <axis xyz="0 0 1"/>
  </joint>
  <link name="hand_left_coupler">
    <inertial>
      <mass value="0.01"/>
      <origin xyz="0 0 0"/>
      <inertia ixx="0.001" ixy="0.0" ixz="0.0" iyy="0.001" iyz="0.0" izz="0.001"/>
    </inertial>
    <visual>
      <origin rpy="0 0 0" xyz="0 0 0"/>
      <geometry>
        <mesh filename="package://kclhand_description/meshes/left_coupler.STL"/>
      </geometry>
      <material name="">
        <color rgba="0.79216 0.81961 0.93333 1"/>
      </material>
    </visual>
    <collision>
      <origin rpy="0 0 0" xyz="0 0 0"/>
      <geometry>
        <mesh filename="package://kclhand_description/meshes/left_coupler.STL"/>
      </geometry>
    </collision>
  </link>
  <joint name="hand_left_finger_lower_joint" type="continuous">
    <origin rpy="-1.2217 -7.6328E-17 1.5708" xyz="0.016246 0.021 0.044635"/>
    <parent link="hand_left_coupler"/>
    <child link="hand_left_finger_lower_link"/>
    <axis xyz="0 0 -1"/>
  </joint>
  <link name="hand_left_finger_lower_link">
    <inertial>
      <mass value="0.01"/>
      <origin xyz="0 0 0"/>
      <inertia ixx="0.001" ixy="0.0" ixz="0.0" iyy="0.001" iyz="0.0" izz="0.001"/>
    </inertial>
    <visual>
      <origin rpy="0 0 0" xyz="0 0 0"/>
      <geometry>
        <mesh filename="package://kclhand_description/meshes/left_finger_lower_link.STL"/>
      </geometry>
      <material name="">
        <color rgba="0.79216 0.81961 0.93333 1"/>
      </material>
    </visual>
    <collision>
      <origin rpy="0 0 0" xyz="0 0 0"/>
      <geometry>
        <mesh filename="package://kclhand_description/meshes/left_finger_lower_link.STL"/>
      </geometry>
    </collision>
  </link>
  <joint name="hand_left_finger_upper_joint" type="continuous">
    <origin rpy="-1.5543E-15 7.7716E-16 0.7854" xyz="0.05 0 0"/>
    <parent link="hand_left_finger_lower_link"/>
    <child link="hand_left_finger_upper_link"/>
    <axis xyz="0 0 1"/>
  </joint>
  <link name="hand_left_finger_upper_link">
    <inertial>
      <mass value="0.01"/>
      <origin xyz="0 0 0"/>
      <inertia ixx="0.001" ixy="0.0" ixz="0.0" iyy="0.001" iyz="0.0" izz="0.001"/>
    </inertial>
    <visual>
      <origin rpy="0 0 0" xyz="0 0 0"/>
      <geometry>
        <mesh filename="package://kclhand_description/meshes/left_finger_upper_link.STL"/>
      </geometry>
      <material name="">
        <color rgba="0.79216 0.81961 0.93333 1"/>
      </material>
    </visual>
    <collision>
      <origin rpy="0 0 0" xyz="0 0 0"/>
      <geometry>
        <mesh filename="package://kclhand_description/meshes/left_finger_upper_link.STL"/>
      </geometry>
    </collision>
  </link>
  <joint name="hand_right_crank_base_joint" type="continuous">
    <origin rpy="-5.5511E-17 -2.7756E-17 1.0472" xyz="0 0 0"/>
    <parent link="hand_base_link"/>
    <child link="hand_right_crank"/>
    <axis xyz="0 0 1"/>
  </joint>
  <link name="hand_right_crank">
    <inertial>
      <mass value="0.01"/>
      <origin xyz="0 0 0"/>
      <inertia ixx="0.001" ixy="0.0" ixz="0.0" iyy="0.001" iyz="0.0" izz="0.001"/>
    </inertial>
    <visual>
      <origin rpy="0 0 0" xyz="0 0 0"/>
      <geometry>
        <mesh filename="package://kclhand_description/meshes/right_crank.STL"/>
      </geometry>
      <material name="">
        <color rgba="0.79216 0.81961 0.93333 1"/>
      </material>
    </visual>
    <collision>
      <origin rpy="0 0 0" xyz="0 0 0"/>
      <geometry>
        <mesh filename="package://kclhand_description/meshes/right_crank.STL"/>
      </geometry>
    </collision>
  </link>
  <joint name="hand_right_coupler_crank_joint" type="continuous">
    <origin rpy="0.40154 -0.63113 -0.62376" xyz="0 0 0"/>
    <parent link="hand_right_crank"/>
    <child link="hand_right_coupler"/>
    <axis xyz="0 0 1"/>
  </joint>
  <link name="hand_right_coupler">
    <inertial>
      <mass value="0.01"/>
      <origin xyz="0 0 0"/>
      <inertia ixx="0.001" ixy="0.0" ixz="0.0" iyy="0.001" iyz="0.0" izz="0.001"/>
    </inertial>
    <visual>
      <origin rpy="0 0 0" xyz="0 0 0"/>
      <geometry>
        <mesh filename="package://kclhand_description/meshes/right_coupler.STL"/>
      </geometry>
      <material name="">
        <color rgba="0.79216 0.81961 0.93333 1"/>
      </material>
    </visual>
    <collision>
      <origin rpy="0 0 0" xyz="0 0 0"/>
      <geometry>
        <mesh filename="package://kclhand_description/meshes/right_coupler.STL"/>
      </geometry>
    </collision>
  </link>
  <joint name="hand_right_finger_lower_joint" type="continuous">
    <origin rpy="-1.9199 -2.047E-16 1.5708" xyz="-0.016246 0.021 0.044635"/>
    <parent link="hand_right_coupler"/>
    <child link="hand_right_finger_lower_link"/>
    <axis xyz="0 0 1"/>
  </joint>
  <link name="hand_right_finger_lower_link">
    <inertial>
      <mass value="0.01"/>
      <origin xyz="0 0 0"/>
      <inertia ixx="0.001" ixy="0.0" ixz="0.0" iyy="0.001" iyz="0.0" izz="0.001"/>
    </inertial>
    <visual>
      <origin rpy="0 0 0" xyz="0 0 0"/>
      <geometry>
        <mesh filename="package://kclhand_description/meshes/right_finger_lower_link.STL"/>
      </geometry>
      <material name="">
        <color rgba="0.79216 0.81961 0.93333 1"/>
      </material>
    </visual>
    <collision>
      <origin rpy="0 0 0" xyz="0 0 0"/>
      <geometry>
        <mesh filename="package://kclhand_description/meshes/right_finger_lower_link.STL"/>
      </geometry>
    </collision>
  </link>
  <joint name="hand_right_finger_upper_joint" type="continuous">
    <origin rpy="4.4409E-16 -2.9143E-16 0.7854" xyz="0.05 0 0"/>
    <parent link="hand_right_finger_lower_link"/>
    <child link="hand_right_finger_upper_link"/>
    <axis xyz="0 0 1"/>
  </joint>
  <link name="hand_right_finger_upper_link">
    <inertial>
      <mass value="0.01"/>
      <origin xyz="0 0 0"/>
      <inertia ixx="0.001" ixy="0.0" ixz="0.0" iyy="0.001" iyz="0.0" izz="0.001"/>
    </inertial>
    <visual>
      <origin rpy="0 0 0" xyz="0 0 0"/>
      <geometry>
        <mesh filename="package://kclhand_description/meshes/right_finger_upper_link.STL"/>
      </geometry>
      <material name="">
        <color rgba="0.792156862745098 0.819607843137255 0.933333333333333 1"/>
      </material>
    </visual>
    <collision>
      <origin rpy="0 0 0" xyz="0 0 0"/>
      <geometry>
        <mesh filename="package://kclhand_description/meshes/right_finger_upper_link.STL"/>
      </geometry>
    </collision>
  </link>
  <joint name="hand_cableCanal_joint" type="fixed">
    <origin rpy="0 0 0" xyz="0.07 0.06 0"/>
    <parent link="hand_wrist_link"/>
    <child link="hand_cableCanal_link"/>
  </joint>
  <link name="hand_cableCanal_link">
    <inertial>
      <mass value="0.01"/>
      <origin xyz="0 0 0"/>
      <inertia ixx="0.001" ixy="0.0" ixz="0.0" iyy="0.001" iyz="0.0" izz="0.001"/>
    </inertial>
    <visual>
      <origin rpy="0 0 0" xyz="0 0 0"/>
      <geometry>
        <box size="0.0 0.0 0.0"/>
      </geometry>
      <material name="">
        <color rgba="0.79216 0.81961 0.93333 1"/>
      </material>
    </visual>
    <collision>
      <origin rpy="0 0 0" xyz="0 0 0"/>
      <geometry>
        <mesh filename="package://kclhand_description/meshes/cableCanalCollision.stl"/>
      </geometry>
    </collision>
  </link>
  <transmission name="hand_left_coupler_crank_joint_trans">
    <type>transmission_interface/SimpleTransmission</type>
    <joint name="hand_left_coupler_crank_joint">
      <hardwareInterface>PositionJointInterface</hardwareInterface>
      <!--hardwareInterface>VelocityJointInterface</hardwareInterface-->
    </joint>
    <actuator name="hand_left_coupler_crank_motor">
      <mechanicalReduction>1</mechanicalReduction>
    </actuator>
  </transmission>
  <transmission name="hand_left_crank_base_trans">
    <type>transmission_interface/SimpleTransmission</type>
    <joint name="hand_left_crank_base_joint">
      <hardwareInterface>PositionJointInterface</hardwareInterface>
      <!--hardwareInterface>VelocityJointInterface</hardwareInterface-->
    </joint>
    <actuator name="hand_left_crank_base_motor">
      <mechanicalReduction>1</mechanicalReduction>
    </actuator>
  </transmission>
  <transmission name="hand_left_finger_lower_trans">
    <type>transmission_interface/SimpleTransmission</type>
    <joint name="hand_left_finger_lower_joint">
      <hardwareInterface>PositionJointInterface</hardwareInterface>
      <!--hardwareInterface>VelocityJointInterface</hardwareInterface-->
    </joint>
    <actuator name="hand_left_finger_lower_motor">
      <mechanicalReduction>1</mechanicalReduction>
    </actuator>
  </transmission>
  <transmission name="hand_left_finger_upper_trans">
    <type>transmission_interface/SimpleTransmission</type>
    <joint name="hand_left_finger_upper_joint">
      <hardwareInterface>PositionJointInterface</hardwareInterface>
      <!--hardwareInterface>VelocityJointInterface</hardwareInterface-->
    </joint>
    <actuator name="hand_left_finger_upper_motor">
      <mechanicalReduction>1</mechanicalReduction>
    </actuator>
  </transmission>
  <transmission name="hand_middle_finger_lower_trans">
    <type>transmission_interface/SimpleTransmission</type>
    <joint name="hand_middle_finger_lower_joint">
      <hardwareInterface>PositionJointInterface</hardwareInterface>
      <!--hardwareInterface>VelocityJointInterface</hardwareInterface-->
    </joint>
    <actuator name="hand_middle_finger_lower_motor">
      <mechanicalReduction>1</mechanicalReduction>
    </actuator>
  </transmission>
  <transmission name="hand_middle_finger_upper_trans">
    <type>transmission_interface/SimpleTransmission</type>
    <joint name="hand_middle_finger_upper_joint">
      <hardwareInterface>PositionJointInterface</hardwareInterface>
      <!--hardwareInterface>VelocityJointInterface</hardwareInterface-->
    </joint>
    <actuator name="hand_middle_finger_upper_motor">
      <mechanicalReduction>1</mechanicalReduction>
    </actuator>
  </transmission>
  <transmission name="hand_right_crank_base_trans">
    <type>transmission_interface/SimpleTransmission</type>
    <joint name="hand_right_crank_base_joint">
      <hardwareInterface>PositionJointInterface</hardwareInterface>
      <!--hardwareInterface>VelocityJointInterface</hardwareInterface-->
    </joint>
    <actuator name="hand_right_crank_base_motor">
      <mechanicalReduction>1</mechanicalReduction>
    </actuator>
  </transmission>
  <transmission name="hand_right_coupler_crank_trans">
    <type>transmission_interface/SimpleTransmission</type>
    <joint name="hand_right_coupler_crank_joint">
      <hardwareInterface>PositionJointInterface</hardwareInterface>
      <!--hardwareInterface>VelocityJointInterface</hardwareInterface-->
    </joint>
    <actuator name="hand_right_coupler_crank_motor">
      <mechanicalReduction>1</mechanicalReduction>
    </actuator>
  </transmission>
  <transmission name="hand_right_finger_lower_trans">
    <type>transmission_interface/SimpleTransmission</type>
    <joint name="hand_right_finger_lower_joint">
      <hardwareInterface>PositionJointInterface</hardwareInterface>
      <!--hardwareInterface>VelocityJointInterface</hardwareInterface-->
    </joint>
    <actuator name="hand_right_finger_lower_motor">
      <mechanicalReduction>1</mechanicalReduction>
    </actuator>
  </transmission>
  <transmission name="hand_right_finger_upper_trans">
    <type>transmission_interface/SimpleTransmission</type>
    <joint name="hand_right_finger_upper_joint">
      <hardwareInterface>PositionJointInterface</hardwareInterface>
      <!--hardwareInterface>VelocityJointInterface</hardwareInterface-->
    </joint>
    <actuator name="hand_right_finger_upper_motor">
      <mechanicalReduction>1</mechanicalReduction>
    </actuator>
  </transmission>
  <gazebo reference="hand_base_link">
    <gravity>true</gravity>
    <self_collide>false</self_collide>
  </gazebo>
  <gazebo reference="hand_left_coupler">
    <gravity>true</gravity>
    <self_collide>false</self_collide>
  </gazebo>
  <gazebo reference="hand_left_crank">
    <gravity>true</gravity>
    <self_collide>false</self_collide>
  </gazebo>
  <gazebo reference="hand_left_finger_lower_link">
    <gravity>true</gravity>
    <self_collide>false</self_collide>
  </gazebo>
  <gazebo reference="hand_left_finger_upper_link">
    <gravity>true</gravity>
    <self_collide>false</self_collide>
  </gazebo>
  <gazebo reference="hand_middle_finger_lower_link">
    <gravity>true</gravity>
    <self_collide>false</self_collide>
  </gazebo>
  <gazebo reference="hand_middle_finger_upper_link">
    <gravity>true</gravity>
    <self_collide>false</self_collide>
  </gazebo>
  <gazebo reference="hand_right_coupler">
    <gravity>true</gravity>
    <self_collide>false</self_collide>
  </gazebo>
  <gazebo reference="hand_right_crank">
    <gravity>true</gravity>
    <self_collide>false</self_collide>
  </gazebo>
  <gazebo reference="hand_right_finger_lower_link">
    <gravity>true</gravity>
    <self_collide>false</self_collide>
  </gazebo>
  <gazebo reference="hand_right_finger_upper_link">
    <gravity>true</gravity>
    <self_collide>false</self_collide>
  </gazebo>
  <gazebo>
    <plugin filename="libhwi_switch_gazebo_ros_control.so" name="ros_control">
      <robotNamespace>hand_controller</robotNamespace>
      <filterJointsParam>joint_names</filterJointsParam>
    </plugin>
  </gazebo>
  <joint name="profile_joint" type="fixed">
    <origin rpy="0 0 0" xyz="0 0 0"/>
    <parent link="base_link"/>
    <child link="profile_link"/>
  </joint>
  <link name="profile_link">
    <inertial>
      <mass value="0.00001"/>
      <origin xyz="0 0 0"/>
      <inertia ixx="1.0" ixy="0.0" ixz="0.0" iyy="1.0" iyz="0.0" izz="1.0"/>
    </inertial>
    <visual>
      <origin rpy="0 0 0" xyz="0 0 0"/>
      <geometry>
        <mesh filename="package://robotino_description/meshes/pan_tilt.stl"/>
      </geometry>
      <material name="Black"/>
    </visual>
    <collision>
      <origin rpy="0 0 0" xyz="0 0 0"/>
      <geometry>
        <mesh filename="package://robotino_description/meshes/pan_tilt.stl"/>
      </geometry>
    </collision>
  </link>
  <gazebo reference="profile_link">
    <gravity>true</gravity>
    <self_collide>false</self_collide>
    <material>Gazebo/Black</material>
  </gazebo>
  <joint name="base_pan_joint" type="fixed">
    <origin rpy="0.012045 -0.0565489 0.0113182" xyz="0.257201 0.0587815 0.637117"/>
    <parent link="profile_link"/>
    <child link="base_pan_link"/>
  </joint>
  <link name="base_pan_link">
    <inertial>
      <mass value="0.00001"/>
      <origin xyz="0 0 0"/>
      <inertia ixx="1.0" ixy="0.0" ixz="0.0" iyy="1.0" iyz="0.0" izz="1.0"/>
    </inertial>
    <visual>
      <origin rpy="0 0 0" xyz="0 0 0"/>
      <geometry>
        <box size="0.001 0.001 0.001"/>
      </geometry>
      <material name="Black"/>
    </visual>
    <collision>
      <origin rpy="0 0 0" xyz="0 0 0"/>
      <geometry>
        <box size="0.001 0.001 0.001"/>
      </geometry>
    </collision>
  </link>
  <gazebo reference="base_pan_link">
    <gravity>true</gravity>
    <self_collide>false</self_collide>
    <material>Gazebo/Black</material>
  </gazebo>
  <joint name="pan_joint" type="revolute">
    <origin rpy="0 0 0" xyz="0 0 0"/>
    <parent link="base_pan_link"/>
    <child link="pan_link"/>
    <axis xyz="0 0 1"/>
    <calibration rising="0.1"/>
    <limit effort="100" lower="-1.57" upper="1.57" velocity="1.4"/>
  </joint>
  <link name="pan_link">
    <inertial>
      <mass value="0.00001"/>
      <origin xyz="0 0 0"/>
      <inertia ixx="1.0" ixy="0.0" ixz="0.0" iyy="1.0" iyz="0.0" izz="1.0"/>
    </inertial>
  </link>
  <joint name="tilt_joint" type="revolute">
    <origin rpy="1.57 0 0" xyz="0 0 0"/>
    <parent link="pan_link"/>
    <child link="tilt_link"/>
    <axis xyz="0 0 -1"/>
    <calibration rising="0.1"/>
    <limit effort="100" lower="-1.57" upper="1.57" velocity="1.4"/>
  </joint>
  <link name="tilt_link">
    <inertial>
      <mass value="0.00001"/>
      <origin xyz="0 0 0"/>
      <inertia ixx="1.0" ixy="0.0" ixz="0.0" iyy="1.0" iyz="0.0" izz="1.0"/>
    </inertial>
  </link>
  <transmission name="tilt_trans">
    <type>transmission_interface/SimpleTransmission</type>
    <joint name="tilt_joint">
      <!--hardwareInterface>EffortJointInterface</hardwareInterface>
        <hardwareInterface>VelocityJointInterface</hardwareInterface-->
      <hardwareInterface>PositionJointInterface</hardwareInterface>
    </joint>
    <actuator name="tilt_motor">
      <mechanicalReduction>1</mechanicalReduction>
    </actuator>
  </transmission>
  <transmission name="pan_trans">
    <type>transmission_interface/SimpleTransmission</type>
    <joint name="pan_joint">
      <!--hardwareInterface>EffortJointInterface</hardwareInterface>
        <hardwareInterface>VelocityJointInterface</hardwareInterface-->
      <hardwareInterface>PositionJointInterface</hardwareInterface>
    </joint>
    <actuator name="pan_motor">
      <mechanicalReduction>1</mechanicalReduction>
    </actuator>
  </transmission>
  <gazebo reference="tilt_link">
    <gravity>true</gravity>
    <self_collide>false</self_collide>
  </gazebo>
  <gazebo reference="pan_link">
    <gravity>true</gravity>
    <self_collide>false</self_collide>
  </gazebo>
  <joint name="kinect_joint" type="fixed">
    <origin rpy="1.57297 -3.11833 3.10173" xyz="0.0772857 0.117459 -0.0273189"/>
    <parent link="tilt_link"/>
    <child link="kinect_link"/>
  </joint>
  <link name="kinect_link">
    <inertial>
      <mass value="0.00001"/>
      <origin xyz="0 0 0"/>
      <inertia ixx="1.0" ixy="0.0" ixz="0.0" iyy="1.0" iyz="0.0" izz="1.0"/>
    </inertial>
    <visual>
      <origin rpy="0 0 0" xyz="0 0 0"/>
      <geometry>
        <box size="0.035 0.18 0.02"/>
      </geometry>
      <material name="Grey"/>
    </visual>
    <collision>
      <origin rpy="0 0 0" xyz="0 0 0"/>
      <geometry>
        <box size="0.035  0.18 0.02"/>
      </geometry>
    </collision>
  </link>
  <!-- <joint name="${name}_frame_joint" type="fixed"> -->
  <!--   <origin xyz="0 0 0" rpy="${M_PI/2} -${M_PI/2} 0" />  -->
  <!--   <parent link="${name}_link"/> -->
  <!--   <child link="${name}_frame"/> -->
  <!-- </joint> -->
  <!-- <link name="${name}_frame"/> -->
  <!-- gazebo extensions -->
  <gazebo reference="kinect_link">
    <sensor name="kinect_frame_sensor" type="depth">
      <always_on>true</always_on>
      <update_rate>20.0</update_rate>
      <visualize>true</visualize>
      <camera>
        <horizontal_fov>1.08210322222</horizontal_fov>
        <image>
          <format>R8G8B8</format>
          <width>640</width>
          <height>480</height>
        </image>
        <clip>
          <near>0.1</near>
          <far>100</far>
        </clip>
        <noise>
          <type>gaussian</type>
          <mean>0.0</mean>
          <stddev>0.005</stddev>
        </noise>
      </camera>
      <plugin filename="libgazebo_ros_openni_kinect.so" name="kinect_controller">
        <updateRate>20.0</updateRate>
        <cameraName>kinect</cameraName>
        <frameName>kinect_depth_optical_frame</frameName>
        <imageTopicName>rgb/image_raw</imageTopicName>
        <depthImageTopicName>depth/image_raw</depthImageTopicName>
        <!--pointCloudTopicName>depth_registered/points</pointCloudTopicName-->
        <pointCloudTopicName>depth/points</pointCloudTopicName>
        <cameraInfoTopicName>rgb/camera_info</cameraInfoTopicName>
        <depthImageCameraInfoTopicName>depth_registered/camera_info</depthImageCameraInfoTopicName>
        <pointCloudCutoff>0.5</pointCloudCutoff>
        <baseline>0.2</baseline>
        <hackBaseline>0.0</hackBaseline>
        <distortionK1>0.0</distortionK1>
        <distortionK2>0.0</distortionK2>
        <distortionK3>0.0</distortionK3>
        <distortionT1>0.0</distortionT1>
        <distortionT2>0.0</distortionT2>
        <CxPrime>0.0</CxPrime>
        <Cx>0.0</Cx>
        <Cy>0.0</Cy>
        <focalLength>0.0</focalLength>
      </plugin>
    </sensor>
    <material>Gazebo/Black</material>
  </gazebo>
  <gazebo>
    <plugin filename="libhwi_switch_gazebo_ros_control.so" name="ros_control">
      <robotNamespace>pan_tilt_controller</robotNamespace>
      <filterJointsParam>joint_names</filterJointsParam>
    </plugin>
  </gazebo>
</robot>

