<?xml version="1.0" ?>
<!-- =================================================================================== -->
<!-- |    This document was autogenerated by xacro from robotino_simple.urdf.xacro     | -->
<!-- |    EDITING THIS FILE BY HAND IS NOT RECOMMENDED                                 | -->
<!-- =================================================================================== -->
<robot name="robot" xmlns:xacro="http://www.ros.org/wiki/xacro">
  <!-- ****************** -->
  <!-- ***** COMMON ***** -->
  <!-- ****************** -->
  <!-- camera mount positions | handeye calibration | relative to base_link -->
  <!-- hokuyo mount positions | relative to base_link -->
  <!-- tilt mount positions | handeye calibration | relative to base_link -->
  <!-- arm mount positions | handeye calibration | relative to base_link -->
  <!-- arm calibration-->
  <!-- kinect mount positions | handeye calibration | relative to tilt_link -->
  <!-- anglebracketusb mount positions | handeye calibration | relative to base_link -->
  <!--gazebo>
    <plugin name="gazebo_ros_control" filename="libgazebo_ros_control.so">
      <robotNamespace>/robotino</robotNamespace>
    </plugin>
  </gazebo-->
  <!-- WHEEL -->
  <!-- Wheel transmission   -->
  <!-- COMMAND BRIDGE -->
  <!--GAZEBO PLUGIN-->
  <!-- GAZEBO OPENNI PLUGIN -->
  <!--<link name="${name}_footprint"/>
   
   <joint name="${name}_footprint_joint" type="fixed">
      <origin xyz="0 0 0" rpy="0 0 0" />
      <child link="${name}_link" />
      <parent link="${name}_footprint"/>
   </joint> -->
  <link name="base_link">
    <inertial>
      <mass value="20"/>
      <origin xyz="0 0 0"/>
      <inertia ixx="75.0" ixy="0.0" ixz="0.0" iyy="75.0" iyz="0.0" izz="75.0"/>
    </inertial>
    <visual>
      <origin rpy="0 0 0" xyz="0 0 0.12"/>
      <geometry>
        <cylinder length="0.24" radius="0.23"/>
      </geometry>
    </visual>
    <collision>
      <origin rpy="0 0 0" xyz="0 0 0.12"/>
      <geometry>
        <cylinder length="0.24" radius="0.23"/>
      </geometry>
    </collision>
  </link>
  <gazebo reference="base_link">
    <material>Gazebo/Grey</material>
    <gravity>true</gravity>
    <self_collide>false</self_collide>
    <sensor name="base_contact_sensor" type="contact">
      <always_on>true</always_on>
      <update_rate>100.0</update_rate>
      <contact>
        <collision>base_link_collision</collision>
        <topic>base_bumper</topic>
      </contact>
      <plugin filename="libgazebo_ros_bumper.so" name="base_gazebo_ros_bumper_controller">
        <frameName>world</frameName>
        <bumperTopicName>base_bumper</bumperTopicName>
      </plugin>
    </sensor>
  </gazebo>
  <!--gazebo>
      <plugin name="p3d_base_controller" filename="libgazebo_ros_p3d.so">
        <alwaysOn>true</alwaysOn>
        <updateRate>100.0</updateRate>
        <bodyName>${name}_link</bodyName>
        <topicName>${name}_pose_ground_truth</topicName>
        <frameName>map</frameName>
        <xyzOffsets>25.7 25.7 0</xyzOffsets-->
  <!-- initialize odometry for fake localization-->
  <!--rpyOffsets>0 0 0</rpyOffsets>
        <gaussianNoise>0.01</gaussianNoise>
      </plugin>
      <canonicalBody>${name}_footprint</canonicalBody>
    </gazebo-->
  <!-- position controller -->
  <gazebo>
    <plugin filename="libgazebo_ros_planar_move.so" name="base_controller">
      <commandTopic>cmd_vel</commandTopic>
      <odometryTopic>odom</odometryTopic>
      <odometryFrame>odom</odometryFrame>
      <odometryRate>20.0</odometryRate>
      <robotBaseFrame>base_link</robotBaseFrame>
    </plugin>
  </gazebo>
  <joint name="wheel0_joint" type="continuous">
    <parent link="base_link"/>
    <child link="wheel0_link"/>
    <origin rpy="0 0 1.04719666667" xyz="0.095 0.14 0.02"/>
    <axis xyz="-1 0 0"/>
  </joint>
  <link name="wheel0_link">
    <inertial>
      <mass value="0.4"/>
      <origin xyz="0 0 0"/>
      <inertia ixx="0.012411765597" ixy="-0.000711733678" ixz="0.00050272983" iyy="0.015218160428" iyz="-0.000004273467" izz="0.011763977943"/>
    </inertial>
    <visual>
      <origin rpy="0 0 0" xyz="0 0 0"/>
      <geometry>
        <!--cylinder length="0.04" radius="0.04"/-->
        <mesh filename="package://robotino_description/meshes/RobotinoWheel.dae" scale="0.01 0.01 0.01"/>
      </geometry>
    </visual>
    <collision>
      <origin rpy="0 1.570795 0" xyz="0 0 0"/>
      <geometry>
        <!--mesh filename="package://robotino_description/meshes/RobotinoWheel.dae" scale="${M_SCALE} ${M_SCALE} ${M_SCALE}"/-->
        <cylinder length="0.04" radius="0.04"/>
      </geometry>
    </collision>
  </link>
  <transmission name="wheel0_trans">
    <type>transmission_interface/SimpleTransmission</type>
    <joint name="wheel0_joint">
      <hardwareInterface>VelocityJointInterface</hardwareInterface>
    </joint>
    <actuator name="wheel0_motor">
      <hardwareInterface>VelocityJointInterface</hardwareInterface>
      <mechanicalReduction>79.2380952381</mechanicalReduction>
    </actuator>
  </transmission>
  <gazebo reference="wheel0_link">
    <mu1 value="0.0"/>
    <!-- 100 -->
    <mu2 value="0.0"/>
    <!-- 100 , http://ode-wiki.org/wiki/index.php?title=FAQ-->
    <kp value="1000000.0"/>
    <kd value="1.0"/>
    <!--fdir1>0 1 0</fdir1>
      <maxContacts>1</maxContacts-->
  </gazebo>
  <joint name="wheel1_joint" type="continuous">
    <parent link="base_link"/>
    <child link="wheel1_link"/>
    <origin rpy="0 0 0" xyz="-0.16 0 0.02"/>
    <axis xyz="1 0 0"/>
  </joint>
  <link name="wheel1_link">
    <inertial>
      <mass value="0.4"/>
      <origin xyz="0 0 0"/>
      <inertia ixx="0.012411765597" ixy="-0.000711733678" ixz="0.00050272983" iyy="0.015218160428" iyz="-0.000004273467" izz="0.011763977943"/>
    </inertial>
    <visual>
      <origin rpy="0 0 0" xyz="0 0 0"/>
      <geometry>
        <!--cylinder length="0.04" radius="0.04"/-->
        <mesh filename="package://robotino_description/meshes/RobotinoWheel.dae" scale="0.01 0.01 0.01"/>
      </geometry>
    </visual>
    <collision>
      <origin rpy="0 1.570795 0" xyz="0 0 0"/>
      <geometry>
        <!--mesh filename="package://robotino_description/meshes/RobotinoWheel.dae" scale="${M_SCALE} ${M_SCALE} ${M_SCALE}"/-->
        <cylinder length="0.04" radius="0.04"/>
      </geometry>
    </collision>
  </link>
  <transmission name="wheel1_trans">
    <type>transmission_interface/SimpleTransmission</type>
    <joint name="wheel1_joint">
      <hardwareInterface>VelocityJointInterface</hardwareInterface>
    </joint>
    <actuator name="wheel1_motor">
      <hardwareInterface>VelocityJointInterface</hardwareInterface>
      <mechanicalReduction>79.2380952381</mechanicalReduction>
    </actuator>
  </transmission>
  <gazebo reference="wheel1_link">
    <mu1 value="0.0"/>
    <!-- 100 -->
    <mu2 value="0.0"/>
    <!-- 100 , http://ode-wiki.org/wiki/index.php?title=FAQ-->
    <kp value="1000000.0"/>
    <kd value="1.0"/>
    <!--fdir1>0 1 0</fdir1>
      <maxContacts>1</maxContacts-->
  </gazebo>
  <joint name="wheel2_joint" type="continuous">
    <parent link="base_link"/>
    <child link="wheel2_link"/>
    <origin rpy="0 0 -1.04719666667" xyz="0.105 -0.15 0.02"/>
    <axis xyz="-1 0 0"/>
  </joint>
  <link name="wheel2_link">
    <inertial>
      <mass value="0.4"/>
      <origin xyz="0 0 0"/>
      <inertia ixx="0.012411765597" ixy="-0.000711733678" ixz="0.00050272983" iyy="0.015218160428" iyz="-0.000004273467" izz="0.011763977943"/>
    </inertial>
    <visual>
      <origin rpy="0 0 0" xyz="0 0 0"/>
      <geometry>
        <!--cylinder length="0.04" radius="0.04"/-->
        <mesh filename="package://robotino_description/meshes/RobotinoWheel.dae" scale="0.01 0.01 0.01"/>
      </geometry>
    </visual>
    <collision>
      <origin rpy="0 1.570795 0" xyz="0 0 0"/>
      <geometry>
        <!--mesh filename="package://robotino_description/meshes/RobotinoWheel.dae" scale="${M_SCALE} ${M_SCALE} ${M_SCALE}"/-->
        <cylinder length="0.04" radius="0.04"/>
      </geometry>
    </collision>
  </link>
  <transmission name="wheel2_trans">
    <type>transmission_interface/SimpleTransmission</type>
    <joint name="wheel2_joint">
      <hardwareInterface>VelocityJointInterface</hardwareInterface>
    </joint>
    <actuator name="wheel2_motor">
      <hardwareInterface>VelocityJointInterface</hardwareInterface>
      <mechanicalReduction>79.2380952381</mechanicalReduction>
    </actuator>
  </transmission>
  <gazebo reference="wheel2_link">
    <mu1 value="0.0"/>
    <!-- 100 -->
    <mu2 value="0.0"/>
    <!-- 100 , http://ode-wiki.org/wiki/index.php?title=FAQ-->
    <kp value="1000000.0"/>
    <kd value="1.0"/>
    <!--fdir1>0 1 0</fdir1>
      <maxContacts>1</maxContacts-->
  </gazebo>
  <joint name="command_bridge_joint" type="fixed">
    <origin rpy="0 0 1.570795" xyz="-0.05 0 0.13"/>
    <parent link="base_link"/>
    <child link="command_bridge_link"/>
  </joint>
  <link name="command_bridge_link">
    <inertial>
      <mass value="0.00001"/>
      <origin xyz="0 0 0"/>
      <inertia ixx="1.0" ixy="0.0" ixz="0.0" iyy="1.0" iyz="0.0" izz="1.0"/>
    </inertial>
    <collision>
      <origin rpy="0 0 0" xyz="0 0 0"/>
      <geometry>
        <box size="0.25 0.11 0.16"/>
      </geometry>
    </collision>
  </link>
  <joint name="hokuyo_joint" type="fixed">
    <origin rpy="0.0 0.0 0.0" xyz="0.064 0.0 0.22"/>
    <parent link="base_link"/>
    <child link="hokuyo_link"/>
  </joint>
  <link name="hokuyo_link">
    <inertial>
      <mass value="0.00001"/>
      <origin xyz="0 0 0"/>
      <inertia ixx="1.0" ixy="0.0" ixz="0.0" iyy="1.0" iyz="0.0" izz="1.0"/>
    </inertial>
    <visual>
      <origin rpy="0 0 1.570795" xyz="0 0 -0.05"/>
      <geometry>
        <mesh filename="package://robotino_description/meshes/RobotinoLaserScanner.dae" scale="0.01 0.01 0.01"/>
      </geometry>
    </visual>
    <collision>
      <origin rpy="0 0 0" xyz="0 0 0.035"/>
      <geometry>
        <cylinder length="0.07" radius="0.02"/>
      </geometry>
    </collision>
  </link>
  <!-- gazebo extensions -->
  <gazebo reference="hokuyo_link">
    <sensor name="hokuyo" type="ray">
      <always_on>true</always_on>
      <update_rate>10</update_rate>
      <pose>0 0 0 0 0 0</pose>
      <visualize>false</visualize>
      <ray>
        <scan>
          <horizontal>
            <samples>640</samples>
            <resolution>1.0</resolution>
            <min_angle>-2.2689</min_angle>
            <max_angle>2.2689</max_angle>
          </horizontal>
        </scan>
        <range>
          <min>0.05</min>
          <max>10.0</max>
          <resolution>0.01</resolution>
        </range>
        <noise>
          <type>gaussian</type>
          <mean>0.0</mean>
          <stddev>0.005</stddev>
        </noise>
      </ray>
      <plugin filename="libgazebo_ros_laser.so" name="gazebo_ros_hokuyo_controller">
        <topicName>scan</topicName>
        <frameName>hokuyo_link</frameName>
      </plugin>
    </sensor>
    <material>Gazebo/White</material>
  </gazebo>
  <joint name="fixed_base_link_base" type="fixed">
    <parent link="base_link"/>
    <child link="base"/>
    <origin rpy="0 0 -1.0471975511965976" xyz="0.0 0.0 0.185"/>
  </joint>
  <link name="odomp"/>
  <joint name="rotatory" type="fixed">
    <parent link="odomp"/>
    <child link="base_link"/>
  </joint>
  <link name="base">
    <inertial>
      <mass value="0.01"/>
      <origin xyz="0 0 0"/>
      <inertia ixx="0.001" ixy="0.0" ixz="0.0" iyy="0.001" iyz="0.0" izz="0.001"/>
    </inertial>
    <visual>
      <geometry>
        <box size="0.04096 0.0473 0.105"/>
      </geometry>
      <material name="blue">
        <color rgba="0 0 .8 1"/>
      </material>
      <origin rpy="0 0 0" xyz="0 0 0.0525"/>
    </visual>
  </link>
  <joint name="fixed_base_motor1" type="fixed">
    <parent link="base"/>
    <child link="motor1"/>
    <origin rpy="0 0 0" xyz="0.0 -0.01591 0.140"/>
  </joint>
  <link name="motor1">
    <inertial>
      <mass value="0.01"/>
      <origin xyz="0 0 0"/>
      <inertia ixx="0.001" ixy="0.0" ixz="0.0" iyy="0.001" iyz="0.0" izz="0.001"/>
    </inertial>
    <visual>
      <geometry>
        <box size="0.07 0.123 0.067"/>
      </geometry>
      <material name="blue">
        <color rgba="0 0 .8 1"/>
      </material>
      <origin rpy="0 0 0" xyz="0 0.0615 0."/>
    </visual>
  </link>
  <joint name="joint1" type="revolute">
    <parent link="motor1"/>
    <child link="link1"/>
    <origin rpy="0 0 0" xyz="0.0 0.0 0."/>
    <axis xyz="0 1 0"/>
    <limit effort="400" lower="-1.8325957145940461" upper="1.8325957145940461" velocity="30"/>
  </joint>
  <link name="link1">
    <inertial>
      <mass value="0.01"/>
      <origin xyz="0 0 0"/>
      <inertia ixx="0.001" ixy="0.0" ixz="0.0" iyy="0.001" iyz="0.0" izz="0.001"/>
    </inertial>
    <visual>
      <geometry>
        <box size="0.06 0.012 0.3"/>
      </geometry>
      <material name="blue"/>
      <origin rpy="0 0 0" xyz="0 0. 0.125"/>
    </visual>
  </link>
  <gazebo reference="link1">
    <material>Gazebo/Black</material>
  </gazebo>
  <joint name="joint2" type="revolute">
    <parent link="link1"/>
    <child link="motor2"/>
    <origin rpy="0 0 0" xyz="0.0 0.0 0.250"/>
    <axis xyz="0 1 0"/>
    <limit effort="190" lower="-2.443460952792061" upper="2.443460952792061" velocity="30"/>
  </joint>
  <link name="motor2">
    <inertial>
      <mass value="0.01"/>
      <origin xyz="0 0 0"/>
      <inertia ixx="0.001" ixy="0.0" ixz="0.0" iyy="0.001" iyz="0.0" izz="0.001"/>
    </inertial>
    <visual>
      <geometry>
        <box size="0.064 0.125 0.054"/>
      </geometry>
      <material name="blue"/>
      <origin rpy="0 0 0" xyz="0 0.0625 0."/>
    </visual>
  </link>
  <joint name="fixed_motor2_link2" type="fixed">
    <parent link="motor2"/>
    <child link="link2"/>
    <origin rpy="0 0 0" xyz="0.0 0.098 0.027"/>
  </joint>
  <link name="link2">
    <inertial>
      <mass value="0.01"/>
      <origin xyz="0 0 0"/>
      <inertia ixx="0.001" ixy="0.0" ixz="0.0" iyy="0.001" iyz="0.0" izz="0.001"/>
    </inertial>
    <visual>
      <geometry>
        <box size="0.064 0.054 0.158"/>
      </geometry>
      <material name="blue"/>
      <origin rpy="0 0 0" xyz="0.0 0.0 0.079"/>
    </visual>
  </link>
  <gazebo reference="link2">
    <material>Gazebo/Grey</material>
  </gazebo>
  <joint name="joint3" type="revolute">
    <parent link="link2"/>
    <child link="link3"/>
    <origin rpy="0 0 0" xyz="0.0 0.0 0.158"/>
    <axis xyz="0 0 1"/>
    <limit effort="190" lower="-3.141592653589793" upper="3.141592653589793" velocity="30"/>
  </joint>
  <link name="link3">
    <inertial>
      <mass value="0.01"/>
      <origin xyz="0 0 0"/>
      <inertia ixx="0.001" ixy="0.0" ixz="0.0" iyy="0.001" iyz="0.0" izz="0.001"/>
    </inertial>
    <visual>
      <geometry>
        <box size="0.052 0.084 0.086"/>
      </geometry>
      <material name="blue"/>
      <origin rpy="0 0 0" xyz="0 -0.015 0.043"/>
    </visual>
  </link>
  <gazebo reference="link3">
    <material>Gazebo/Black</material>
  </gazebo>
  <joint name="joint4" type="revolute">
    <parent link="link3"/>
    <child link="link4"/>
    <origin rpy="0 0 0" xyz="0.0 -0.057 0.065"/>
    <axis xyz="0 1 0"/>
    <limit effort="160" lower="-3.141592653589793" upper="3.141592653589793" velocity="30"/>
  </joint>
  <link name="link4">
    <inertial>
      <mass value="0.01"/>
      <origin xyz="0 0 0"/>
      <inertia ixx="0.001" ixy="0.0" ixz="0.0" iyy="0.001" iyz="0.0" izz="0.001"/>
    </inertial>
    <visual>
      <geometry>
        <box size="0.042 0.042 0.084"/>
      </geometry>
      <material name="blue"/>
      <origin rpy="0 0 0" xyz="0. -0.021 -0.007"/>
    </visual>
  </link>
  <gazebo reference="link4">
    <material>Gazebo/Grey</material>
  </gazebo>
  <joint name="joint5" type="revolute">
    <parent link="link4"/>
    <child link="link5"/>
    <origin rpy="0 0 0" xyz="0.0 -0.027 0.035"/>
    <axis xyz="0 0 1"/>
    <limit effort="160" lower="-3.141592653589793" upper="3.141592653589793" velocity="30"/>
  </joint>
  <link name="link5">
    <inertial>
      <mass value="0.01"/>
      <origin xyz="0 0 0"/>
      <inertia ixx="0.001" ixy="0.0" ixz="0.0" iyy="0.001" iyz="0.0" izz="0.001"/>
    </inertial>
  </link>
  <gazebo reference="link5">
    <material>Gazebo/Black</material>
  </gazebo>
  <transmission name="arm_1_trans">
    <type>transmission_interface/SimpleTransmission</type>
    <joint name="joint1">
      <hardwareInterface>PositionJointInterface</hardwareInterface>
      <hardwareInterface>VelocityJointInterface</hardwareInterface>
    </joint>
    <actuator name="arm_1_motor">
      <mechanicalReduction>1</mechanicalReduction>
    </actuator>
  </transmission>
  <transmission name="arm_2_trans">
    <type>transmission_interface/SimpleTransmission</type>
    <joint name="joint2">
      <hardwareInterface>PositionJointInterface</hardwareInterface>
      <hardwareInterface>VelocityJointInterface</hardwareInterface>
    </joint>
    <actuator name="arm_2_motor">
      <mechanicalReduction>1</mechanicalReduction>
    </actuator>
  </transmission>
  <transmission name="arm_3_trans">
    <type>transmission_interface/SimpleTransmission</type>
    <joint name="joint3">
      <hardwareInterface>PositionJointInterface</hardwareInterface>
      <hardwareInterface>VelocityJointInterface</hardwareInterface>
    </joint>
    <actuator name="arm_3_motor">
      <mechanicalReduction>1</mechanicalReduction>
    </actuator>
  </transmission>
  <transmission name="arm_4_trans">
    <type>transmission_interface/SimpleTransmission</type>
    <joint name="joint4">
      <hardwareInterface>PositionJointInterface</hardwareInterface>
      <hardwareInterface>VelocityJointInterface</hardwareInterface>
    </joint>
    <actuator name="arm_4_motor">
      <mechanicalReduction>1</mechanicalReduction>
    </actuator>
  </transmission>
  <transmission name="arm_5_trans">
    <type>transmission_interface/SimpleTransmission</type>
    <joint name="joint5">
      <hardwareInterface>PositionJointInterface</hardwareInterface>
      <hardwareInterface>VelocityJointInterface</hardwareInterface>
    </joint>
    <actuator name="arm_5_motor">
      <mechanicalReduction>1</mechanicalReduction>
    </actuator>
  </transmission>
  <transmission name="arm_6_trans">
    <type>transmission_interface/SimpleTransmission</type>
    <joint name="joint6">
      <hardwareInterface>PositionJointInterface</hardwareInterface>
      <hardwareInterface>VelocityJointInterface</hardwareInterface>
    </joint>
    <actuator name="arm_6_motor">
      <mechanicalReduction>1</mechanicalReduction>
    </actuator>
  </transmission>
  <transmission name="arm_7_trans">
    <type>transmission_interface/SimpleTransmission</type>
    <joint name="joint7">
      <hardwareInterface>PositionJointInterface</hardwareInterface>
      <hardwareInterface>VelocityJointInterface</hardwareInterface>
    </joint>
    <actuator name="arm_7_motor">
      <mechanicalReduction>1</mechanicalReduction>
    </actuator>
  </transmission>
  <gazebo>
    <plugin filename="libhwi_switch_gazebo_ros_control.so" name="ros_control">
      <robotNamespace>arm_controller</robotNamespace>
      <filterJointsParam>joint_names</filterJointsParam>
    </plugin>
  </gazebo>
  <!-- hand -->
  <joint name="hand_wrist_joint" type="fixed">
    <origin rpy="1.5707963 0 0" xyz="0 0 0"/>
    <parent link="link5"/>
    <child link="hand_wrist_link"/>
  </joint>
  <link name="hand_wrist_link">
    <gravity>0</gravity>
    <inertial>
      <origin rpy="0 0 0" xyz="0.01557 -0.035456 0.0089893"/>
      <mass value="0.090062"/>
      <inertia ixx="0.00019055" ixy="-9.6717E-07" ixz="-9.3483E-06" iyy="6.2823E-05" iyz="-5.5839E-07" izz="0.00017976"/>
    </inertial>
    <visual>
      <origin rpy="0 0 0" xyz="0 0 0"/>
      <geometry>
        <mesh filename="package://kclhand_description/meshes/wrist.stl"/>
      </geometry>
      <material name="">
        <color rgba="0.79216 0.81961 0.93333 1"/>
      </material>
    </visual>
    <collision>
      <origin rpy="0 0 0" xyz="0 0 0"/>
      <geometry>
        <mesh filename="package://kclhand_description/meshes/wrist.stl"/>
      </geometry>
    </collision>
  </link>
  <joint name="hand_base_joint" type="fixed">
    <origin rpy="0 0.52 0" xyz="-0.02105 0.1485 0"/>
    <parent link="hand_wrist_link"/>
    <child link="hand_base_link"/>
  </joint>
  <link name="hand_base_link">
    <gravity>0</gravity>
    <inertial>
      <origin rpy="0 0 0" xyz="0.01557 -0.035456 0.0089893"/>
      <mass value="0.090062"/>
      <inertia ixx="0.00019055" ixy="-9.6717E-07" ixz="-9.3483E-06" iyy="6.2823E-05" iyz="-5.5839E-07" izz="0.00017976"/>
    </inertial>
    <visual>
      <origin rpy="0 0 0" xyz="0 0 0"/>
      <geometry>
        <mesh filename="package://kclhand_description/meshes/base_link.STL"/>
      </geometry>
      <material name="">
        <color rgba="0.79216 0.81961 0.93333 1"/>
      </material>
    </visual>
    <collision>
      <origin rpy="0 0 0" xyz="0 0 0"/>
      <geometry>
        <mesh filename="package://kclhand_description/meshes/base_link.STL"/>
      </geometry>
    </collision>
  </link>
  <joint name="hand_middle_finger_lower_joint" type="continuous">
    <origin rpy="-0.5236 5.5511E-17 1.5708" xyz="0.035507 0.02 0.0205"/>
    <parent link="hand_base_link"/>
    <child link="hand_middle_finger_lower_link"/>
    <axis xyz="0 0 -1"/>
  </joint>
  <link name="hand_middle_finger_lower_link">
    <gravity>0</gravity>
    <inertial>
      <origin rpy="0 0 0" xyz="0.024233 0 0.00037037"/>
      <mass value="0.006486"/>
      <inertia ixx="3.4547E-07" ixy="1.0406E-14" ixz="-5.6131E-08" iyy="2.2725E-06" iyz="1.7474E-25" izz="2.1581E-06"/>
    </inertial>
    <visual>
      <origin rpy="0 0 0" xyz="0 0 0"/>
      <geometry>
        <mesh filename="package://kclhand_description/meshes/middle_finger_lower_link.STL"/>
      </geometry>
      <material name="">
        <color rgba="0.79216 0.81961 0.93333 1"/>
      </material>
    </visual>
    <collision>
      <origin rpy="0 0 0" xyz="0 0 0"/>
      <geometry>
        <mesh filename="package://kclhand_description/meshes/middle_finger_lower_link.STL"/>
      </geometry>
    </collision>
  </link>
  <joint name="hand_middle_finger_upper_joint" type="continuous">
    <origin rpy="0 0 0.7854" xyz="0.05 0 0"/>
    <parent link="hand_middle_finger_lower_link"/>
    <child link="hand_middle_finger_upper_link"/>
    <axis xyz="0 0 1"/>
  </joint>
  <link name="hand_middle_finger_upper_link">
    <gravity>0</gravity>
    <inertial>
      <origin rpy="0 0 0" xyz="0.020984 -8.2445E-05 1.3574E-08"/>
      <mass value="0.0074578"/>
      <inertia ixx="1.9676E-07" ixy="-1.6657E-08" ixz="4.2518E-13" iyy="1.5058E-06" iyz="-7.6094E-13" izz="1.4941E-06"/>
    </inertial>
    <visual>
      <origin rpy="0 0 0" xyz="0 0 0"/>
      <geometry>
        <mesh filename="package://kclhand_description/meshes/middle_finger_upper_link.STL"/>
      </geometry>
      <material name="">
        <color rgba="0.79216 0.81961 0.93333 1"/>
      </material>
    </visual>
    <collision>
      <origin rpy="0 0 0" xyz="0 0 0"/>
      <geometry>
        <mesh filename="package://kclhand_description/meshes/middle_finger_upper_link.STL"/>
      </geometry>
    </collision>
  </link>
  <joint name="hand_left_crank_base_joint" type="continuous">
    <origin rpy="-2.1588 0.44783 -1.8518" xyz="0 0 0"/>
    <parent link="hand_base_link"/>
    <child link="hand_left_crank"/>
    <axis xyz="0 0 1"/>
  </joint>
  <link name="hand_left_crank">
    <gravity>0</gravity>
    <inertial>
      <origin rpy="0 0 0" xyz="0.014612 -1.3878E-17 0.044306"/>
      <mass value="0.0043398"/>
      <inertia ixx="1.3753E-07" ixy="9.099E-23" ixz="-9.7593E-08" iyy="5.3471E-07" iyz="-1.1911E-22" izz="5.344E-07"/>
    </inertial>
    <visual>
      <origin rpy="0 0 0" xyz="0 0 0"/>
      <geometry>
        <mesh filename="package://kclhand_description/meshes/left_crank.STL"/>
      </geometry>
      <material name="">
        <color rgba="0.79216 0.81961 0.93333 1"/>
      </material>
    </visual>
    <collision>
      <origin rpy="0 0 0" xyz="0 0 0"/>
      <geometry>
        <mesh filename="package://kclhand_description/meshes/left_crank.STL"/>
      </geometry>
    </collision>
  </link>
  <joint name="hand_left_coupler_crank_joint" type="continuous">
    <origin rpy="0.40154 0.63113 0.62376" xyz="0 0 0"/>
    <parent link="hand_left_crank"/>
    <child link="hand_left_coupler"/>
    <axis xyz="0 0 1"/>
  </joint>
  <link name="hand_left_coupler">
    <gravity>0</gravity>
    <inertial>
      <origin rpy="0 0 0" xyz="0.025652 0.0023238 0.036819"/>
      <mass value="0.01251"/>
      <inertia ixx="2.1785E-06" ixy="-2.738E-07" ixz="-1.67E-06" iyy="4.045E-06" iyz="2.2624E-07" izz="2.9076E-06"/>
    </inertial>
    <visual>
      <origin rpy="0 0 0" xyz="0 0 0"/>
      <geometry>
        <mesh filename="package://kclhand_description/meshes/left_coupler.STL"/>
      </geometry>
      <material name="">
        <color rgba="0.79216 0.81961 0.93333 1"/>
      </material>
    </visual>
    <collision>
      <origin rpy="0 0 0" xyz="0 0 0"/>
      <geometry>
        <mesh filename="package://kclhand_description/meshes/left_coupler.STL"/>
      </geometry>
    </collision>
  </link>
  <joint name="hand_left_finger_lower_joint" type="continuous">
    <origin rpy="-1.2217 -7.6328E-17 1.5708" xyz="0.016246 0.021 0.044635"/>
    <parent link="hand_left_coupler"/>
    <child link="hand_left_finger_lower_link"/>
    <axis xyz="0 0 -1"/>
  </joint>
  <link name="hand_left_finger_lower_link">
    <gravity>0</gravity>
    <inertial>
      <origin rpy="0 0 0" xyz="0.024233 3.4086E-11 0.00037037"/>
      <mass value="0.006486"/>
      <inertia ixx="3.4547E-07" ixy="7.2695E-15" ixz="-5.6131E-08" iyy="2.2725E-06" iyz="-6.516E-16" izz="2.1581E-06"/>
    </inertial>
    <visual>
      <origin rpy="0 0 0" xyz="0 0 0"/>
      <geometry>
        <mesh filename="package://kclhand_description/meshes/left_finger_lower_link.STL"/>
      </geometry>
      <material name="">
        <color rgba="0.79216 0.81961 0.93333 1"/>
      </material>
    </visual>
    <collision>
      <origin rpy="0 0 0" xyz="0 0 0"/>
      <geometry>
        <mesh filename="package://kclhand_description/meshes/left_finger_lower_link.STL"/>
      </geometry>
    </collision>
  </link>
  <joint name="hand_left_finger_upper_joint" type="continuous">
    <origin rpy="-1.5543E-15 7.7716E-16 0.7854" xyz="0.05 0 0"/>
    <parent link="hand_left_finger_lower_link"/>
    <child link="hand_left_finger_upper_link"/>
    <axis xyz="0 0 1"/>
  </joint>
  <link name="hand_left_finger_upper_link">
    <gravity>0</gravity>
    <inertial>
      <origin rpy="0 0 0" xyz="0.020984 -8.2445E-05 1.4832E-08"/>
      <mass value="0.0074578"/>
      <inertia ixx="1.9676E-07" ixy="-1.6657E-08" ixz="4.8306E-13" iyy="1.5058E-06" iyz="-7.8866E-13" izz="1.4941E-06"/>
    </inertial>
    <visual>
      <origin rpy="0 0 0" xyz="0 0 0"/>
      <geometry>
        <mesh filename="package://kclhand_description/meshes/left_finger_upper_link.STL"/>
      </geometry>
      <material name="">
        <color rgba="0.79216 0.81961 0.93333 1"/>
      </material>
    </visual>
    <collision>
      <origin rpy="0 0 0" xyz="0 0 0"/>
      <geometry>
        <mesh filename="package://kclhand_description/meshes/left_finger_upper_link.STL"/>
      </geometry>
    </collision>
  </link>
  <joint name="hand_right_crank_base_joint" type="continuous">
    <origin rpy="-5.5511E-17 -2.7756E-17 1.0472" xyz="0 0 0"/>
    <parent link="hand_base_link"/>
    <child link="hand_right_crank"/>
    <axis xyz="0 0 1"/>
  </joint>
  <link name="hand_right_crank">
    <gravity>0</gravity>
    <inertial>
      <origin rpy="0 0 0" xyz="-0.014612 0 0.044306"/>
      <mass value="0.0043398"/>
      <inertia ixx="1.3753E-07" ixy="2.0514E-22" ixz="9.7593E-08" iyy="5.3471E-07" iyz="-9.2644E-23" izz="5.344E-07"/>
    </inertial>
    <visual>
      <origin rpy="0 0 0" xyz="0 0 0"/>
      <geometry>
        <mesh filename="package://kclhand_description/meshes/right_crank.STL"/>
      </geometry>
      <material name="">
        <color rgba="0.79216 0.81961 0.93333 1"/>
      </material>
    </visual>
    <collision>
      <origin rpy="0 0 0" xyz="0 0 0"/>
      <geometry>
        <mesh filename="package://kclhand_description/meshes/right_crank.STL"/>
      </geometry>
    </collision>
  </link>
  <joint name="hand_right_coupler_crank_joint" type="continuous">
    <origin rpy="0.40154 -0.63113 -0.62376" xyz="0 0 0"/>
    <parent link="hand_right_crank"/>
    <child link="hand_right_coupler"/>
    <axis xyz="0 0 1"/>
  </joint>
  <link name="hand_right_coupler">
    <gravity>0</gravity>
    <inertial>
      <origin rpy="0 0 0" xyz="-0.024811 0.0024049 0.037771"/>
      <mass value="0.011998"/>
      <inertia ixx="1.8794E-06" ixy="2.475E-07" ixz="1.426E-06" iyy="3.5227E-06" iyz="1.971E-07" izz="2.6629E-06"/>
    </inertial>
    <visual>
      <origin rpy="0 0 0" xyz="0 0 0"/>
      <geometry>
        <mesh filename="package://kclhand_description/meshes/right_coupler.STL"/>
      </geometry>
      <material name="">
        <color rgba="0.79216 0.81961 0.93333 1"/>
      </material>
    </visual>
    <collision>
      <origin rpy="0 0 0" xyz="0 0 0"/>
      <geometry>
        <mesh filename="package://kclhand_description/meshes/right_coupler.STL"/>
      </geometry>
    </collision>
  </link>
  <joint name="hand_right_finger_lower_joint" type="continuous">
    <origin rpy="-1.9199 -2.047E-16 1.5708" xyz="-0.016246 0.021 0.044635"/>
    <parent link="hand_right_coupler"/>
    <child link="hand_right_finger_lower_link"/>
    <axis xyz="0 0 1"/>
  </joint>
  <link name="hand_right_finger_lower_link">
    <gravity>0</gravity>
    <inertial>
      <origin rpy="0 0 0" xyz="0.024233 3.4086E-11 -0.00037037"/>
      <mass value="0.006486"/>
      <inertia ixx="3.4547E-07" ixy="-6.8751E-15" ixz="5.6131E-08" iyy="2.2725E-06" iyz="-6.9268E-16" izz="2.1581E-06"/>
    </inertial>
    <visual>
      <origin rpy="0 0 0" xyz="0 0 0"/>
      <geometry>
        <mesh filename="package://kclhand_description/meshes/right_finger_lower_link.STL"/>
      </geometry>
      <material name="">
        <color rgba="0.79216 0.81961 0.93333 1"/>
      </material>
    </visual>
    <collision>
      <origin rpy="0 0 0" xyz="0 0 0"/>
      <geometry>
        <mesh filename="package://kclhand_description/meshes/right_finger_lower_link.STL"/>
      </geometry>
    </collision>
  </link>
  <joint name="hand_right_finger_upper_joint" type="continuous">
    <origin rpy="4.4409E-16 -2.9143E-16 0.7854" xyz="0.05 0 0"/>
    <parent link="hand_right_finger_lower_link"/>
    <child link="hand_right_finger_upper_link"/>
    <axis xyz="0 0 1"/>
  </joint>
  <link name="hand_right_finger_upper_link">
    <gravity>0</gravity>
    <inertial>
      <origin rpy="0 0 0" xyz="0.0209841782024376 -8.24447259299282E-05 1.48380963488348E-08"/>
      <mass value="0.00745775236371133"/>
      <inertia ixx="1.96760101056754E-07" ixy="-1.66570648066968E-08" ixz="4.83304215932166E-13" iyy="1.50575433290444E-06" iyz="-7.89718168534389E-13" izz="1.49411790379235E-06"/>
    </inertial>
    <visual>
      <origin rpy="0 0 0" xyz="0 0 0"/>
      <geometry>
        <mesh filename="package://kclhand_description/meshes/right_finger_upper_link.STL"/>
      </geometry>
      <material name="">
        <color rgba="0.792156862745098 0.819607843137255 0.933333333333333 1"/>
      </material>
    </visual>
    <collision>
      <origin rpy="0 0 0" xyz="0 0 0"/>
      <geometry>
        <mesh filename="package://kclhand_description/meshes/right_finger_upper_link.STL"/>
      </geometry>
    </collision>
  </link>
  <transmission name="hand_left_coupler_crank_joint_trans">
    <type>transmission_interface/SimpleTransmission</type>
    <joint name="hand_left_coupler_crank_joint">
      <hardwareInterface>PositionJointInterface</hardwareInterface>
      <!--hardwareInterface>VelocityJointInterface</hardwareInterface-->
    </joint>
    <actuator name="hand_left_coupler_crank_motor">
      <mechanicalReduction>1</mechanicalReduction>
    </actuator>
  </transmission>
  <transmission name="hand_left_crank_base_trans">
    <type>transmission_interface/SimpleTransmission</type>
    <joint name="hand_left_crank_base_joint">
      <hardwareInterface>PositionJointInterface</hardwareInterface>
      <!--hardwareInterface>VelocityJointInterface</hardwareInterface-->
    </joint>
    <actuator name="hand_left_crank_base_motor">
      <mechanicalReduction>1</mechanicalReduction>
    </actuator>
  </transmission>
  <transmission name="hand_left_finger_lower_trans">
    <type>transmission_interface/SimpleTransmission</type>
    <joint name="hand_left_finger_lower_joint">
      <hardwareInterface>PositionJointInterface</hardwareInterface>
      <!--hardwareInterface>VelocityJointInterface</hardwareInterface-->
    </joint>
    <actuator name="hand_left_finger_lower_motor">
      <mechanicalReduction>1</mechanicalReduction>
    </actuator>
  </transmission>
  <transmission name="hand_left_finger_upper_trans">
    <type>transmission_interface/SimpleTransmission</type>
    <joint name="hand_left_finger_upper_joint">
      <hardwareInterface>PositionJointInterface</hardwareInterface>
      <!--hardwareInterface>VelocityJointInterface</hardwareInterface-->
    </joint>
    <actuator name="hand_left_finger_upper_motor">
      <mechanicalReduction>1</mechanicalReduction>
    </actuator>
  </transmission>
  <transmission name="hand_middle_finger_lower_trans">
    <type>transmission_interface/SimpleTransmission</type>
    <joint name="hand_middle_finger_lower_joint">
      <hardwareInterface>PositionJointInterface</hardwareInterface>
      <!--hardwareInterface>VelocityJointInterface</hardwareInterface-->
    </joint>
    <actuator name="hand_middle_finger_lower_motor">
      <mechanicalReduction>1</mechanicalReduction>
    </actuator>
  </transmission>
  <transmission name="hand_middle_finger_upper_trans">
    <type>transmission_interface/SimpleTransmission</type>
    <joint name="hand_middle_finger_upper_joint">
      <hardwareInterface>PositionJointInterface</hardwareInterface>
      <!--hardwareInterface>VelocityJointInterface</hardwareInterface-->
    </joint>
    <actuator name="hand_middle_finger_upper_motor">
      <mechanicalReduction>1</mechanicalReduction>
    </actuator>
  </transmission>
  <transmission name="hand_right_crank_base_trans">
    <type>transmission_interface/SimpleTransmission</type>
    <joint name="hand_right_crank_base_joint">
      <hardwareInterface>PositionJointInterface</hardwareInterface>
      <!--hardwareInterface>VelocityJointInterface</hardwareInterface-->
    </joint>
    <actuator name="hand_right_crank_base_motor">
      <mechanicalReduction>1</mechanicalReduction>
    </actuator>
  </transmission>
  <transmission name="hand_right_coupler_crank_trans">
    <type>transmission_interface/SimpleTransmission</type>
    <joint name="hand_right_coupler_crank_joint">
      <hardwareInterface>PositionJointInterface</hardwareInterface>
      <!--hardwareInterface>VelocityJointInterface</hardwareInterface-->
    </joint>
    <actuator name="hand_right_coupler_crank_motor">
      <mechanicalReduction>1</mechanicalReduction>
    </actuator>
  </transmission>
  <transmission name="hand_right_finger_lower_trans">
    <type>transmission_interface/SimpleTransmission</type>
    <joint name="hand_right_finger_lower_joint">
      <hardwareInterface>PositionJointInterface</hardwareInterface>
      <!--hardwareInterface>VelocityJointInterface</hardwareInterface-->
    </joint>
    <actuator name="hand_right_finger_lower_motor">
      <mechanicalReduction>1</mechanicalReduction>
    </actuator>
  </transmission>
  <transmission name="hand_right_finger_upper_trans">
    <type>transmission_interface/SimpleTransmission</type>
    <joint name="hand_right_finger_upper_joint">
      <hardwareInterface>PositionJointInterface</hardwareInterface>
      <!--hardwareInterface>VelocityJointInterface</hardwareInterface-->
    </joint>
    <actuator name="hand_right_finger_upper_motor">
      <mechanicalReduction>1</mechanicalReduction>
    </actuator>
  </transmission>
  <gazebo reference="hand_base_link">
    <gravity>true</gravity>
    <self_collide>false</self_collide>
  </gazebo>
  <gazebo reference="hand_left_coupler">
    <gravity>true</gravity>
    <self_collide>false</self_collide>
  </gazebo>
  <gazebo reference="hand_left_crank">
    <gravity>true</gravity>
    <self_collide>false</self_collide>
  </gazebo>
  <gazebo reference="hand_left_finger_lower_link">
    <gravity>true</gravity>
    <self_collide>false</self_collide>
  </gazebo>
  <gazebo reference="hand_left_finger_upper_link">
    <gravity>true</gravity>
    <self_collide>false</self_collide>
  </gazebo>
  <gazebo reference="hand_middle_finger_lower_link">
    <gravity>true</gravity>
    <self_collide>false</self_collide>
  </gazebo>
  <gazebo reference="hand_middle_finger_upper_link">
    <gravity>true</gravity>
    <self_collide>false</self_collide>
  </gazebo>
  <gazebo reference="hand_right_coupler">
    <gravity>true</gravity>
    <self_collide>false</self_collide>
  </gazebo>
  <gazebo reference="hand_right_crank">
    <gravity>true</gravity>
    <self_collide>false</self_collide>
  </gazebo>
  <gazebo reference="hand_right_finger_lower_link">
    <gravity>true</gravity>
    <self_collide>false</self_collide>
  </gazebo>
  <gazebo reference="hand_right_finger_upper_link">
    <gravity>true</gravity>
    <self_collide>false</self_collide>
  </gazebo>
  <gazebo>
    <plugin filename="libhwi_switch_gazebo_ros_control.so" name="ros_control">
      <robotNamespace>hand_controller</robotNamespace>
      <filterJointsParam>joint_names</filterJointsParam>
    </plugin>
  </gazebo>
</robot>

