<?xml version="1.0" ?>
<!-- =================================================================================== -->
<!-- |    This document was autogenerated by xacro from robotino_base_plan.urdf.xacro  | -->
<!-- |    EDITING THIS FILE BY HAND IS NOT RECOMMENDED                                 | -->
<!-- =================================================================================== -->
<robot name="robot" xmlns:xacro="http://www.ros.org/wiki/xacro">
  <!-- ****************** -->
  <!-- ***** COMMON ***** -->
  <!-- ****************** -->
  <!-- hokuyo mount positions | relative to base_link -->
  <!-- pan_tilt mount positions | handeye calibration | relative to base_link -->
  <!--property name="pan_tilt_x" value="0.310911"/>
  <property name="pan_tilt_y" value="0.0177173"/>
  <property name="pan_tilt_z" value="0.683637"/>
  <property name="pan_tilt_roll" value="3.0864"/>
  <property name="pan_tilt_pitch" value="3.08658"/>
  <property name="pan_tilt_yaw" value="3.13856"/-->
  <!-- kinect mount positions | handeye calibration | relative to pan_tilt_link -->
  <!--property name="kinect_x" value="0.0162762"/>
  <property name="kinect_y" value="0.0736591"/>
  <property name="kinect_z" value="-0.0649505"/>
  <property name="kinect_roll" value="-1.53"/>
  <property name="kinect_pitch" value="-0.0315698"/>
  <property name="kinect_yaw" value="0.0239961"/-->
  <!-- pan_tilt mount positions | handeye calibration | relative to base_link -->
  <!-- kinect mount positions | handeye calibration | relative to pan_tilt_link -->
  <!-- arm mount positions | handeye calibration | relative to base_link -->
  <!-- arm calibration-->
  <!-- WHEEL -->
  <!-- Wheel transmission   -->
  <!--GAZEBO PLUGIN-->
  <!-- GAZEBO OPENNI PLUGIN -->
  <!-- include other model components -->
  <material name="SoftHand/LightGrey">
    <color rgba="0.7 0.7 0.7 1.0"/>
  </material>
  <material name="SoftHand/DarkGrey">
    <color rgba="0.4 0.4 0.4 1.0"/>
  </material>
  <material name="SoftHand/Black">
    <color rgba="0.0 0.0 0.0 1.0"/>
  </material>
  <material name="SoftHand/DarkGolden">
    <color rgba="0.4 0.4 0.3 1.0"/>
  </material>
  <material name="SoftHand/Blue">
    <color rgba="0.0 0.0 0.8 0.9"/>
  </material>
  <material name="SoftHand/LightBlue">
    <color rgba="0.0 0.4 1.0 0.5"/>
  </material>
  <!-- configure how all joints will behave in gazebo (particular behavior can be set at each joint as well) -->
  <!-- set friction properties -->
  <!-- <xacro:insert_block name="gazebo_friction_properties"/> -->
  <!-- <xacro:insert_block name="gazebo_other_properties"/> -->
  <!-- NOTE: inertia values are approximated using meshlab and only using the significant elements -->
  <!-- from http://answers.ros.org/question/11350/is-there-any-way-to-calculate-inertial-property-of-a-robot-to-simulate-it-in-gazebo/s
    One general rule of thumb I use for checking my inertia tensors is: If total mass of the rigid body is m, and the dimension of the corresponding body is d, then check to see if ixx, iyy, izz are near m*(d/2)^2.

    This is by no means correct, but a sanity check to make sure the moment of inertia are the right order of magnitudes, so the model behaves somewhat physically realistically.
    -->
  <!-- conversions -->
  <!-- I couldn't make the simulation work with realistic values, so I tweaked the conversion values -->
  <!-- not so negligible, otherwise simulation fails -->
  <!-- MESHLAB RESULT 
Opened mesh /home/crosales/Code/catkin_ws/src/pisa-iit-soft-hand/soft_hand/soft_hand_description/meshes/knuckle.stl in 9 msec
All files opened in 1398 msec
Enabled Decorate mode Show Axis
Mesh Bounding Box Size 34.382004 14.000006 24.628571
Mesh Bounding Box Diag 44.549847 
Mesh Volume is 3450.446777
Mesh Surface is 4583.448730
Thin shell barycenter 1.201245 0.001308 0.586193
Center of Mass is 1.285644 -0.000958 0.425011
Inertia Tensor is :
| 160373.578125 -18.966606 13918.184570 |
| -18.966606 311858.187500 59.538574 |
| 13918.184570 59.538574 249686.000000 |
Principal axes are :
| 0.988611 -0.000038 0.150492 |
| 0.000180 1.000000 -0.000933 |
| -0.150492 0.000949 0.988611 |
axis momenta are :
| 158254.859375 311858.250000 251804.656250 |
-->
  <!-- MESHLAB RESULT 
Opened mesh /home/crosales/Code/catkin_ws/src/pisa-iit-soft-hand/soft_hand/soft_hand_description/meshes/thumb_knuckle.stl in 6 msec
All files opened in 1493 msec
Enabled Decorate mode Show Axis
Mesh Bounding Box Size 38.298431 21.449932 21.967697
Mesh Bounding Box Diag 49.086140 
Mesh Volume is 3444.315186
Mesh Surface is 4292.456543
Thin shell barycenter 14.662230 -0.440256 0.060471
Center of Mass is 13.608098 -0.532174 -0.216691
Inertia Tensor is :
| 121779.453125 -25104.320312 -7351.798340 |
| -25104.320312 336414.968750 4401.581055 |
| -7351.798340 4401.581055 333794.062500 |
Principal axes are :
| 0.992996 -0.113512 0.032781 |
| 0.113844 0.845023 -0.522470 |
| 0.031606 0.522542 0.852027 |
axis momenta are :
| 118667.312500 342509.062500 330812.125000 |
-->
  <!-- MESHLAB RESULT 
Opened mesh /home/crosales/Code/catkin_ws/src/pisa-iit-soft-hand/soft_hand/soft_hand_description/meshes/phalanx.stl in 8 msec
All files opened in 1240 msec
Mesh Bounding Box Size 25.158094 14.000006 18.515181
Mesh Bounding Box Diag 34.230713 
Mesh Volume is 2003.388916
Mesh Surface is 2495.472412
Thin shell barycenter 5.001481 0.001261 0.002639
Center of Mass is 5.074337 -0.004524 -0.262953
Inertia Tensor is :
| 79493.273438 -2.796152 -5974.423340 |
| -2.796152 121398.460938 16.481358 |
| -5974.423340 16.481358 122965.343750 |
Principal axes are :
| 0.991019 0.000928 -0.133714 |
| 0.000013 0.999975 0.007040 |
| 0.133718 -0.006979 0.990995 |
axis momenta are :
| 78687.148438 121398.343750 123771.585938 |
-->
  <!-- MESHLAB RESULT 
Opened mesh /home/crosales/Code/catkin_ws/src/pisa-iit-soft-hand/soft_hand/soft_hand_description/meshes/fingertip.stl in 7 msec
All files opened in 1241 msec
Mesh Bounding Box Size 32.299561 14.000006 19.228573
Mesh Bounding Box Diag 40.112339 
Mesh Volume is 3519.114502
Mesh Surface is 4175.043945
Thin shell barycenter 8.126755 0.000146 0.955067
Center of Mass is 9.849094 0.000560 0.820286
Inertia Tensor is :
| 133971.296875 -13.962580 -14369.020508 |
| -13.962580 308096.281250 -12.146572 |
| -14369.020508 -12.146572 287758.875000 |
Principal axes are :
| 0.995737 -0.000033 -0.092238 |
| 0.000086 1.000000 0.000569 |
| 0.092238 -0.000574 0.995737 |
axis momenta are :
| 132640.250000 308096.281250 289089.906250 |
-->
  <!-- MESHLAB RESULT 
Opened mesh /home/crosales/Code/catkin_ws/src/pisa-iit-soft-hand/soft_hand/soft_hand_description/meshes/palm_right.stl in 13 msec
All files opened in 1178 msec
Mesh Bounding Box Size 36.539444 91.129791 84.829025
Mesh Bounding Box Diag 129.752579 
Mesh Volume is 76748.765625
Mesh Surface is 52111.375000
Thin shell barycenter -5.584415 -7.926011 28.832655
Center of Mass is -4.568758 -6.808116 27.653328
Inertia Tensor is :
| 55001040.000000 -714369.625000 -867280.437500 |
| -714369.625000 31722332.000000 -1570798.250000 |
| -867280.437500 -1570798.250000 37379544.000000 |
Principal axes are :
| 0.998540 0.038402 0.037998 |
| -0.027432 0.966351 -0.255759 |
| -0.046541 0.254343 0.965993 |
axis momenta are :
| 55061088.000000 31280510.000000 37761316.000000 |
-->
  <!-- accesories -->
  <!-- joint properties -->
  <!-- synergy vector -->
  <!-- synergy joint properties -->
  <!-- SOFT FINGER model -->
  <!-- 4 fingers are equal (index, middle, ring, little) -->
  <!-- THUMB MODEL -->
  <!-- It has one joint less than rest of fingers -->
  <!-- SOFT HAND MODEL -->
  <link name="base_link">
    <inertial>
      <mass value="10"/>
      <origin xyz="0 0 0"/>
      <inertia ixx="75.0" ixy="0.0" ixz="0.0" iyy="75.0" iyz="0.0" izz="75.0"/>
    </inertial>
  </link>
  <joint name="base_jointx" type="prismatic">
    <parent link="base_link"/>
    <child link="base_linkx"/>
    <origin rpy="0 0 0" xyz="0 0 0"/>
    <axis xyz="1 0 0"/>
    <limit effort="190" lower="-10" upper="10" velocity="30"/>
  </joint>
  <link name="base_linkx">
    <inertial>
      <mass value="10"/>
      <origin xyz="0 0 0"/>
      <inertia ixx="75.0" ixy="0.0" ixz="0.0" iyy="75.0" iyz="0.0" izz="75.0"/>
    </inertial>
  </link>
  <joint name="base_jointy" type="prismatic">
    <parent link="base_linkx"/>
    <child link="base_linky"/>
    <origin rpy="0 0 0" xyz="0 0 0"/>
    <axis xyz="0 1 0"/>
    <limit effort="190" lower="-10" upper="10" velocity="30"/>
  </joint>
  <link name="base_linky">
    <inertial>
      <mass value="10"/>
      <origin xyz="0 0 0"/>
      <inertia ixx="75.0" ixy="0.0" ixz="0.0" iyy="75.0" iyz="0.0" izz="75.0"/>
    </inertial>
  </link>
  <joint name="base_jointz" type="revolute">
    <parent link="base_linky"/>
    <child link="base_linkz"/>
    <origin rpy="0 0 0" xyz="0 0 0"/>
    <axis xyz="0 0 1"/>
    <limit effort="190" lower="-3.14" upper="3.14" velocity="30"/>
  </joint>
  <link name="base_linkz">
    <inertial>
      <mass value="10"/>
      <origin xyz="0 0 0"/>
      <inertia ixx="75.0" ixy="0.0" ixz="0.0" iyy="75.0" iyz="0.0" izz="75.0"/>
    </inertial>
  </link>
  <joint name="base_body_joint" type="fixed">
    <parent link="base_linkz"/>
    <child link="base_body_link"/>
    <origin rpy="0 0 0" xyz="0 0 0"/>
  </joint>
  <link name="base_body_link">
    <inertial>
      <mass value="10"/>
      <origin xyz="0 0 0"/>
      <inertia ixx="75.0" ixy="0.0" ixz="0.0" iyy="75.0" iyz="0.0" izz="75.0"/>
    </inertial>
    <visual>
      <origin rpy="0 0 0" xyz="0.01 0 0"/>
      <geometry>
        <mesh filename="package://robotino_description/meshes/RobotinoBody.dae"/>
      </geometry>
    </visual>
    <collision>
      <origin rpy="0 0 0" xyz="0.01 0 0.12"/>
      <geometry>
        <cylinder length="0.24" radius="0.23"/>
      </geometry>
    </collision>
  </link>
  <gazebo reference="base_link">
    <material>Gazebo/Grey</material>
    <gravity>true</gravity>
    <self_collide>false</self_collide>
    <sensor name="base_contact_sensor" type="contact">
      <always_on>true</always_on>
      <update_rate>100.0</update_rate>
      <contact>
        <collision>base_link_collision</collision>
        <topic>base_bumper</topic>
      </contact>
      <plugin filename="libgazebo_ros_bumper.so" name="base_gazebo_ros_bumper_controller">
        <frameName>world</frameName>
        <bumperTopicName>base_bumper</bumperTopicName>
      </plugin>
    </sensor>
  </gazebo>
  <joint name="wheel0_joint" type="continuous">
    <parent link="base_linkz"/>
    <child link="wheel0_link"/>
    <origin rpy="0 0 1.04719666667" xyz="0.095 0.14 0.02"/>
    <axis xyz="-1 0 0"/>
  </joint>
  <link name="wheel0_link">
    <inertial>
      <mass value="0.4"/>
      <origin xyz="0 0 0"/>
      <inertia ixx="0.012411765597" ixy="-0.000711733678" ixz="0.00050272983" iyy="0.015218160428" iyz="-0.000004273467" izz="0.011763977943"/>
    </inertial>
    <visual>
      <origin rpy="0 0 0" xyz="0 0 0"/>
      <geometry>
        <!--cylinder length="0.04" radius="0.04"/-->
        <mesh filename="package://robotino_description/meshes/RobotinoWheel.dae" scale="0.01 0.01 0.01"/>
      </geometry>
    </visual>
    <collision>
      <origin rpy="0 1.570795 0" xyz="0 0 0"/>
      <geometry>
        <!--mesh filename="package://robotino_description/meshes/RobotinoWheel.dae" scale="${M_SCALE} ${M_SCALE} ${M_SCALE}"/-->
        <cylinder length="0.04" radius="0.04"/>
      </geometry>
    </collision>
  </link>
  <transmission name="wheel0_trans">
    <type>transmission_interface/SimpleTransmission</type>
    <joint name="wheel0_joint">
      <hardwareInterface>VelocityJointInterface</hardwareInterface>
    </joint>
    <actuator name="wheel0_motor">
      <hardwareInterface>VelocityJointInterface</hardwareInterface>
      <mechanicalReduction>79.2380952381</mechanicalReduction>
    </actuator>
  </transmission>
  <gravity>true</gravity>
  <self_collide>false</self_collide>
  <!--gazebo reference="${name}_link">
      <mu1 value="100.0" /> 
      <mu2 value="100.0" /> 
      <kp  value="1000000.0" />
      <kd  value="1.0" />
      <fdir1>0 1 0</fdir1>
      <maxContacts>1</maxContacts>
    </gazebo-->
  <joint name="wheel1_joint" type="continuous">
    <parent link="base_linkz"/>
    <child link="wheel1_link"/>
    <origin rpy="0 0 0" xyz="-0.16 0 0.02"/>
    <axis xyz="1 0 0"/>
  </joint>
  <link name="wheel1_link">
    <inertial>
      <mass value="0.4"/>
      <origin xyz="0 0 0"/>
      <inertia ixx="0.012411765597" ixy="-0.000711733678" ixz="0.00050272983" iyy="0.015218160428" iyz="-0.000004273467" izz="0.011763977943"/>
    </inertial>
    <visual>
      <origin rpy="0 0 0" xyz="0 0 0"/>
      <geometry>
        <!--cylinder length="0.04" radius="0.04"/-->
        <mesh filename="package://robotino_description/meshes/RobotinoWheel.dae" scale="0.01 0.01 0.01"/>
      </geometry>
    </visual>
    <collision>
      <origin rpy="0 1.570795 0" xyz="0 0 0"/>
      <geometry>
        <!--mesh filename="package://robotino_description/meshes/RobotinoWheel.dae" scale="${M_SCALE} ${M_SCALE} ${M_SCALE}"/-->
        <cylinder length="0.04" radius="0.04"/>
      </geometry>
    </collision>
  </link>
  <transmission name="wheel1_trans">
    <type>transmission_interface/SimpleTransmission</type>
    <joint name="wheel1_joint">
      <hardwareInterface>VelocityJointInterface</hardwareInterface>
    </joint>
    <actuator name="wheel1_motor">
      <hardwareInterface>VelocityJointInterface</hardwareInterface>
      <mechanicalReduction>79.2380952381</mechanicalReduction>
    </actuator>
  </transmission>
  <gravity>true</gravity>
  <self_collide>false</self_collide>
  <!--gazebo reference="${name}_link">
      <mu1 value="100.0" /> 
      <mu2 value="100.0" /> 
      <kp  value="1000000.0" />
      <kd  value="1.0" />
      <fdir1>0 1 0</fdir1>
      <maxContacts>1</maxContacts>
    </gazebo-->
  <joint name="wheel2_joint" type="continuous">
    <parent link="base_linkz"/>
    <child link="wheel2_link"/>
    <origin rpy="0 0 -1.04719666667" xyz="0.105 -0.15 0.02"/>
    <axis xyz="-1 0 0"/>
  </joint>
  <link name="wheel2_link">
    <inertial>
      <mass value="0.4"/>
      <origin xyz="0 0 0"/>
      <inertia ixx="0.012411765597" ixy="-0.000711733678" ixz="0.00050272983" iyy="0.015218160428" iyz="-0.000004273467" izz="0.011763977943"/>
    </inertial>
    <visual>
      <origin rpy="0 0 0" xyz="0 0 0"/>
      <geometry>
        <!--cylinder length="0.04" radius="0.04"/-->
        <mesh filename="package://robotino_description/meshes/RobotinoWheel.dae" scale="0.01 0.01 0.01"/>
      </geometry>
    </visual>
    <collision>
      <origin rpy="0 1.570795 0" xyz="0 0 0"/>
      <geometry>
        <!--mesh filename="package://robotino_description/meshes/RobotinoWheel.dae" scale="${M_SCALE} ${M_SCALE} ${M_SCALE}"/-->
        <cylinder length="0.04" radius="0.04"/>
      </geometry>
    </collision>
  </link>
  <transmission name="wheel2_trans">
    <type>transmission_interface/SimpleTransmission</type>
    <joint name="wheel2_joint">
      <hardwareInterface>VelocityJointInterface</hardwareInterface>
    </joint>
    <actuator name="wheel2_motor">
      <hardwareInterface>VelocityJointInterface</hardwareInterface>
      <mechanicalReduction>79.2380952381</mechanicalReduction>
    </actuator>
  </transmission>
  <gravity>true</gravity>
  <self_collide>false</self_collide>
  <!--gazebo reference="${name}_link">
      <mu1 value="100.0" /> 
      <mu2 value="100.0" /> 
      <kp  value="1000000.0" />
      <kd  value="1.0" />
      <fdir1>0 1 0</fdir1>
      <maxContacts>1</maxContacts>
    </gazebo-->
  <gazebo>
    <plugin filename="libhwi_switch_gazebo_ros_control.so" name="ros_control">
      <robotNamespace>base_controller</robotNamespace>
      <filterJointsParam>joint_names</filterJointsParam>
    </plugin>
  </gazebo>
  <joint name="hokuyo_joint" type="fixed">
    <origin rpy="0.0 0.0 0.0" xyz="0.208610627 0.0 0.095"/>
    <parent link="base_linkz"/>
    <child link="hokuyo_link"/>
  </joint>
  <link name="hokuyo_link">
    <inertial>
      <mass value="0.00001"/>
      <origin xyz="0 0 0"/>
      <inertia ixx="1.0" ixy="0.0" ixz="0.0" iyy="1.0" iyz="0.0" izz="1.0"/>
    </inertial>
    <visual>
      <origin rpy="0 0 1.570795" xyz="0 0 -0.05"/>
      <geometry>
        <mesh filename="package://robotino_description/meshes/hokuyo.dae" scale="0.01 0.01 0.01"/>
      </geometry>
    </visual>
    <collision>
      <origin rpy="0 0 0" xyz="0 0 0.035"/>
      <geometry>
        <cylinder length="0.07" radius="0.02"/>
      </geometry>
    </collision>
  </link>
  <!-- gazebo extensions -->
  <gazebo reference="hokuyo_link">
    <sensor name="hokuyo" type="ray">
      <always_on>true</always_on>
      <update_rate>10</update_rate>
      <pose>0 0 0 0 0 0</pose>
      <visualize>false</visualize>
      <ray>
        <scan>
          <horizontal>
            <samples>512</samples>
            <resolution>1.0</resolution>
            <min_angle>-1.570796</min_angle>
            <max_angle>1.570796</max_angle>
          </horizontal>
        </scan>
        <range>
          <min>0.05</min>
          <max>6.0</max>
          <resolution>0.01</resolution>
        </range>
        <noise>
          <type>gaussian</type>
          <mean>0.0</mean>
          <stddev>0.005</stddev>
        </noise>
      </ray>
      <plugin filename="libgazebo_ros_laser.so" name="gazebo_ros_hokuyo_controller">
        <topicName>scan</topicName>
        <frameName>hokuyo_link</frameName>
      </plugin>
    </sensor>
    <material>Gazebo/White</material>
  </gazebo>
  <joint name="arm_base_joint" type="fixed">
    <parent link="base_linkz"/>
    <child link="arm_base_link"/>
    <axis xyz="0 0 1"/>
    <origin rpy="0.0 0.0 -1" xyz="0.0 -0.01591 0.32"/>
  </joint>
  <link name="arm_base_link">
    <inertial>
      <mass value="0.01"/>
      <origin xyz="0 0 0"/>
      <inertia ixx="0.001" ixy="0.0" ixz="0.0" iyy="0.001" iyz="0.0" izz="0.001"/>
    </inertial>
    <visual>
      <geometry>
        <mesh filename="package://robotino_description/meshes/arm/link0.stl"/>
      </geometry>
      <material name="white">
        <color rgba="1 1 1 1"/>
      </material>
      <origin rpy="0 0 0" xyz="0 0 0."/>
    </visual>
    <collision>
      <origin rpy="0 0 0" xyz="0 0 0."/>
      <geometry>
        <mesh filename="package://robotino_description/meshes/arm/link0_collision.stl"/>
      </geometry>
    </collision>
  </link>
  <joint name="arm_joint1" type="revolute">
    <parent link="arm_base_link"/>
    <child link="arm_link1"/>
    <origin rpy="0 0 0" xyz="0.0 0.0 0.0"/>
    <axis xyz="0 1 0"/>
    <limit effort="190" lower="-1.9" upper="1.9" velocity="30"/>
  </joint>
  <link name="arm_link1">
    <inertial>
      <mass value="0.01"/>
      <origin xyz="0 0 0"/>
      <inertia ixx="0.001" ixy="0.0" ixz="0.0" iyy="0.001" iyz="0.0" izz="0.001"/>
    </inertial>
    <visual>
      <geometry>
        <mesh filename="package://robotino_description/meshes/arm/link1.stl"/>
      </geometry>
      <material name="white"/>
      <origin rpy="0 0 0" xyz="0 0 0"/>
    </visual>
    <collision>
      <origin rpy="0 0 0" xyz="0 0 0"/>
      <geometry>
        <mesh filename="package://robotino_description/meshes/arm/link1_collision.stl"/>
      </geometry>
    </collision>
  </link>
  <gazebo reference="arm_link1">
    <material>Gazebo/White</material>
  </gazebo>
  <joint name="arm_joint2" type="revolute">
    <parent link="arm_link1"/>
    <child link="arm_motor2"/>
    <origin rpy="0 0 0" xyz="0.0 0.0 0.25"/>
    <axis xyz="0 1 0"/>
    <limit effort="190" lower="-1.9" upper="1.9" velocity="30"/>
  </joint>
  <link name="arm_motor2">
    <inertial>
      <mass value="0.01"/>
      <origin xyz="0 0 0"/>
      <inertia ixx="0.001" ixy="0.0" ixz="0.0" iyy="0.001" iyz="0.0" izz="0.001"/>
    </inertial>
    <visual>
      <geometry>
        <box size="0 0 0"/>
      </geometry>
      <material name="white"/>
      <origin rpy="0 0 0" xyz="0 0.0625 0."/>
    </visual>
  </link>
  <joint name="fixed_motor2_link2" type="fixed">
    <parent link="arm_motor2"/>
    <child link="arm_link2"/>
    <origin rpy="0 0 0" xyz="0.0 0.098 0.027"/>
  </joint>
  <link name="arm_link2">
    <inertial>
      <mass value="0.01"/>
      <origin xyz="0 0 0"/>
      <inertia ixx="0.001" ixy="0.0" ixz="0.0" iyy="0.001" iyz="0.0" izz="0.001"/>
    </inertial>
    <visual>
      <geometry>
        <mesh filename="package://robotino_description/meshes/arm/link2.stl"/>
      </geometry>
      <material name="white"/>
      <origin rpy="0 0 0" xyz="0 0 0"/>
    </visual>
    <collision>
      <origin rpy="0 0 0" xyz="0 0 0"/>
      <geometry>
        <mesh filename="package://robotino_description/meshes/arm/link2_collision.stl"/>
      </geometry>
    </collision>
  </link>
  <gazebo reference="arm_link2">
    <material>Gazebo/White</material>
  </gazebo>
  <joint name="arm_joint3" type="revolute">
    <parent link="arm_link2"/>
    <child link="arm_link3"/>
    <origin rpy="0 0 0" xyz="0.0 0.0 0.158"/>
    <axis xyz="0 0 1"/>
    <limit effort="190" lower="-1.7" upper="1.7" velocity="30"/>
  </joint>
  <link name="arm_link3">
    <inertial>
      <mass value="0.01"/>
      <origin xyz="0 0 0"/>
      <inertia ixx="0.001" ixy="0.0" ixz="0.0" iyy="0.001" iyz="0.0" izz="0.001"/>
    </inertial>
    <visual>
      <geometry>
        <mesh filename="package://robotino_description/meshes/arm/link3.stl"/>
      </geometry>
      <material name="white"/>
      <origin rpy="0 0 0" xyz="0 0 0"/>
    </visual>
    <collision>
      <origin rpy="0 0 0" xyz="0 0 0"/>
      <geometry>
        <mesh filename="package://robotino_description/meshes/arm/link3_collision.stl"/>
      </geometry>
    </collision>
  </link>
  <gazebo reference="arm_link3">
    <material>Gazebo/White</material>
  </gazebo>
  <joint name="arm_joint4" type="revolute">
    <parent link="arm_link3"/>
    <child link="arm_link4"/>
    <origin rpy="0 0 0" xyz="0.0 -0.057 0.065"/>
    <axis xyz="0 1 0"/>
    <limit effort="160" lower="-1.7" upper="1.7" velocity="30"/>
  </joint>
  <link name="arm_link4">
    <inertial>
      <mass value="0.01"/>
      <origin xyz="0 0 0"/>
      <inertia ixx="0.001" ixy="0.0" ixz="0.0" iyy="0.001" iyz="0.0" izz="0.001"/>
    </inertial>
    <visual>
      <geometry>
        <mesh filename="package://robotino_description/meshes/arm/link4.stl"/>
      </geometry>
      <material name="white"/>
      <origin rpy="0 0 0" xyz="0 0 0"/>
    </visual>
    <collision>
      <origin rpy="0 0 0" xyz="0 0 0"/>
      <geometry>
        <mesh filename="package://robotino_description/meshes/arm/link4_collision.stl"/>
      </geometry>
    </collision>
  </link>
  <gazebo reference="arm_link4">
    <material>Gazebo/White</material>
  </gazebo>
  <joint name="arm_joint5" type="revolute">
    <parent link="arm_link4"/>
    <child link="arm_link5"/>
    <origin rpy="0 0 0" xyz="0.0 -0.027 0.035"/>
    <axis xyz="0 0 1"/>
    <limit effort="160" lower="-1.7" upper="1.7" velocity="30"/>
  </joint>
  <link name="arm_link5">
    <inertial>
      <mass value="0.01"/>
      <origin xyz="0 0 0"/>
      <inertia ixx="0.001" ixy="0.0" ixz="0.0" iyy="0.001" iyz="0.0" izz="0.001"/>
    </inertial>
  </link>
  <gazebo reference="arm_link5">
    <material>Gazebo/White</material>
  </gazebo>
  <transmission name="arm_1_trans">
    <type>transmission_interface/SimpleTransmission</type>
    <joint name="arm_joint1">
      <hardwareInterface>PositionJointInterface</hardwareInterface>
    </joint>
    <actuator name="arm_1_motor">
      <mechanicalReduction>1</mechanicalReduction>
    </actuator>
  </transmission>
  <transmission name="arm_2_trans">
    <type>transmission_interface/SimpleTransmission</type>
    <joint name="arm_joint2">
      <hardwareInterface>PositionJointInterface</hardwareInterface>
    </joint>
    <actuator name="arm_2_motor">
      <mechanicalReduction>1</mechanicalReduction>
    </actuator>
  </transmission>
  <transmission name="arm_3_trans">
    <type>transmission_interface/SimpleTransmission</type>
    <joint name="arm_joint3">
      <hardwareInterface>PositionJointInterface</hardwareInterface>
    </joint>
    <actuator name="arm_3_motor">
      <mechanicalReduction>1</mechanicalReduction>
    </actuator>
  </transmission>
  <transmission name="arm_4_trans">
    <type>transmission_interface/SimpleTransmission</type>
    <joint name="arm_joint4">
      <hardwareInterface>PositionJointInterface</hardwareInterface>
    </joint>
    <actuator name="arm_4_motor">
      <mechanicalReduction>1</mechanicalReduction>
    </actuator>
  </transmission>
  <transmission name="arm_5_trans">
    <type>transmission_interface/SimpleTransmission</type>
    <joint name="arm_joint5">
      <hardwareInterface>PositionJointInterface</hardwareInterface>
    </joint>
    <actuator name="arm_5_motor">
      <mechanicalReduction>1</mechanicalReduction>
    </actuator>
  </transmission>
  <transmission name="arm_base_trans">
    <type>transmission_interface/SimpleTransmission</type>
    <joint name="arm_base_joint">
      <hardwareInterface>PositionJointInterface</hardwareInterface>
    </joint>
    <actuator name="arm_base_motor">
      <mechanicalReduction>1</mechanicalReduction>
    </actuator>
  </transmission>
  <gazebo>
    <plugin filename="libhwi_switch_gazebo_ros_control.so" name="ros_control">
      <robotNamespace>arm_controller</robotNamespace>
      <filterJointsParam>joint_names</filterJointsParam>
    </plugin>
  </gazebo>
  <!-- PACMAN VERION ALREADY INCLUDES THE COUPLER, CLAMP AND BASE -->
  <joint name="hand_wrist_joint" type="fixed">
    <origin rpy="1.5707963 0 0" xyz="0 0 0"/>
    <parent link="arm_link5"/>
    <child link="hand_wrist_link"/>
  </joint>
  <!--Original wrist with KCL F/T-->
  <link name="hand_wrist_link">
    <inertial>
      <mass value="0.01"/>
      <origin xyz="0 0 0"/>
      <inertia ixx="0.001" ixy="0.0" ixz="0.0" iyy="0.001" iyz="0.0" izz="0.001"/>
    </inertial>
    <visual>
      <origin rpy="1.5708 0 0" xyz="0 0 0"/>
      <geometry>
        <mesh filename="package://soft_hand_description/meshes/wrist.stl"/>
      </geometry>
      <material name="">
        <color rgba="0.79216 0.81961 0.93333 1"/>
      </material>
    </visual>
    <collision>
      <origin rpy="1.5708 0 0" xyz="0 0 0"/>
      <geometry>
        <mesh filename="package://soft_hand_description/meshes/wrist.stl"/>
      </geometry>
    </collision>
  </link>
  <joint name="hand_base_joint" type="fixed">
    <origin rpy="0 0.52 0" xyz="-0.02105 0.1485 0"/>
    <parent link="hand_wrist_link"/>
    <child link="hand_base_link"/>
  </joint>
  <!-- Angular adapter for SoftHand -->
  <link name="hand_base_link" parent="hand_wrist_link">
    <inertial>
      <mass value="0.01"/>
      <origin xyz="0 0 0"/>
      <inertia ixx="0.001" ixy="0.0" ixz="0.0" iyy="0.001" iyz="0.0" izz="0.001"/>
    </inertial>
    <visual>
      <origin rpy="3.14 0.7854 3.14" xyz="-0.02 -0.145 0.07"/>
      <geometry>
        <mesh filename="package://soft_hand_description/meshes/robotino_softhand_adapter_scaled.stl"/>
      </geometry>
      <material name="">
        <color rgba="0.79216 0.81961 0.93333 1"/>
      </material>
    </visual>
    <collision>
      <origin rpy="3.14 0.7854 3.14" xyz="-0.02 -0.145 0.07"/>
      <geometry>
        <mesh filename="package://soft_hand_description/meshes/robotino_softhand_adapter_scaled.stl"/>
      </geometry>
    </collision>
  </link>
  <!-- CLAMP -->
  <joint name="hand_base_link_hand_clamp_joint" type="fixed">
    <origin rpy="0 -0.7854 0" xyz="-0.02 -0.145 0.07"/>
    <parent link="hand_base_link"/>
    <child link="hand_clamp"/>
  </joint>
  <link name="hand_clamp">
    <visual>
      <origin rpy="0 0 0" xyz="0 0 0"/>
      <geometry>
        <mesh filename="package://soft_hand_description/meshes/accesories/clamp.stl"/>
      </geometry>
      <material name="SoftHand/Blue"/>
    </visual>
    <collision>
      <origin rpy="0 0 0" xyz="0 0 0"/>
      <geometry>
        <box size="0.066 0.0725 0.0256"/>
      </geometry>
    </collision>
  </link>
  <!-- SOFT HAND BASE -->
  <joint name="hand_clamp_hand_softhand_base_joint" type="fixed">
    <origin rpy="0 0 0" xyz="0 0 0.004"/>
    <parent link="hand_clamp"/>
    <child link="hand_softhand_base"/>
  </joint>
  <link name="hand_softhand_base">
    <visual>
      <origin rpy="0 0 0" xyz="0 0 0"/>
      <geometry>
        <mesh filename="package://soft_hand_description/meshes/accesories/softhand_base_right.stl"/>
      </geometry>
      <material name="SoftHand/Blue"/>
    </visual>
    <collision>
      <origin rpy="0 0 0" xyz="0 0 0.031"/>
      <geometry>
        <box size="0.066 0.066 0.062"/>
      </geometry>
    </collision>
  </link>
  <!-- PALM -->
  <joint name="hand_palm_joint" type="fixed">
    <origin rpy="0 0 0" xyz="0.002 0.00695 0.0535"/>
    <parent link="hand_softhand_base"/>
    <child link="hand_palm_link"/>
  </joint>
  <link name="hand_palm_link">
    <inertial>
      <origin xyz="-0.004568758 -0.006808116 0.027653328"/>
      <mass value="2.28"/>
      <inertia ixx="1.6302" ixy="0.0228" ixz="0.0228" iyy="0.9462" iyz="0.0456" izz="1.1058"/>
    </inertial>
    <visual>
      <geometry>
        <mesh filename="package://soft_hand_description/meshes/palm_right.stl" scale=" .001 .001 .001"/>
      </geometry>
      <material name="SoftHand/DarkGrey"/>
    </visual>
    <collision>
      <geometry>
        <mesh filename="package://soft_hand_description/meshes/palm_right_collision.stl" scale=" .001 .001 .001"/>
      </geometry>
    </collision>
  </link>
  <!-- MOTOR JOINT -->
  <joint name="hand_synergy_joint" type="revolute">
    <parent link="hand_palm_link"/>
    <child link="hand_invisible_wire_link"/>
    <axis xyz="0 0 1"/>
    <limit effort="100" lower="0.0" upper="1.0" velocity="100000"/>
    <dynamics damping="0.0" friction="0.0"/>
  </joint>
  <link name="hand_invisible_wire_link">
    <inertial>
      <origin xyz="0 0 0"/>
      <mass value="0.1"/>
      <inertia ixx="0.001" ixy="0.0" ixz="0.0" iyy="0.001" iyz="0.0" izz="0.001"/>
    </inertial>
  </link>
  <!-- THUMB AND FINGERS -->
  <!-- change anchor points accordingly to the leftness -->
  <!-- KNUCKLE -->
  <joint name="hand_thumb_abd_joint" type="revolute">
    <origin rpy="0.0 -0.38397275793662144 1.5707963267948966" xyz="0.00566972 0.0296160 0.0553140"/>
    <parent link="hand_palm_link"/>
    <child link="hand_thumb_knuckle_link"/>
    <axis xyz="0 0 -1"/>
    <limit effort="100" lower="0.0" upper="1.57079632679" velocity="100"/>
    <dynamics damping="0.0" friction="0.0"/>
  </joint>
  <link name="hand_thumb_knuckle_link">
    <inertial>
      <origin xyz="0.013608098 -0.000532174 -0.000216691"/>
      <mass value="0.09"/>
      <inertia ixx="0.00315" ixy="0.00027" ixz="-0.00054" iyy="0.009" iyz="0.00018" izz="0.009"/>
    </inertial>
    <visual>
      <geometry>
        <mesh filename="package://soft_hand_description/meshes/thumb_knuckle_right.stl" scale=" .001 .001 .001"/>
      </geometry>
      <material name="SoftHand/DarkGrey"/>
    </visual>
    <collision>
      <geometry>
        <mesh filename="package://soft_hand_description/meshes/thumb_knuckle_right_collision.stl" scale=" .001 .001 .001"/>
      </geometry>
    </collision>
  </link>
  <!-- PROXIMAL PHALANGE -->
  <joint name="hand_thumb_inner_joint" type="revolute">
    <!-- <origin xyz="0.022500000 -0.003300000 0.0" rpy="0.42662757656587236 0.0 0.18131960430075023" /> -->
    <origin rpy="0.42662757656587236 0.0 0.0" xyz="0.022500000 -0.003300000 0.0"/>
    <parent link="hand_thumb_knuckle_link"/>
    <child link="hand_thumb_fake_link1"/>
    <axis xyz="0 -1 0"/>
    <limit effort="100" lower="0.0" upper="0.785398163397" velocity="100"/>
    <dynamics damping="0.0" friction="0.0"/>
  </joint>
  <link name="hand_thumb_fake_link1">
    <inertial>
      <origin xyz="0 0 0"/>
      <mass value="0.1"/>
      <inertia ixx="0.001" ixy="0.0" ixz="0.0" iyy="0.001" iyz="0.0" izz="0.001"/>
    </inertial>
  </link>
  <joint name="hand_thumb_inner_joint_mimic" type="revolute">
    <origin rpy="0 0 0" xyz="0.013 0 0"/>
    <parent link="hand_thumb_fake_link1"/>
    <child link="hand_thumb_proximal_link"/>
    <axis xyz="0 -1 0"/>
    <limit effort="100" lower="0.0" upper="0.785398163397" velocity="100"/>
    <dynamics damping="0.0" friction="0.0"/>
  </joint>
  <link name="hand_thumb_proximal_link">
    <inertial>
      <origin xyz="0.005074337 -4.524e-06 -0.000262953"/>
      <mass value="0.05"/>
      <inertia ixx="0.00175" ixy="0.0" ixz="0.0001" iyy="0.00275" iyz="0.0" izz="0.00275"/>
    </inertial>
    <visual>
      <geometry>
        <mesh filename="package://soft_hand_description/meshes/phalanx.stl" scale=" .001 .001 .001"/>
      </geometry>
      <material name="SoftHand/DarkGrey"/>
    </visual>
    <collision>
      <geometry>
        <mesh filename="package://soft_hand_description/meshes/phalanx_collision.stl" scale=" .001 .001 .001"/>
      </geometry>
    </collision>
  </link>
  <!-- DISTAL PHALANGE -->
  <joint name="hand_thumb_outer_joint" type="revolute">
    <origin rpy="0 0 0" xyz="0.009 0 0.0"/>
    <parent link="hand_thumb_proximal_link"/>
    <child link="hand_thumb_fake_link3"/>
    <axis xyz="0 -1 0"/>
    <limit effort="100" lower="0.0" upper="0.785398163397" velocity="100"/>
    <dynamics damping="0.0" friction="0.0"/>
  </joint>
  <link name="hand_thumb_fake_link3">
    <inertial>
      <origin xyz="0 0 0"/>
      <mass value="0.1"/>
      <inertia ixx="0.001" ixy="0.0" ixz="0.0" iyy="0.001" iyz="0.0" izz="0.001"/>
    </inertial>
  </link>
  <joint name="hand_thumb_outer_joint_mimic" type="revolute">
    <origin rpy="0 0 0" xyz="0.013 0 0"/>
    <parent link="hand_thumb_fake_link3"/>
    <child link="hand_thumb_distal_link"/>
    <axis xyz="0 -1 0"/>
    <limit effort="100" lower="0.0" upper="0.785398163397" velocity="100"/>
    <dynamics damping="0.0" friction="0.0"/>
  </joint>
  <link name="hand_thumb_distal_link">
    <inertial>
      <origin xyz="0.009849094 5.6e-07 0.000820286"/>
      <mass value="0.1"/>
      <inertia ixx="0.0035" ixy="0.0" ixz="0.0002" iyy="0.008" iyz="0.0" izz="0.0076"/>
    </inertial>
    <visual>
      <geometry>
        <mesh filename="package://soft_hand_description/meshes/fingertip.stl" scale=" .001 .001 .001"/>
      </geometry>
      <material name="SoftHand/DarkGrey"/>
    </visual>
    <collision>
      <geometry>
        <mesh filename="package://soft_hand_description/meshes/fingertip_collision.stl" scale=" .001 .001 .001"/>
      </geometry>
    </collision>
  </link>
  <!-- KNUCKLE -->
  <joint name="hand_index_abd_joint" type="revolute">
    <origin rpy="1.5707963267948966 -1.4835299330931884 1.5707963267948966" xyz="-0.0033 0.0195 0.0936994"/>
    <parent link="hand_palm_link"/>
    <child link="hand_index_knuckle_link"/>
    <axis xyz="0 0 1"/>
    <limit effort="100" lower="-0.523598775598" upper="0.523598775598" velocity="100"/>
    <dynamics damping="0.0" friction="0.0"/>
  </joint>
  <link name="hand_index_knuckle_link">
    <inertial>
      <origin xyz="0.001285644 -9.58e-07 0.000425011"/>
      <mass value="0.09"/>
      <inertia ixx="0.00405" ixy="0.0" ixz="0.00045" iyy="0.0081" iyz="0.0" izz="0.0063"/>
    </inertial>
    <visual>
      <geometry>
        <mesh filename="package://soft_hand_description/meshes/knuckle.stl" scale=" .001 .001 .001"/>
      </geometry>
      <material name="SoftHand/DarkGrey"/>
    </visual>
    <collision>
      <geometry>
        <mesh filename="package://soft_hand_description/meshes/knuckle_collision.stl" scale=" .001 .001 .001"/>
      </geometry>
    </collision>
  </link>
  <!-- PROXIMAL PHALANGE -->
  <joint name="hand_index_inner_joint" type="revolute">
    <origin rpy="0 0 0" xyz="0.009 0 0"/>
    <parent link="hand_index_knuckle_link"/>
    <child link="hand_index_fake_link1"/>
    <axis xyz="0 -1 0"/>
    <limit effort="100" lower="0.0" upper="0.785398163397" velocity="100"/>
    <dynamics damping="0.0" friction="0.0"/>
  </joint>
  <link name="hand_index_fake_link1">
    <inertial>
      <origin xyz="0 0 0"/>
      <mass value="0.1"/>
      <inertia ixx="0.001" ixy="0.0" ixz="0.0" iyy="0.001" iyz="0.0" izz="0.001"/>
    </inertial>
  </link>
  <joint name="hand_index_inner_joint_mimic" type="revolute">
    <origin rpy="0 0 0" xyz="0.013 0 0"/>
    <parent link="hand_index_fake_link1"/>
    <child link="hand_index_proximal_link"/>
    <axis xyz="0 -1 0"/>
    <limit effort="100" lower="0.0" upper="0.785398163397" velocity="100"/>
    <dynamics damping="0.0" friction="0.0"/>
  </joint>
  <link name="hand_index_proximal_link">
    <inertial>
      <origin xyz="0.005074337 -4.524e-06 -0.000262953"/>
      <mass value="0.05"/>
      <inertia ixx="0.00175" ixy="0.0" ixz="0.0001" iyy="0.00275" iyz="0.0" izz="0.00275"/>
    </inertial>
    <visual>
      <geometry>
        <mesh filename="package://soft_hand_description/meshes/phalanx.stl" scale=" .001 .001 .001"/>
      </geometry>
      <material name="SoftHand/DarkGrey"/>
    </visual>
    <collision>
      <geometry>
        <mesh filename="package://soft_hand_description/meshes/phalanx_collision.stl" scale=" .001 .001 .001"/>
      </geometry>
    </collision>
  </link>
  <!-- MIDDLE PHALANGE -->
  <joint name="hand_index_middle_joint" type="revolute">
    <origin rpy="0 0 0" xyz="0.009 0 0"/>
    <parent link="hand_index_proximal_link"/>
    <child link="hand_index_fake_link2"/>
    <axis xyz="0 -1 0"/>
    <limit effort="100" lower="0.0" upper="0.785398163397" velocity="100"/>
    <dynamics damping="0.0" friction="0.0"/>
  </joint>
  <link name="hand_index_fake_link2">
    <inertial>
      <origin xyz="0 0 0"/>
      <mass value="0.1"/>
      <inertia ixx="0.001" ixy="0.0" ixz="0.0" iyy="0.001" iyz="0.0" izz="0.001"/>
    </inertial>
  </link>
  <joint name="hand_index_middle_joint_mimic" type="revolute">
    <origin rpy="0 0 0" xyz="0.013 0 0"/>
    <parent link="hand_index_fake_link2"/>
    <child link="hand_index_middle_link"/>
    <axis xyz="0 -1 0"/>
    <limit effort="100" lower="0.0" upper="0.785398163397" velocity="100"/>
    <dynamics damping="0.0" friction="0.0"/>
  </joint>
  <link name="hand_index_middle_link">
    <inertial>
      <origin xyz="0.005074337 -4.524e-06 -0.000262953"/>
      <mass value="0.05"/>
      <inertia ixx="0.00175" ixy="0.0" ixz="0.0001" iyy="0.00275" iyz="0.0" izz="0.00275"/>
    </inertial>
    <visual>
      <geometry>
        <mesh filename="package://soft_hand_description/meshes/phalanx.stl" scale=" .001 .001 .001"/>
      </geometry>
      <material name="SoftHand/DarkGrey"/>
    </visual>
    <collision>
      <geometry>
        <mesh filename="package://soft_hand_description/meshes/phalanx_collision.stl" scale=" .001 .001 .001"/>
      </geometry>
    </collision>
  </link>
  <!-- DISTAL PHALANGE -->
  <joint name="hand_index_outer_joint" type="revolute">
    <origin rpy="0 0 0" xyz="0.009 0 0"/>
    <parent link="hand_index_middle_link"/>
    <child link="hand_index_fake_link3"/>
    <axis xyz="0 -1 0"/>
    <limit effort="100" lower="0.0" upper="0.785398163397" velocity="100"/>
    <dynamics damping="0.0" friction="0.0"/>
  </joint>
  <link name="hand_index_fake_link3">
    <inertial>
      <origin xyz="0 0 0"/>
      <mass value="0.1"/>
      <inertia ixx="0.001" ixy="0.0" ixz="0.0" iyy="0.001" iyz="0.0" izz="0.001"/>
    </inertial>
  </link>
  <joint name="hand_index_outer_joint_mimic" type="revolute">
    <origin rpy="0 0 0" xyz="0.013 0 0"/>
    <parent link="hand_index_fake_link3"/>
    <child link="hand_index_distal_link"/>
    <axis xyz="0 -1 0"/>
    <limit effort="100" lower="0.0" upper="0.785398163397" velocity="100"/>
    <dynamics damping="0.0" friction="0.0"/>
  </joint>
  <link name="hand_index_distal_link">
    <inertial>
      <origin xyz="0.009849094 5.6e-07 0.000820286"/>
      <mass value="0.1"/>
      <inertia ixx="0.0035" ixy="0.0" ixz="0.0002" iyy="0.008" iyz="0.0" izz="0.0076"/>
    </inertial>
    <visual>
      <geometry>
        <mesh filename="package://soft_hand_description/meshes/fingertip.stl" scale=" .001 .001 .001"/>
      </geometry>
      <material name="SoftHand/DarkGrey"/>
    </visual>
    <collision>
      <geometry>
        <mesh filename="package://soft_hand_description/meshes/fingertip_collision.stl" scale=" .001 .001 .001"/>
      </geometry>
    </collision>
  </link>
  <!-- KNUCKLE -->
  <joint name="hand_middle_abd_joint" type="revolute">
    <origin rpy="3.141592 -1.5707963267948966 0.0" xyz="-0.003300000 0.0 0.100699"/>
    <parent link="hand_palm_link"/>
    <child link="hand_middle_knuckle_link"/>
    <axis xyz="0 0 1"/>
    <limit effort="100" lower="-0.523598775598" upper="0.523598775598" velocity="100"/>
    <dynamics damping="0.0" friction="0.0"/>
  </joint>
  <link name="hand_middle_knuckle_link">
    <inertial>
      <origin xyz="0.001285644 -9.58e-07 0.000425011"/>
      <mass value="0.09"/>
      <inertia ixx="0.00405" ixy="0.0" ixz="0.00045" iyy="0.0081" iyz="0.0" izz="0.0063"/>
    </inertial>
    <visual>
      <geometry>
        <mesh filename="package://soft_hand_description/meshes/knuckle.stl" scale=" .001 .001 .001"/>
      </geometry>
      <material name="SoftHand/DarkGrey"/>
    </visual>
    <collision>
      <geometry>
        <mesh filename="package://soft_hand_description/meshes/knuckle_collision.stl" scale=" .001 .001 .001"/>
      </geometry>
    </collision>
  </link>
  <!-- PROXIMAL PHALANGE -->
  <joint name="hand_middle_inner_joint" type="revolute">
    <origin rpy="0 0 0" xyz="0.009 0 0"/>
    <parent link="hand_middle_knuckle_link"/>
    <child link="hand_middle_fake_link1"/>
    <axis xyz="0 -1 0"/>
    <limit effort="100" lower="0.0" upper="0.785398163397" velocity="100"/>
    <dynamics damping="0.0" friction="0.0"/>
  </joint>
  <link name="hand_middle_fake_link1">
    <inertial>
      <origin xyz="0 0 0"/>
      <mass value="0.1"/>
      <inertia ixx="0.001" ixy="0.0" ixz="0.0" iyy="0.001" iyz="0.0" izz="0.001"/>
    </inertial>
  </link>
  <joint name="hand_middle_inner_joint_mimic" type="revolute">
    <origin rpy="0 0 0" xyz="0.013 0 0"/>
    <parent link="hand_middle_fake_link1"/>
    <child link="hand_middle_proximal_link"/>
    <axis xyz="0 -1 0"/>
    <limit effort="100" lower="0.0" upper="0.785398163397" velocity="100"/>
    <dynamics damping="0.0" friction="0.0"/>
  </joint>
  <link name="hand_middle_proximal_link">
    <inertial>
      <origin xyz="0.005074337 -4.524e-06 -0.000262953"/>
      <mass value="0.05"/>
      <inertia ixx="0.00175" ixy="0.0" ixz="0.0001" iyy="0.00275" iyz="0.0" izz="0.00275"/>
    </inertial>
    <visual>
      <geometry>
        <mesh filename="package://soft_hand_description/meshes/phalanx.stl" scale=" .001 .001 .001"/>
      </geometry>
      <material name="SoftHand/DarkGrey"/>
    </visual>
    <collision>
      <geometry>
        <mesh filename="package://soft_hand_description/meshes/phalanx_collision.stl" scale=" .001 .001 .001"/>
      </geometry>
    </collision>
  </link>
  <!-- MIDDLE PHALANGE -->
  <joint name="hand_middle_middle_joint" type="revolute">
    <origin rpy="0 0 0" xyz="0.009 0 0"/>
    <parent link="hand_middle_proximal_link"/>
    <child link="hand_middle_fake_link2"/>
    <axis xyz="0 -1 0"/>
    <limit effort="100" lower="0.0" upper="0.785398163397" velocity="100"/>
    <dynamics damping="0.0" friction="0.0"/>
  </joint>
  <link name="hand_middle_fake_link2">
    <inertial>
      <origin xyz="0 0 0"/>
      <mass value="0.1"/>
      <inertia ixx="0.001" ixy="0.0" ixz="0.0" iyy="0.001" iyz="0.0" izz="0.001"/>
    </inertial>
  </link>
  <joint name="hand_middle_middle_joint_mimic" type="revolute">
    <origin rpy="0 0 0" xyz="0.013 0 0"/>
    <parent link="hand_middle_fake_link2"/>
    <child link="hand_middle_middle_link"/>
    <axis xyz="0 -1 0"/>
    <limit effort="100" lower="0.0" upper="0.785398163397" velocity="100"/>
    <dynamics damping="0.0" friction="0.0"/>
  </joint>
  <link name="hand_middle_middle_link">
    <inertial>
      <origin xyz="0.005074337 -4.524e-06 -0.000262953"/>
      <mass value="0.05"/>
      <inertia ixx="0.00175" ixy="0.0" ixz="0.0001" iyy="0.00275" iyz="0.0" izz="0.00275"/>
    </inertial>
    <visual>
      <geometry>
        <mesh filename="package://soft_hand_description/meshes/phalanx.stl" scale=" .001 .001 .001"/>
      </geometry>
      <material name="SoftHand/DarkGrey"/>
    </visual>
    <collision>
      <geometry>
        <mesh filename="package://soft_hand_description/meshes/phalanx_collision.stl" scale=" .001 .001 .001"/>
      </geometry>
    </collision>
  </link>
  <!-- DISTAL PHALANGE -->
  <joint name="hand_middle_outer_joint" type="revolute">
    <origin rpy="0 0 0" xyz="0.009 0 0"/>
    <parent link="hand_middle_middle_link"/>
    <child link="hand_middle_fake_link3"/>
    <axis xyz="0 -1 0"/>
    <limit effort="100" lower="0.0" upper="0.785398163397" velocity="100"/>
    <dynamics damping="0.0" friction="0.0"/>
  </joint>
  <link name="hand_middle_fake_link3">
    <inertial>
      <origin xyz="0 0 0"/>
      <mass value="0.1"/>
      <inertia ixx="0.001" ixy="0.0" ixz="0.0" iyy="0.001" iyz="0.0" izz="0.001"/>
    </inertial>
  </link>
  <joint name="hand_middle_outer_joint_mimic" type="revolute">
    <origin rpy="0 0 0" xyz="0.013 0 0"/>
    <parent link="hand_middle_fake_link3"/>
    <child link="hand_middle_distal_link"/>
    <axis xyz="0 -1 0"/>
    <limit effort="100" lower="0.0" upper="0.785398163397" velocity="100"/>
    <dynamics damping="0.0" friction="0.0"/>
  </joint>
  <link name="hand_middle_distal_link">
    <inertial>
      <origin xyz="0.009849094 5.6e-07 0.000820286"/>
      <mass value="0.1"/>
      <inertia ixx="0.0035" ixy="0.0" ixz="0.0002" iyy="0.008" iyz="0.0" izz="0.0076"/>
    </inertial>
    <visual>
      <geometry>
        <mesh filename="package://soft_hand_description/meshes/fingertip.stl" scale=" .001 .001 .001"/>
      </geometry>
      <material name="SoftHand/DarkGrey"/>
    </visual>
    <collision>
      <geometry>
        <mesh filename="package://soft_hand_description/meshes/fingertip_collision.stl" scale=" .001 .001 .001"/>
      </geometry>
    </collision>
  </link>
  <!-- KNUCKLE -->
  <joint name="hand_ring_abd_joint" type="revolute">
    <origin rpy="-1.5707963267948966 -1.5184364298870514 -1.5707963267948966 " xyz="-0.0033 -0.0195 0.0936994"/>
    <parent link="hand_palm_link"/>
    <child link="hand_ring_knuckle_link"/>
    <axis xyz="0 0 1"/>
    <limit effort="100" lower="-0.523598775598" upper="0.523598775598" velocity="100"/>
    <dynamics damping="0.0" friction="0.0"/>
  </joint>
  <link name="hand_ring_knuckle_link">
    <inertial>
      <origin xyz="0.001285644 -9.58e-07 0.000425011"/>
      <mass value="0.09"/>
      <inertia ixx="0.00405" ixy="0.0" ixz="0.00045" iyy="0.0081" iyz="0.0" izz="0.0063"/>
    </inertial>
    <visual>
      <geometry>
        <mesh filename="package://soft_hand_description/meshes/knuckle.stl" scale=" .001 .001 .001"/>
      </geometry>
      <material name="SoftHand/DarkGrey"/>
    </visual>
    <collision>
      <geometry>
        <mesh filename="package://soft_hand_description/meshes/knuckle_collision.stl" scale=" .001 .001 .001"/>
      </geometry>
    </collision>
  </link>
  <!-- PROXIMAL PHALANGE -->
  <joint name="hand_ring_inner_joint" type="revolute">
    <origin rpy="0 0 0" xyz="0.009 0 0"/>
    <parent link="hand_ring_knuckle_link"/>
    <child link="hand_ring_fake_link1"/>
    <axis xyz="0 -1 0"/>
    <limit effort="100" lower="0.0" upper="0.785398163397" velocity="100"/>
    <dynamics damping="0.0" friction="0.0"/>
  </joint>
  <link name="hand_ring_fake_link1">
    <inertial>
      <origin xyz="0 0 0"/>
      <mass value="0.1"/>
      <inertia ixx="0.001" ixy="0.0" ixz="0.0" iyy="0.001" iyz="0.0" izz="0.001"/>
    </inertial>
  </link>
  <joint name="hand_ring_inner_joint_mimic" type="revolute">
    <origin rpy="0 0 0" xyz="0.013 0 0"/>
    <parent link="hand_ring_fake_link1"/>
    <child link="hand_ring_proximal_link"/>
    <axis xyz="0 -1 0"/>
    <limit effort="100" lower="0.0" upper="0.785398163397" velocity="100"/>
    <dynamics damping="0.0" friction="0.0"/>
  </joint>
  <link name="hand_ring_proximal_link">
    <inertial>
      <origin xyz="0.005074337 -4.524e-06 -0.000262953"/>
      <mass value="0.05"/>
      <inertia ixx="0.00175" ixy="0.0" ixz="0.0001" iyy="0.00275" iyz="0.0" izz="0.00275"/>
    </inertial>
    <visual>
      <geometry>
        <mesh filename="package://soft_hand_description/meshes/phalanx.stl" scale=" .001 .001 .001"/>
      </geometry>
      <material name="SoftHand/DarkGrey"/>
    </visual>
    <collision>
      <geometry>
        <mesh filename="package://soft_hand_description/meshes/phalanx_collision.stl" scale=" .001 .001 .001"/>
      </geometry>
    </collision>
  </link>
  <!-- MIDDLE PHALANGE -->
  <joint name="hand_ring_middle_joint" type="revolute">
    <origin rpy="0 0 0" xyz="0.009 0 0"/>
    <parent link="hand_ring_proximal_link"/>
    <child link="hand_ring_fake_link2"/>
    <axis xyz="0 -1 0"/>
    <limit effort="100" lower="0.0" upper="0.785398163397" velocity="100"/>
    <dynamics damping="0.0" friction="0.0"/>
  </joint>
  <link name="hand_ring_fake_link2">
    <inertial>
      <origin xyz="0 0 0"/>
      <mass value="0.1"/>
      <inertia ixx="0.001" ixy="0.0" ixz="0.0" iyy="0.001" iyz="0.0" izz="0.001"/>
    </inertial>
  </link>
  <joint name="hand_ring_middle_joint_mimic" type="revolute">
    <origin rpy="0 0 0" xyz="0.013 0 0"/>
    <parent link="hand_ring_fake_link2"/>
    <child link="hand_ring_middle_link"/>
    <axis xyz="0 -1 0"/>
    <limit effort="100" lower="0.0" upper="0.785398163397" velocity="100"/>
    <dynamics damping="0.0" friction="0.0"/>
  </joint>
  <link name="hand_ring_middle_link">
    <inertial>
      <origin xyz="0.005074337 -4.524e-06 -0.000262953"/>
      <mass value="0.05"/>
      <inertia ixx="0.00175" ixy="0.0" ixz="0.0001" iyy="0.00275" iyz="0.0" izz="0.00275"/>
    </inertial>
    <visual>
      <geometry>
        <mesh filename="package://soft_hand_description/meshes/phalanx.stl" scale=" .001 .001 .001"/>
      </geometry>
      <material name="SoftHand/DarkGrey"/>
    </visual>
    <collision>
      <geometry>
        <mesh filename="package://soft_hand_description/meshes/phalanx_collision.stl" scale=" .001 .001 .001"/>
      </geometry>
    </collision>
  </link>
  <!-- DISTAL PHALANGE -->
  <joint name="hand_ring_outer_joint" type="revolute">
    <origin rpy="0 0 0" xyz="0.009 0 0"/>
    <parent link="hand_ring_middle_link"/>
    <child link="hand_ring_fake_link3"/>
    <axis xyz="0 -1 0"/>
    <limit effort="100" lower="0.0" upper="0.785398163397" velocity="100"/>
    <dynamics damping="0.0" friction="0.0"/>
  </joint>
  <link name="hand_ring_fake_link3">
    <inertial>
      <origin xyz="0 0 0"/>
      <mass value="0.1"/>
      <inertia ixx="0.001" ixy="0.0" ixz="0.0" iyy="0.001" iyz="0.0" izz="0.001"/>
    </inertial>
  </link>
  <joint name="hand_ring_outer_joint_mimic" type="revolute">
    <origin rpy="0 0 0" xyz="0.013 0 0"/>
    <parent link="hand_ring_fake_link3"/>
    <child link="hand_ring_distal_link"/>
    <axis xyz="0 -1 0"/>
    <limit effort="100" lower="0.0" upper="0.785398163397" velocity="100"/>
    <dynamics damping="0.0" friction="0.0"/>
  </joint>
  <link name="hand_ring_distal_link">
    <inertial>
      <origin xyz="0.009849094 5.6e-07 0.000820286"/>
      <mass value="0.1"/>
      <inertia ixx="0.0035" ixy="0.0" ixz="0.0002" iyy="0.008" iyz="0.0" izz="0.0076"/>
    </inertial>
    <visual>
      <geometry>
        <mesh filename="package://soft_hand_description/meshes/fingertip.stl" scale=" .001 .001 .001"/>
      </geometry>
      <material name="SoftHand/DarkGrey"/>
    </visual>
    <collision>
      <geometry>
        <mesh filename="package://soft_hand_description/meshes/fingertip_collision.stl" scale=" .001 .001 .001"/>
      </geometry>
    </collision>
  </link>
  <!-- KNUCKLE -->
  <joint name="hand_little_abd_joint" type="revolute">
    <origin rpy="-1.5707963267948966 -1.4835299330931884 -1.5707963267948966" xyz="-0.0033 -0.039 0.0836994"/>
    <parent link="hand_palm_link"/>
    <child link="hand_little_knuckle_link"/>
    <axis xyz="0 0 1"/>
    <limit effort="100" lower="-0.523598775598" upper="0.523598775598" velocity="100"/>
    <dynamics damping="0.0" friction="0.0"/>
  </joint>
  <link name="hand_little_knuckle_link">
    <inertial>
      <origin xyz="0.001285644 -9.58e-07 0.000425011"/>
      <mass value="0.09"/>
      <inertia ixx="0.00405" ixy="0.0" ixz="0.00045" iyy="0.0081" iyz="0.0" izz="0.0063"/>
    </inertial>
    <visual>
      <geometry>
        <mesh filename="package://soft_hand_description/meshes/knuckle.stl" scale=" .001 .001 .001"/>
      </geometry>
      <material name="SoftHand/DarkGrey"/>
    </visual>
    <collision>
      <geometry>
        <mesh filename="package://soft_hand_description/meshes/knuckle_collision.stl" scale=" .001 .001 .001"/>
      </geometry>
    </collision>
  </link>
  <!-- PROXIMAL PHALANGE -->
  <joint name="hand_little_inner_joint" type="revolute">
    <origin rpy="0 0 0" xyz="0.009 0 0"/>
    <parent link="hand_little_knuckle_link"/>
    <child link="hand_little_fake_link1"/>
    <axis xyz="0 -1 0"/>
    <limit effort="100" lower="0.0" upper="0.785398163397" velocity="100"/>
    <dynamics damping="0.0" friction="0.0"/>
  </joint>
  <link name="hand_little_fake_link1">
    <inertial>
      <origin xyz="0 0 0"/>
      <mass value="0.1"/>
      <inertia ixx="0.001" ixy="0.0" ixz="0.0" iyy="0.001" iyz="0.0" izz="0.001"/>
    </inertial>
  </link>
  <joint name="hand_little_inner_joint_mimic" type="revolute">
    <origin rpy="0 0 0" xyz="0.013 0 0"/>
    <parent link="hand_little_fake_link1"/>
    <child link="hand_little_proximal_link"/>
    <axis xyz="0 -1 0"/>
    <limit effort="100" lower="0.0" upper="0.785398163397" velocity="100"/>
    <dynamics damping="0.0" friction="0.0"/>
  </joint>
  <link name="hand_little_proximal_link">
    <inertial>
      <origin xyz="0.005074337 -4.524e-06 -0.000262953"/>
      <mass value="0.05"/>
      <inertia ixx="0.00175" ixy="0.0" ixz="0.0001" iyy="0.00275" iyz="0.0" izz="0.00275"/>
    </inertial>
    <visual>
      <geometry>
        <mesh filename="package://soft_hand_description/meshes/phalanx.stl" scale=" .001 .001 .001"/>
      </geometry>
      <material name="SoftHand/DarkGrey"/>
    </visual>
    <collision>
      <geometry>
        <mesh filename="package://soft_hand_description/meshes/phalanx_collision.stl" scale=" .001 .001 .001"/>
      </geometry>
    </collision>
  </link>
  <!-- MIDDLE PHALANGE -->
  <joint name="hand_little_middle_joint" type="revolute">
    <origin rpy="0 0 0" xyz="0.009 0 0"/>
    <parent link="hand_little_proximal_link"/>
    <child link="hand_little_fake_link2"/>
    <axis xyz="0 -1 0"/>
    <limit effort="100" lower="0.0" upper="0.785398163397" velocity="100"/>
    <dynamics damping="0.0" friction="0.0"/>
  </joint>
  <link name="hand_little_fake_link2">
    <inertial>
      <origin xyz="0 0 0"/>
      <mass value="0.1"/>
      <inertia ixx="0.001" ixy="0.0" ixz="0.0" iyy="0.001" iyz="0.0" izz="0.001"/>
    </inertial>
  </link>
  <joint name="hand_little_middle_joint_mimic" type="revolute">
    <origin rpy="0 0 0" xyz="0.013 0 0"/>
    <parent link="hand_little_fake_link2"/>
    <child link="hand_little_middle_link"/>
    <axis xyz="0 -1 0"/>
    <limit effort="100" lower="0.0" upper="0.785398163397" velocity="100"/>
    <dynamics damping="0.0" friction="0.0"/>
  </joint>
  <link name="hand_little_middle_link">
    <inertial>
      <origin xyz="0.005074337 -4.524e-06 -0.000262953"/>
      <mass value="0.05"/>
      <inertia ixx="0.00175" ixy="0.0" ixz="0.0001" iyy="0.00275" iyz="0.0" izz="0.00275"/>
    </inertial>
    <visual>
      <geometry>
        <mesh filename="package://soft_hand_description/meshes/phalanx.stl" scale=" .001 .001 .001"/>
      </geometry>
      <material name="SoftHand/DarkGrey"/>
    </visual>
    <collision>
      <geometry>
        <mesh filename="package://soft_hand_description/meshes/phalanx_collision.stl" scale=" .001 .001 .001"/>
      </geometry>
    </collision>
  </link>
  <!-- DISTAL PHALANGE -->
  <joint name="hand_little_outer_joint" type="revolute">
    <origin rpy="0 0 0" xyz="0.009 0 0"/>
    <parent link="hand_little_middle_link"/>
    <child link="hand_little_fake_link3"/>
    <axis xyz="0 -1 0"/>
    <limit effort="100" lower="0.0" upper="0.785398163397" velocity="100"/>
    <dynamics damping="0.0" friction="0.0"/>
  </joint>
  <link name="hand_little_fake_link3">
    <inertial>
      <origin xyz="0 0 0"/>
      <mass value="0.1"/>
      <inertia ixx="0.001" ixy="0.0" ixz="0.0" iyy="0.001" iyz="0.0" izz="0.001"/>
    </inertial>
  </link>
  <joint name="hand_little_outer_joint_mimic" type="revolute">
    <origin rpy="0 0 0" xyz="0.013 0 0"/>
    <parent link="hand_little_fake_link3"/>
    <child link="hand_little_distal_link"/>
    <axis xyz="0 -1 0"/>
    <limit effort="100" lower="0.0" upper="0.785398163397" velocity="100"/>
    <dynamics damping="0.0" friction="0.0"/>
  </joint>
  <link name="hand_little_distal_link">
    <inertial>
      <origin xyz="0.009849094 5.6e-07 0.000820286"/>
      <mass value="0.1"/>
      <inertia ixx="0.0035" ixy="0.0" ixz="0.0002" iyy="0.008" iyz="0.0" izz="0.0076"/>
    </inertial>
    <visual>
      <geometry>
        <mesh filename="package://soft_hand_description/meshes/fingertip.stl" scale=" .001 .001 .001"/>
      </geometry>
      <material name="SoftHand/DarkGrey"/>
    </visual>
    <collision>
      <geometry>
        <mesh filename="package://soft_hand_description/meshes/fingertip_collision.stl" scale=" .001 .001 .001"/>
      </geometry>
    </collision>
  </link>
  <transmission name="hand_thumb_abd_trans">
    <robotNamespace>hand</robotNamespace>
    <type>transmission_interface/SimpleTransmission</type>
    <joint name="hand_thumb_abd_joint">
      <hardwareInterface>EffortJointInterface</hardwareInterface>
    </joint>
    <actuator name="hand_thumb_abd_motor">
      <mechanicalReduction>1.0</mechanicalReduction>
    </actuator>
  </transmission>
  <transmission name="hand_thumb_inner_trans">
    <robotNamespace>hand</robotNamespace>
    <type>transmission_interface/SimpleTransmission</type>
    <joint name="hand_thumb_inner_joint">
      <hardwareInterface>EffortJointInterface</hardwareInterface>
    </joint>
    <actuator name="hand_thumb_inner_motor">
      <mechanicalReduction>1.0</mechanicalReduction>
    </actuator>
  </transmission>
  <transmission name="hand_thumb_inner_mimic_trans">
    <robotNamespace>hand</robotNamespace>
    <type>transmission_interface/SimpleTransmission</type>
    <joint name="hand_thumb_inner_joint_mimic">
      <hardwareInterface>EffortJointInterface</hardwareInterface>
    </joint>
    <actuator name="hand_thumb_inner_motor">
      <mechanicalReduction>1.0</mechanicalReduction>
    </actuator>
  </transmission>
  <transmission name="hand_thumb_outer_trans">
    <robotNamespace>hand</robotNamespace>
    <type>transmission_interface/SimpleTransmission</type>
    <joint name="hand_thumb_outer_joint">
      <hardwareInterface>EffortJointInterface</hardwareInterface>
    </joint>
    <actuator name="hand_thumb_outer_motor">
      <mechanicalReduction>1.0</mechanicalReduction>
    </actuator>
  </transmission>
  <transmission name="hand_thumb_outer_mimic_trans">
    <robotNamespace>hand</robotNamespace>
    <type>transmission_interface/SimpleTransmission</type>
    <joint name="hand_thumb_outer_joint_mimic">
      <hardwareInterface>EffortJointInterface</hardwareInterface>
    </joint>
    <actuator name="hand_thumb_outer_motor">
      <mechanicalReduction>1.0</mechanicalReduction>
    </actuator>
  </transmission>
  <transmission name="hand_index_abd_trans">
    <robotNamespace>hand</robotNamespace>
    <type>transmission_interface/SimpleTransmission</type>
    <joint name="hand_index_abd_joint">
      <hardwareInterface>EffortJointInterface</hardwareInterface>
    </joint>
    <actuator name="hand_index_abd_motor">
      <mechanicalReduction>1.0</mechanicalReduction>
    </actuator>
  </transmission>
  <transmission name="hand_index_inner_trans">
    <robotNamespace>hand</robotNamespace>
    <type>transmission_interface/SimpleTransmission</type>
    <joint name="hand_index_inner_joint">
      <hardwareInterface>EffortJointInterface</hardwareInterface>
    </joint>
    <actuator name="hand_index_inner_motor">
      <mechanicalReduction>1.0</mechanicalReduction>
    </actuator>
  </transmission>
  <transmission name="hand_index_inner_mimic_trans">
    <robotNamespace>hand</robotNamespace>
    <type>transmission_interface/SimpleTransmission</type>
    <joint name="hand_index_inner_joint_mimic">
      <hardwareInterface>EffortJointInterface</hardwareInterface>
    </joint>
    <actuator name="hand_index_inner_motor">
      <mechanicalReduction>1.0</mechanicalReduction>
    </actuator>
  </transmission>
  <transmission name="hand_index_middle_trans">
    <robotNamespace>hand</robotNamespace>
    <type>transmission_interface/SimpleTransmission</type>
    <joint name="hand_index_middle_joint">
      <hardwareInterface>EffortJointInterface</hardwareInterface>
    </joint>
    <actuator name="hand_index_middle_motor">
      <mechanicalReduction>1.0</mechanicalReduction>
    </actuator>
  </transmission>
  <transmission name="hand_index_middle_mimic_trans">
    <robotNamespace>hand</robotNamespace>
    <type>transmission_interface/SimpleTransmission</type>
    <joint name="hand_index_middle_joint_mimic">
      <hardwareInterface>EffortJointInterface</hardwareInterface>
    </joint>
    <actuator name="hand_index_middle_motor">
      <mechanicalReduction>1.0</mechanicalReduction>
    </actuator>
  </transmission>
  <transmission name="hand_index_outer_trans">
    <robotNamespace>hand</robotNamespace>
    <type>transmission_interface/SimpleTransmission</type>
    <joint name="hand_index_outer_joint">
      <hardwareInterface>EffortJointInterface</hardwareInterface>
    </joint>
    <actuator name="hand_index_outer_motor">
      <mechanicalReduction>1.0</mechanicalReduction>
    </actuator>
  </transmission>
  <transmission name="hand_index_outer_mimic_trans">
    <robotNamespace>hand</robotNamespace>
    <type>transmission_interface/SimpleTransmission</type>
    <joint name="hand_index_outer_joint_mimic">
      <hardwareInterface>EffortJointInterface</hardwareInterface>
    </joint>
    <actuator name="hand_index_outer_motor">
      <mechanicalReduction>1.0</mechanicalReduction>
    </actuator>
  </transmission>
  <transmission name="hand_middle_abd_trans">
    <robotNamespace>hand</robotNamespace>
    <type>transmission_interface/SimpleTransmission</type>
    <joint name="hand_middle_abd_joint">
      <hardwareInterface>EffortJointInterface</hardwareInterface>
    </joint>
    <actuator name="hand_middle_abd_motor">
      <mechanicalReduction>1.0</mechanicalReduction>
    </actuator>
  </transmission>
  <transmission name="hand_middle_inner_trans">
    <robotNamespace>hand</robotNamespace>
    <type>transmission_interface/SimpleTransmission</type>
    <joint name="hand_middle_inner_joint">
      <hardwareInterface>EffortJointInterface</hardwareInterface>
    </joint>
    <actuator name="hand_middle_inner_motor">
      <mechanicalReduction>1.0</mechanicalReduction>
    </actuator>
  </transmission>
  <transmission name="hand_middle_inner_mimic_trans">
    <robotNamespace>hand</robotNamespace>
    <type>transmission_interface/SimpleTransmission</type>
    <joint name="hand_middle_inner_joint_mimic">
      <hardwareInterface>EffortJointInterface</hardwareInterface>
    </joint>
    <actuator name="hand_middle_inner_motor">
      <mechanicalReduction>1.0</mechanicalReduction>
    </actuator>
  </transmission>
  <transmission name="hand_middle_middle_trans">
    <robotNamespace>hand</robotNamespace>
    <type>transmission_interface/SimpleTransmission</type>
    <joint name="hand_middle_middle_joint">
      <hardwareInterface>EffortJointInterface</hardwareInterface>
    </joint>
    <actuator name="hand_middle_middle_motor">
      <mechanicalReduction>1.0</mechanicalReduction>
    </actuator>
  </transmission>
  <transmission name="hand_middle_middle_mimic_trans">
    <robotNamespace>hand</robotNamespace>
    <type>transmission_interface/SimpleTransmission</type>
    <joint name="hand_middle_middle_joint_mimic">
      <hardwareInterface>EffortJointInterface</hardwareInterface>
    </joint>
    <actuator name="hand_middle_middle_motor">
      <mechanicalReduction>1.0</mechanicalReduction>
    </actuator>
  </transmission>
  <transmission name="hand_middle_outer_trans">
    <robotNamespace>hand</robotNamespace>
    <type>transmission_interface/SimpleTransmission</type>
    <joint name="hand_middle_outer_joint">
      <hardwareInterface>EffortJointInterface</hardwareInterface>
    </joint>
    <actuator name="hand_middle_outer_motor">
      <mechanicalReduction>1.0</mechanicalReduction>
    </actuator>
  </transmission>
  <transmission name="hand_middle_outer_mimic_trans">
    <robotNamespace>hand</robotNamespace>
    <type>transmission_interface/SimpleTransmission</type>
    <joint name="hand_middle_outer_joint_mimic">
      <hardwareInterface>EffortJointInterface</hardwareInterface>
    </joint>
    <actuator name="hand_middle_outer_motor">
      <mechanicalReduction>1.0</mechanicalReduction>
    </actuator>
  </transmission>
  <transmission name="hand_ring_abd_trans">
    <robotNamespace>hand</robotNamespace>
    <type>transmission_interface/SimpleTransmission</type>
    <joint name="hand_ring_abd_joint">
      <hardwareInterface>EffortJointInterface</hardwareInterface>
    </joint>
    <actuator name="hand_ring_abd_motor">
      <mechanicalReduction>1.0</mechanicalReduction>
    </actuator>
  </transmission>
  <transmission name="hand_ring_inner_trans">
    <robotNamespace>hand</robotNamespace>
    <type>transmission_interface/SimpleTransmission</type>
    <joint name="hand_ring_inner_joint">
      <hardwareInterface>EffortJointInterface</hardwareInterface>
    </joint>
    <actuator name="hand_ring_inner_motor">
      <mechanicalReduction>1.0</mechanicalReduction>
    </actuator>
  </transmission>
  <transmission name="hand_ring_inner_mimic_trans">
    <robotNamespace>hand</robotNamespace>
    <type>transmission_interface/SimpleTransmission</type>
    <joint name="hand_ring_inner_joint_mimic">
      <hardwareInterface>EffortJointInterface</hardwareInterface>
    </joint>
    <actuator name="hand_ring_inner_motor">
      <mechanicalReduction>1.0</mechanicalReduction>
    </actuator>
  </transmission>
  <transmission name="hand_ring_middle_trans">
    <robotNamespace>hand</robotNamespace>
    <type>transmission_interface/SimpleTransmission</type>
    <joint name="hand_ring_middle_joint">
      <hardwareInterface>EffortJointInterface</hardwareInterface>
    </joint>
    <actuator name="hand_ring_middle_motor">
      <mechanicalReduction>1.0</mechanicalReduction>
    </actuator>
  </transmission>
  <transmission name="hand_ring_middle_mimic_trans">
    <robotNamespace>hand</robotNamespace>
    <type>transmission_interface/SimpleTransmission</type>
    <joint name="hand_ring_middle_joint_mimic">
      <hardwareInterface>EffortJointInterface</hardwareInterface>
    </joint>
    <actuator name="hand_ring_middle_motor">
      <mechanicalReduction>1.0</mechanicalReduction>
    </actuator>
  </transmission>
  <transmission name="hand_ring_outer_trans">
    <robotNamespace>hand</robotNamespace>
    <type>transmission_interface/SimpleTransmission</type>
    <joint name="hand_ring_outer_joint">
      <hardwareInterface>EffortJointInterface</hardwareInterface>
    </joint>
    <actuator name="hand_ring_outer_motor">
      <mechanicalReduction>1.0</mechanicalReduction>
    </actuator>
  </transmission>
  <transmission name="hand_ring_outer_mimic_trans">
    <robotNamespace>hand</robotNamespace>
    <type>transmission_interface/SimpleTransmission</type>
    <joint name="hand_ring_outer_joint_mimic">
      <hardwareInterface>EffortJointInterface</hardwareInterface>
    </joint>
    <actuator name="hand_ring_outer_motor">
      <mechanicalReduction>1.0</mechanicalReduction>
    </actuator>
  </transmission>
  <transmission name="hand_little_abd_trans">
    <robotNamespace>hand</robotNamespace>
    <type>transmission_interface/SimpleTransmission</type>
    <joint name="hand_little_abd_joint">
      <hardwareInterface>EffortJointInterface</hardwareInterface>
    </joint>
    <actuator name="hand_little_abd_motor">
      <mechanicalReduction>1.0</mechanicalReduction>
    </actuator>
  </transmission>
  <transmission name="hand_little_inner_trans">
    <robotNamespace>hand</robotNamespace>
    <type>transmission_interface/SimpleTransmission</type>
    <joint name="hand_little_inner_joint">
      <hardwareInterface>EffortJointInterface</hardwareInterface>
    </joint>
    <actuator name="hand_little_inner_motor">
      <mechanicalReduction>1.0</mechanicalReduction>
    </actuator>
  </transmission>
  <transmission name="hand_little_inner_mimic_trans">
    <robotNamespace>hand</robotNamespace>
    <type>transmission_interface/SimpleTransmission</type>
    <joint name="hand_little_inner_joint_mimic">
      <hardwareInterface>EffortJointInterface</hardwareInterface>
    </joint>
    <actuator name="hand_little_inner_motor">
      <mechanicalReduction>1.0</mechanicalReduction>
    </actuator>
  </transmission>
  <transmission name="hand_little_middle_trans">
    <robotNamespace>hand</robotNamespace>
    <type>transmission_interface/SimpleTransmission</type>
    <joint name="hand_little_middle_joint">
      <hardwareInterface>EffortJointInterface</hardwareInterface>
    </joint>
    <actuator name="hand_little_middle_motor">
      <mechanicalReduction>1.0</mechanicalReduction>
    </actuator>
  </transmission>
  <transmission name="hand_little_middle_mimic_trans">
    <robotNamespace>hand</robotNamespace>
    <type>transmission_interface/SimpleTransmission</type>
    <joint name="hand_little_middle_joint_mimic">
      <hardwareInterface>EffortJointInterface</hardwareInterface>
    </joint>
    <actuator name="hand_little_middle_motor">
      <mechanicalReduction>1.0</mechanicalReduction>
    </actuator>
  </transmission>
  <transmission name="hand_little_outer_trans">
    <robotNamespace>hand</robotNamespace>
    <type>transmission_interface/SimpleTransmission</type>
    <joint name="hand_little_outer_joint">
      <hardwareInterface>EffortJointInterface</hardwareInterface>
    </joint>
    <actuator name="hand_little_outer_motor">
      <mechanicalReduction>1.0</mechanicalReduction>
    </actuator>
  </transmission>
  <transmission name="hand_little_outer_mimic_trans">
    <robotNamespace>hand</robotNamespace>
    <type>transmission_interface/SimpleTransmission</type>
    <joint name="hand_little_outer_joint_mimic">
      <hardwareInterface>EffortJointInterface</hardwareInterface>
    </joint>
    <actuator name="hand_little_outer_motor">
      <mechanicalReduction>1.0</mechanicalReduction>
    </actuator>
  </transmission>
  <!-- PLUGINS -->
  <gazebo>
    <plugin filename="libgazebo_ros_control.so" name="gazebo_ros_control">
      <robotNamespace>hand</robotNamespace>
    </plugin>
  </gazebo>
  <!-- LINKS -->
  <gazebo reference="hand_palm_link">
    <sensor name="hand_palm_link_contact" type="contact">
      <!-- the gazebo contact sensor -->
      <always_on>1</always_on>
      <update_rate>1000.0</update_rate>
      <contact>
        <collision>hand_palm_link_collision</collision>
        <topic>hand_palm_link_collision</topic>
      </contact>
      <!-- to publish a ros message with contact information -->
      <plugin filename="libgazebo_ros_bumper.so" name="hand_palm_link_gazebo_ros_bumper_plugin">
        <alwaysOn>true</alwaysOn>
        <frameName>hand_palm_link</frameName>
        <updateRate>100.0</updateRate>
        <bumperTopicName>/contacts/hand_palm_link</bumperTopicName>
      </plugin>
    </sensor>
    <gravity>true</gravity>
    <mu1>500.0</mu1>
    <mu2>500.0</mu2>
    <kp>1000000.0</kp>
    <kd>100.0</kd>
    <!-- <fdir1>string</fdir1> -->
    <!-- <dampingFactor>double</dampingFactor> -->
    <!-- <maxVel>double</maxVel> -->
    <!-- <minDepth>double</minDepth> -->
    <!-- <maxContacts>int</maxContacts> -->
  </gazebo>
  <gazebo reference="hand_thumb_knuckle_link">
    <sensor name="hand_thumb_knuckle_link_contact" type="contact">
      <!-- the gazebo contact sensor -->
      <always_on>1</always_on>
      <update_rate>1000.0</update_rate>
      <contact>
        <collision>hand_thumb_knuckle_link_collision</collision>
        <topic>hand_thumb_knuckle_link_collision</topic>
      </contact>
      <!-- to publish a ros message with contact information -->
      <plugin filename="libgazebo_ros_bumper.so" name="hand_thumb_knuckle_link_gazebo_ros_bumper_plugin">
        <alwaysOn>true</alwaysOn>
        <frameName>hand_thumb_knuckle_link</frameName>
        <updateRate>100.0</updateRate>
        <bumperTopicName>/contacts/hand_thumb_knuckle_link</bumperTopicName>
      </plugin>
    </sensor>
    <gravity>true</gravity>
    <mu1>500.0</mu1>
    <mu2>500.0</mu2>
    <kp>1000000.0</kp>
    <kd>100.0</kd>
    <!-- <fdir1>string</fdir1> -->
    <!-- <dampingFactor>double</dampingFactor> -->
    <!-- <maxVel>double</maxVel> -->
    <!-- <minDepth>double</minDepth> -->
    <!-- <maxContacts>int</maxContacts> -->
  </gazebo>
  <gazebo reference="hand_thumb_proximal_link">
    <sensor name="hand_thumb_proximal_link_contact" type="contact">
      <!-- the gazebo contact sensor -->
      <always_on>1</always_on>
      <update_rate>1000.0</update_rate>
      <contact>
        <collision>hand_thumb_proximal_link_collision</collision>
        <topic>hand_thumb_proximal_link_collision</topic>
      </contact>
      <!-- to publish a ros message with contact information -->
      <plugin filename="libgazebo_ros_bumper.so" name="hand_thumb_proximal_link_gazebo_ros_bumper_plugin">
        <alwaysOn>true</alwaysOn>
        <frameName>hand_thumb_proximal_link</frameName>
        <updateRate>100.0</updateRate>
        <bumperTopicName>/contacts/hand_thumb_proximal_link</bumperTopicName>
      </plugin>
    </sensor>
    <gravity>true</gravity>
    <mu1>500.0</mu1>
    <mu2>500.0</mu2>
    <kp>1000000.0</kp>
    <kd>100.0</kd>
    <!-- <fdir1>string</fdir1> -->
    <!-- <dampingFactor>double</dampingFactor> -->
    <!-- <maxVel>double</maxVel> -->
    <!-- <minDepth>double</minDepth> -->
    <!-- <maxContacts>int</maxContacts> -->
  </gazebo>
  <gazebo reference="hand_thumb_distal_link">
    <sensor name="hand_thumb_distal_link_contact" type="contact">
      <!-- the gazebo contact sensor -->
      <always_on>1</always_on>
      <update_rate>1000.0</update_rate>
      <contact>
        <collision>hand_thumb_distal_link_collision</collision>
        <topic>hand_thumb_distal_link_collision</topic>
      </contact>
      <!-- to publish a ros message with contact information -->
      <plugin filename="libgazebo_ros_bumper.so" name="hand_thumb_distal_link_gazebo_ros_bumper_plugin">
        <alwaysOn>true</alwaysOn>
        <frameName>hand_thumb_distal_link</frameName>
        <updateRate>100.0</updateRate>
        <bumperTopicName>/contacts/hand_thumb_distal_link</bumperTopicName>
      </plugin>
    </sensor>
    <gravity>true</gravity>
    <mu1>500.0</mu1>
    <mu2>500.0</mu2>
    <kp>1000000.0</kp>
    <kd>100.0</kd>
    <!-- <fdir1>string</fdir1> -->
    <!-- <dampingFactor>double</dampingFactor> -->
    <!-- <maxVel>double</maxVel> -->
    <!-- <minDepth>double</minDepth> -->
    <!-- <maxContacts>int</maxContacts> -->
  </gazebo>
  <gazebo reference="hand_index_knuckle_link">
    <sensor name="hand_index_knuckle_link_contact" type="contact">
      <!-- the gazebo contact sensor -->
      <always_on>1</always_on>
      <update_rate>1000.0</update_rate>
      <contact>
        <collision>hand_index_knuckle_link_collision</collision>
        <topic>hand_index_knuckle_link_collision</topic>
      </contact>
      <!-- to publish a ros message with contact information -->
      <plugin filename="libgazebo_ros_bumper.so" name="hand_index_knuckle_link_gazebo_ros_bumper_plugin">
        <alwaysOn>true</alwaysOn>
        <frameName>hand_index_knuckle_link</frameName>
        <updateRate>100.0</updateRate>
        <bumperTopicName>/contacts/hand_index_knuckle_link</bumperTopicName>
      </plugin>
    </sensor>
    <gravity>true</gravity>
    <mu1>500.0</mu1>
    <mu2>500.0</mu2>
    <kp>1000000.0</kp>
    <kd>100.0</kd>
    <!-- <fdir1>string</fdir1> -->
    <!-- <dampingFactor>double</dampingFactor> -->
    <!-- <maxVel>double</maxVel> -->
    <!-- <minDepth>double</minDepth> -->
    <!-- <maxContacts>int</maxContacts> -->
  </gazebo>
  <gazebo reference="hand_index_proximal_link">
    <sensor name="hand_index_proximal_link_contact" type="contact">
      <!-- the gazebo contact sensor -->
      <always_on>1</always_on>
      <update_rate>1000.0</update_rate>
      <contact>
        <collision>hand_index_proximal_link_collision</collision>
        <topic>hand_index_proximal_link_collision</topic>
      </contact>
      <!-- to publish a ros message with contact information -->
      <plugin filename="libgazebo_ros_bumper.so" name="hand_index_proximal_link_gazebo_ros_bumper_plugin">
        <alwaysOn>true</alwaysOn>
        <frameName>hand_index_proximal_link</frameName>
        <updateRate>100.0</updateRate>
        <bumperTopicName>/contacts/hand_index_proximal_link</bumperTopicName>
      </plugin>
    </sensor>
    <gravity>true</gravity>
    <mu1>500.0</mu1>
    <mu2>500.0</mu2>
    <kp>1000000.0</kp>
    <kd>100.0</kd>
    <!-- <fdir1>string</fdir1> -->
    <!-- <dampingFactor>double</dampingFactor> -->
    <!-- <maxVel>double</maxVel> -->
    <!-- <minDepth>double</minDepth> -->
    <!-- <maxContacts>int</maxContacts> -->
  </gazebo>
  <gazebo reference="hand_index_middle_link">
    <sensor name="hand_index_middle_link_contact" type="contact">
      <!-- the gazebo contact sensor -->
      <always_on>1</always_on>
      <update_rate>1000.0</update_rate>
      <contact>
        <collision>hand_index_middle_link_collision</collision>
        <topic>hand_index_middle_link_collision</topic>
      </contact>
      <!-- to publish a ros message with contact information -->
      <plugin filename="libgazebo_ros_bumper.so" name="hand_index_middle_link_gazebo_ros_bumper_plugin">
        <alwaysOn>true</alwaysOn>
        <frameName>hand_index_middle_link</frameName>
        <updateRate>100.0</updateRate>
        <bumperTopicName>/contacts/hand_index_middle_link</bumperTopicName>
      </plugin>
    </sensor>
    <gravity>true</gravity>
    <mu1>500.0</mu1>
    <mu2>500.0</mu2>
    <kp>1000000.0</kp>
    <kd>100.0</kd>
    <!-- <fdir1>string</fdir1> -->
    <!-- <dampingFactor>double</dampingFactor> -->
    <!-- <maxVel>double</maxVel> -->
    <!-- <minDepth>double</minDepth> -->
    <!-- <maxContacts>int</maxContacts> -->
  </gazebo>
  <gazebo reference="hand_index_distal_link">
    <sensor name="hand_index_distal_link_contact" type="contact">
      <!-- the gazebo contact sensor -->
      <always_on>1</always_on>
      <update_rate>1000.0</update_rate>
      <contact>
        <collision>hand_index_distal_link_collision</collision>
        <topic>hand_index_distal_link_collision</topic>
      </contact>
      <!-- to publish a ros message with contact information -->
      <plugin filename="libgazebo_ros_bumper.so" name="hand_index_distal_link_gazebo_ros_bumper_plugin">
        <alwaysOn>true</alwaysOn>
        <frameName>hand_index_distal_link</frameName>
        <updateRate>100.0</updateRate>
        <bumperTopicName>/contacts/hand_index_distal_link</bumperTopicName>
      </plugin>
    </sensor>
    <gravity>true</gravity>
    <mu1>500.0</mu1>
    <mu2>500.0</mu2>
    <kp>1000000.0</kp>
    <kd>100.0</kd>
    <!-- <fdir1>string</fdir1> -->
    <!-- <dampingFactor>double</dampingFactor> -->
    <!-- <maxVel>double</maxVel> -->
    <!-- <minDepth>double</minDepth> -->
    <!-- <maxContacts>int</maxContacts> -->
  </gazebo>
  <gazebo reference="hand_middle_knuckle_link">
    <sensor name="hand_middle_knuckle_link_contact" type="contact">
      <!-- the gazebo contact sensor -->
      <always_on>1</always_on>
      <update_rate>1000.0</update_rate>
      <contact>
        <collision>hand_middle_knuckle_link_collision</collision>
        <topic>hand_middle_knuckle_link_collision</topic>
      </contact>
      <!-- to publish a ros message with contact information -->
      <plugin filename="libgazebo_ros_bumper.so" name="hand_middle_knuckle_link_gazebo_ros_bumper_plugin">
        <alwaysOn>true</alwaysOn>
        <frameName>hand_middle_knuckle_link</frameName>
        <updateRate>100.0</updateRate>
        <bumperTopicName>/contacts/hand_middle_knuckle_link</bumperTopicName>
      </plugin>
    </sensor>
    <gravity>true</gravity>
    <mu1>500.0</mu1>
    <mu2>500.0</mu2>
    <kp>1000000.0</kp>
    <kd>100.0</kd>
    <!-- <fdir1>string</fdir1> -->
    <!-- <dampingFactor>double</dampingFactor> -->
    <!-- <maxVel>double</maxVel> -->
    <!-- <minDepth>double</minDepth> -->
    <!-- <maxContacts>int</maxContacts> -->
  </gazebo>
  <gazebo reference="hand_middle_proximal_link">
    <sensor name="hand_middle_proximal_link_contact" type="contact">
      <!-- the gazebo contact sensor -->
      <always_on>1</always_on>
      <update_rate>1000.0</update_rate>
      <contact>
        <collision>hand_middle_proximal_link_collision</collision>
        <topic>hand_middle_proximal_link_collision</topic>
      </contact>
      <!-- to publish a ros message with contact information -->
      <plugin filename="libgazebo_ros_bumper.so" name="hand_middle_proximal_link_gazebo_ros_bumper_plugin">
        <alwaysOn>true</alwaysOn>
        <frameName>hand_middle_proximal_link</frameName>
        <updateRate>100.0</updateRate>
        <bumperTopicName>/contacts/hand_middle_proximal_link</bumperTopicName>
      </plugin>
    </sensor>
    <gravity>true</gravity>
    <mu1>500.0</mu1>
    <mu2>500.0</mu2>
    <kp>1000000.0</kp>
    <kd>100.0</kd>
    <!-- <fdir1>string</fdir1> -->
    <!-- <dampingFactor>double</dampingFactor> -->
    <!-- <maxVel>double</maxVel> -->
    <!-- <minDepth>double</minDepth> -->
    <!-- <maxContacts>int</maxContacts> -->
  </gazebo>
  <gazebo reference="hand_middle_middle_link">
    <sensor name="hand_middle_middle_link_contact" type="contact">
      <!-- the gazebo contact sensor -->
      <always_on>1</always_on>
      <update_rate>1000.0</update_rate>
      <contact>
        <collision>hand_middle_middle_link_collision</collision>
        <topic>hand_middle_middle_link_collision</topic>
      </contact>
      <!-- to publish a ros message with contact information -->
      <plugin filename="libgazebo_ros_bumper.so" name="hand_middle_middle_link_gazebo_ros_bumper_plugin">
        <alwaysOn>true</alwaysOn>
        <frameName>hand_middle_middle_link</frameName>
        <updateRate>100.0</updateRate>
        <bumperTopicName>/contacts/hand_middle_middle_link</bumperTopicName>
      </plugin>
    </sensor>
    <gravity>true</gravity>
    <mu1>500.0</mu1>
    <mu2>500.0</mu2>
    <kp>1000000.0</kp>
    <kd>100.0</kd>
    <!-- <fdir1>string</fdir1> -->
    <!-- <dampingFactor>double</dampingFactor> -->
    <!-- <maxVel>double</maxVel> -->
    <!-- <minDepth>double</minDepth> -->
    <!-- <maxContacts>int</maxContacts> -->
  </gazebo>
  <gazebo reference="hand_middle_distal_link">
    <sensor name="hand_middle_distal_link_contact" type="contact">
      <!-- the gazebo contact sensor -->
      <always_on>1</always_on>
      <update_rate>1000.0</update_rate>
      <contact>
        <collision>hand_middle_distal_link_collision</collision>
        <topic>hand_middle_distal_link_collision</topic>
      </contact>
      <!-- to publish a ros message with contact information -->
      <plugin filename="libgazebo_ros_bumper.so" name="hand_middle_distal_link_gazebo_ros_bumper_plugin">
        <alwaysOn>true</alwaysOn>
        <frameName>hand_middle_distal_link</frameName>
        <updateRate>100.0</updateRate>
        <bumperTopicName>/contacts/hand_middle_distal_link</bumperTopicName>
      </plugin>
    </sensor>
    <gravity>true</gravity>
    <mu1>500.0</mu1>
    <mu2>500.0</mu2>
    <kp>1000000.0</kp>
    <kd>100.0</kd>
    <!-- <fdir1>string</fdir1> -->
    <!-- <dampingFactor>double</dampingFactor> -->
    <!-- <maxVel>double</maxVel> -->
    <!-- <minDepth>double</minDepth> -->
    <!-- <maxContacts>int</maxContacts> -->
  </gazebo>
  <gazebo reference="hand_ring_knuckle_link">
    <sensor name="hand_ring_knuckle_link_contact" type="contact">
      <!-- the gazebo contact sensor -->
      <always_on>1</always_on>
      <update_rate>1000.0</update_rate>
      <contact>
        <collision>hand_ring_knuckle_link_collision</collision>
        <topic>hand_ring_knuckle_link_collision</topic>
      </contact>
      <!-- to publish a ros message with contact information -->
      <plugin filename="libgazebo_ros_bumper.so" name="hand_ring_knuckle_link_gazebo_ros_bumper_plugin">
        <alwaysOn>true</alwaysOn>
        <frameName>hand_ring_knuckle_link</frameName>
        <updateRate>100.0</updateRate>
        <bumperTopicName>/contacts/hand_ring_knuckle_link</bumperTopicName>
      </plugin>
    </sensor>
    <gravity>true</gravity>
    <mu1>500.0</mu1>
    <mu2>500.0</mu2>
    <kp>1000000.0</kp>
    <kd>100.0</kd>
    <!-- <fdir1>string</fdir1> -->
    <!-- <dampingFactor>double</dampingFactor> -->
    <!-- <maxVel>double</maxVel> -->
    <!-- <minDepth>double</minDepth> -->
    <!-- <maxContacts>int</maxContacts> -->
  </gazebo>
  <gazebo reference="hand_ring_proximal_link">
    <sensor name="hand_ring_proximal_link_contact" type="contact">
      <!-- the gazebo contact sensor -->
      <always_on>1</always_on>
      <update_rate>1000.0</update_rate>
      <contact>
        <collision>hand_ring_proximal_link_collision</collision>
        <topic>hand_ring_proximal_link_collision</topic>
      </contact>
      <!-- to publish a ros message with contact information -->
      <plugin filename="libgazebo_ros_bumper.so" name="hand_ring_proximal_link_gazebo_ros_bumper_plugin">
        <alwaysOn>true</alwaysOn>
        <frameName>hand_ring_proximal_link</frameName>
        <updateRate>100.0</updateRate>
        <bumperTopicName>/contacts/hand_ring_proximal_link</bumperTopicName>
      </plugin>
    </sensor>
    <gravity>true</gravity>
    <mu1>500.0</mu1>
    <mu2>500.0</mu2>
    <kp>1000000.0</kp>
    <kd>100.0</kd>
    <!-- <fdir1>string</fdir1> -->
    <!-- <dampingFactor>double</dampingFactor> -->
    <!-- <maxVel>double</maxVel> -->
    <!-- <minDepth>double</minDepth> -->
    <!-- <maxContacts>int</maxContacts> -->
  </gazebo>
  <gazebo reference="hand_ring_middle_link">
    <sensor name="hand_ring_middle_link_contact" type="contact">
      <!-- the gazebo contact sensor -->
      <always_on>1</always_on>
      <update_rate>1000.0</update_rate>
      <contact>
        <collision>hand_ring_middle_link_collision</collision>
        <topic>hand_ring_middle_link_collision</topic>
      </contact>
      <!-- to publish a ros message with contact information -->
      <plugin filename="libgazebo_ros_bumper.so" name="hand_ring_middle_link_gazebo_ros_bumper_plugin">
        <alwaysOn>true</alwaysOn>
        <frameName>hand_ring_middle_link</frameName>
        <updateRate>100.0</updateRate>
        <bumperTopicName>/contacts/hand_ring_middle_link</bumperTopicName>
      </plugin>
    </sensor>
    <gravity>true</gravity>
    <mu1>500.0</mu1>
    <mu2>500.0</mu2>
    <kp>1000000.0</kp>
    <kd>100.0</kd>
    <!-- <fdir1>string</fdir1> -->
    <!-- <dampingFactor>double</dampingFactor> -->
    <!-- <maxVel>double</maxVel> -->
    <!-- <minDepth>double</minDepth> -->
    <!-- <maxContacts>int</maxContacts> -->
  </gazebo>
  <gazebo reference="hand_ring_distal_link">
    <sensor name="hand_ring_distal_link_contact" type="contact">
      <!-- the gazebo contact sensor -->
      <always_on>1</always_on>
      <update_rate>1000.0</update_rate>
      <contact>
        <collision>hand_ring_distal_link_collision</collision>
        <topic>hand_ring_distal_link_collision</topic>
      </contact>
      <!-- to publish a ros message with contact information -->
      <plugin filename="libgazebo_ros_bumper.so" name="hand_ring_distal_link_gazebo_ros_bumper_plugin">
        <alwaysOn>true</alwaysOn>
        <frameName>hand_ring_distal_link</frameName>
        <updateRate>100.0</updateRate>
        <bumperTopicName>/contacts/hand_ring_distal_link</bumperTopicName>
      </plugin>
    </sensor>
    <gravity>true</gravity>
    <mu1>500.0</mu1>
    <mu2>500.0</mu2>
    <kp>1000000.0</kp>
    <kd>100.0</kd>
    <!-- <fdir1>string</fdir1> -->
    <!-- <dampingFactor>double</dampingFactor> -->
    <!-- <maxVel>double</maxVel> -->
    <!-- <minDepth>double</minDepth> -->
    <!-- <maxContacts>int</maxContacts> -->
  </gazebo>
  <gazebo reference="hand_little_knuckle_link">
    <sensor name="hand_little_knuckle_link_contact" type="contact">
      <!-- the gazebo contact sensor -->
      <always_on>1</always_on>
      <update_rate>1000.0</update_rate>
      <contact>
        <collision>hand_little_knuckle_link_collision</collision>
        <topic>hand_little_knuckle_link_collision</topic>
      </contact>
      <!-- to publish a ros message with contact information -->
      <plugin filename="libgazebo_ros_bumper.so" name="hand_little_knuckle_link_gazebo_ros_bumper_plugin">
        <alwaysOn>true</alwaysOn>
        <frameName>hand_little_knuckle_link</frameName>
        <updateRate>100.0</updateRate>
        <bumperTopicName>/contacts/hand_little_knuckle_link</bumperTopicName>
      </plugin>
    </sensor>
    <gravity>true</gravity>
    <mu1>500.0</mu1>
    <mu2>500.0</mu2>
    <kp>1000000.0</kp>
    <kd>100.0</kd>
    <!-- <fdir1>string</fdir1> -->
    <!-- <dampingFactor>double</dampingFactor> -->
    <!-- <maxVel>double</maxVel> -->
    <!-- <minDepth>double</minDepth> -->
    <!-- <maxContacts>int</maxContacts> -->
  </gazebo>
  <gazebo reference="hand_little_proximal_link">
    <sensor name="hand_little_proximal_link_contact" type="contact">
      <!-- the gazebo contact sensor -->
      <always_on>1</always_on>
      <update_rate>1000.0</update_rate>
      <contact>
        <collision>hand_little_proximal_link_collision</collision>
        <topic>hand_little_proximal_link_collision</topic>
      </contact>
      <!-- to publish a ros message with contact information -->
      <plugin filename="libgazebo_ros_bumper.so" name="hand_little_proximal_link_gazebo_ros_bumper_plugin">
        <alwaysOn>true</alwaysOn>
        <frameName>hand_little_proximal_link</frameName>
        <updateRate>100.0</updateRate>
        <bumperTopicName>/contacts/hand_little_proximal_link</bumperTopicName>
      </plugin>
    </sensor>
    <gravity>true</gravity>
    <mu1>500.0</mu1>
    <mu2>500.0</mu2>
    <kp>1000000.0</kp>
    <kd>100.0</kd>
    <!-- <fdir1>string</fdir1> -->
    <!-- <dampingFactor>double</dampingFactor> -->
    <!-- <maxVel>double</maxVel> -->
    <!-- <minDepth>double</minDepth> -->
    <!-- <maxContacts>int</maxContacts> -->
  </gazebo>
  <gazebo reference="hand_little_middle_link">
    <sensor name="hand_little_middle_link_contact" type="contact">
      <!-- the gazebo contact sensor -->
      <always_on>1</always_on>
      <update_rate>1000.0</update_rate>
      <contact>
        <collision>hand_little_middle_link_collision</collision>
        <topic>hand_little_middle_link_collision</topic>
      </contact>
      <!-- to publish a ros message with contact information -->
      <plugin filename="libgazebo_ros_bumper.so" name="hand_little_middle_link_gazebo_ros_bumper_plugin">
        <alwaysOn>true</alwaysOn>
        <frameName>hand_little_middle_link</frameName>
        <updateRate>100.0</updateRate>
        <bumperTopicName>/contacts/hand_little_middle_link</bumperTopicName>
      </plugin>
    </sensor>
    <gravity>true</gravity>
    <mu1>500.0</mu1>
    <mu2>500.0</mu2>
    <kp>1000000.0</kp>
    <kd>100.0</kd>
    <!-- <fdir1>string</fdir1> -->
    <!-- <dampingFactor>double</dampingFactor> -->
    <!-- <maxVel>double</maxVel> -->
    <!-- <minDepth>double</minDepth> -->
    <!-- <maxContacts>int</maxContacts> -->
  </gazebo>
  <gazebo reference="hand_little_distal_link">
    <sensor name="hand_little_distal_link_contact" type="contact">
      <!-- the gazebo contact sensor -->
      <always_on>1</always_on>
      <update_rate>1000.0</update_rate>
      <contact>
        <collision>hand_little_distal_link_collision</collision>
        <topic>hand_little_distal_link_collision</topic>
      </contact>
      <!-- to publish a ros message with contact information -->
      <plugin filename="libgazebo_ros_bumper.so" name="hand_little_distal_link_gazebo_ros_bumper_plugin">
        <alwaysOn>true</alwaysOn>
        <frameName>hand_little_distal_link</frameName>
        <updateRate>100.0</updateRate>
        <bumperTopicName>/contacts/hand_little_distal_link</bumperTopicName>
      </plugin>
    </sensor>
    <gravity>true</gravity>
    <mu1>500.0</mu1>
    <mu2>500.0</mu2>
    <kp>1000000.0</kp>
    <kd>100.0</kd>
    <!-- <fdir1>string</fdir1> -->
    <!-- <dampingFactor>double</dampingFactor> -->
    <!-- <maxVel>double</maxVel> -->
    <!-- <minDepth>double</minDepth> -->
    <!-- <maxContacts>int</maxContacts> -->
  </gazebo>
  <!-- JOINTS -->
  <gazebo reference="hand_thumb_abd_joint">
    <provideFeedback>True</provideFeedback>
    <!--
		<kp> </kp>
		<kd> 1.0 </kd>
		<stopCfm> </stopCfm>
		<stopErp> </stopErp>
		<cfmDamping> </cfmDamping>
		<fudgeFactor> </fudgeFactor>
		-->
  </gazebo>
  <gazebo reference="hand_thumb_inner_joint">
    <provideFeedback>True</provideFeedback>
    <!--
		<kp> </kp>
		<kd> 1.0 </kd>
		<stopCfm> </stopCfm>
		<stopErp> </stopErp>
		<cfmDamping> </cfmDamping>
		<fudgeFactor> </fudgeFactor>
		-->
  </gazebo>
  <gazebo reference="hand_thumb_outer_joint">
    <provideFeedback>True</provideFeedback>
    <!--
		<kp> </kp>
		<kd> 1.0 </kd>
		<stopCfm> </stopCfm>
		<stopErp> </stopErp>
		<cfmDamping> </cfmDamping>
		<fudgeFactor> </fudgeFactor>
		-->
  </gazebo>
  <gazebo reference="hand_index_abd_joint">
    <provideFeedback>True</provideFeedback>
    <!--
		<kp> </kp>
		<kd> 1.0 </kd>
		<stopCfm> </stopCfm>
		<stopErp> </stopErp>
		<cfmDamping> </cfmDamping>
		<fudgeFactor> </fudgeFactor>
		-->
  </gazebo>
  <gazebo reference="hand_index_inner_joint">
    <provideFeedback>True</provideFeedback>
    <!--
		<kp> </kp>
		<kd> 1.0 </kd>
		<stopCfm> </stopCfm>
		<stopErp> </stopErp>
		<cfmDamping> </cfmDamping>
		<fudgeFactor> </fudgeFactor>
		-->
  </gazebo>
  <gazebo reference="hand_index_middle_joint">
    <provideFeedback>True</provideFeedback>
    <!--
		<kp> </kp>
		<kd> 1.0 </kd>
		<stopCfm> </stopCfm>
		<stopErp> </stopErp>
		<cfmDamping> </cfmDamping>
		<fudgeFactor> </fudgeFactor>
		-->
  </gazebo>
  <gazebo reference="hand_index_outer_joint">
    <provideFeedback>True</provideFeedback>
    <!--
		<kp> </kp>
		<kd> 1.0 </kd>
		<stopCfm> </stopCfm>
		<stopErp> </stopErp>
		<cfmDamping> </cfmDamping>
		<fudgeFactor> </fudgeFactor>
		-->
  </gazebo>
  <gazebo reference="hand_middle_abd_joint">
    <provideFeedback>True</provideFeedback>
    <!--
		<kp> </kp>
		<kd> 1.0 </kd>
		<stopCfm> </stopCfm>
		<stopErp> </stopErp>
		<cfmDamping> </cfmDamping>
		<fudgeFactor> </fudgeFactor>
		-->
  </gazebo>
  <gazebo reference="hand_middle_inner_joint">
    <provideFeedback>True</provideFeedback>
    <!--
		<kp> </kp>
		<kd> 1.0 </kd>
		<stopCfm> </stopCfm>
		<stopErp> </stopErp>
		<cfmDamping> </cfmDamping>
		<fudgeFactor> </fudgeFactor>
		-->
  </gazebo>
  <gazebo reference="hand_middle_middle_joint">
    <provideFeedback>True</provideFeedback>
    <!--
		<kp> </kp>
		<kd> 1.0 </kd>
		<stopCfm> </stopCfm>
		<stopErp> </stopErp>
		<cfmDamping> </cfmDamping>
		<fudgeFactor> </fudgeFactor>
		-->
  </gazebo>
  <gazebo reference="hand_middle_outer_joint">
    <provideFeedback>True</provideFeedback>
    <!--
		<kp> </kp>
		<kd> 1.0 </kd>
		<stopCfm> </stopCfm>
		<stopErp> </stopErp>
		<cfmDamping> </cfmDamping>
		<fudgeFactor> </fudgeFactor>
		-->
  </gazebo>
  <gazebo reference="hand_ring_abd_joint">
    <provideFeedback>True</provideFeedback>
    <!--
		<kp> </kp>
		<kd> 1.0 </kd>
		<stopCfm> </stopCfm>
		<stopErp> </stopErp>
		<cfmDamping> </cfmDamping>
		<fudgeFactor> </fudgeFactor>
		-->
  </gazebo>
  <gazebo reference="hand_ring_inner_joint">
    <provideFeedback>True</provideFeedback>
    <!--
		<kp> </kp>
		<kd> 1.0 </kd>
		<stopCfm> </stopCfm>
		<stopErp> </stopErp>
		<cfmDamping> </cfmDamping>
		<fudgeFactor> </fudgeFactor>
		-->
  </gazebo>
  <gazebo reference="hand_ring_middle_joint">
    <provideFeedback>True</provideFeedback>
    <!--
		<kp> </kp>
		<kd> 1.0 </kd>
		<stopCfm> </stopCfm>
		<stopErp> </stopErp>
		<cfmDamping> </cfmDamping>
		<fudgeFactor> </fudgeFactor>
		-->
  </gazebo>
  <gazebo reference="hand_ring_outer_joint">
    <provideFeedback>True</provideFeedback>
    <!--
		<kp> </kp>
		<kd> 1.0 </kd>
		<stopCfm> </stopCfm>
		<stopErp> </stopErp>
		<cfmDamping> </cfmDamping>
		<fudgeFactor> </fudgeFactor>
		-->
  </gazebo>
  <gazebo reference="hand_little_abd_joint">
    <provideFeedback>True</provideFeedback>
    <!--
		<kp> </kp>
		<kd> 1.0 </kd>
		<stopCfm> </stopCfm>
		<stopErp> </stopErp>
		<cfmDamping> </cfmDamping>
		<fudgeFactor> </fudgeFactor>
		-->
  </gazebo>
  <gazebo reference="hand_little_inner_joint">
    <provideFeedback>True</provideFeedback>
    <!--
		<kp> </kp>
		<kd> 1.0 </kd>
		<stopCfm> </stopCfm>
		<stopErp> </stopErp>
		<cfmDamping> </cfmDamping>
		<fudgeFactor> </fudgeFactor>
		-->
  </gazebo>
  <gazebo reference="hand_little_middle_joint">
    <provideFeedback>True</provideFeedback>
    <!--
		<kp> </kp>
		<kd> 1.0 </kd>
		<stopCfm> </stopCfm>
		<stopErp> </stopErp>
		<cfmDamping> </cfmDamping>
		<fudgeFactor> </fudgeFactor>
		-->
  </gazebo>
  <gazebo reference="hand_little_outer_joint">
    <provideFeedback>True</provideFeedback>
    <!--
		<kp> </kp>
		<kd> 1.0 </kd>
		<stopCfm> </stopCfm>
		<stopErp> </stopErp>
		<cfmDamping> </cfmDamping>
		<fudgeFactor> </fudgeFactor>
		-->
  </gazebo>
  <!-- mimic joints -->
  <gazebo reference="hand_thumb_inner_joint_mimic">
    <provideFeedback>True</provideFeedback>
    <!--
		<kp> </kp>
		<kd> 1.0 </kd>
		<stopCfm> </stopCfm>
		<stopErp> </stopErp>
		<cfmDamping> </cfmDamping>
		<fudgeFactor> </fudgeFactor>
		-->
  </gazebo>
  <gazebo reference="hand_thumb_outer_joint_mimic">
    <provideFeedback>True</provideFeedback>
    <!--
		<kp> </kp>
		<kd> 1.0 </kd>
		<stopCfm> </stopCfm>
		<stopErp> </stopErp>
		<cfmDamping> </cfmDamping>
		<fudgeFactor> </fudgeFactor>
		-->
  </gazebo>
  <gazebo reference="hand_index_inner_joint_mimic">
    <provideFeedback>True</provideFeedback>
    <!--
		<kp> </kp>
		<kd> 1.0 </kd>
		<stopCfm> </stopCfm>
		<stopErp> </stopErp>
		<cfmDamping> </cfmDamping>
		<fudgeFactor> </fudgeFactor>
		-->
  </gazebo>
  <gazebo reference="hand_index_middle_joint_mimic">
    <provideFeedback>True</provideFeedback>
    <!--
		<kp> </kp>
		<kd> 1.0 </kd>
		<stopCfm> </stopCfm>
		<stopErp> </stopErp>
		<cfmDamping> </cfmDamping>
		<fudgeFactor> </fudgeFactor>
		-->
  </gazebo>
  <gazebo reference="hand_index_outer_joint_mimic">
    <provideFeedback>True</provideFeedback>
    <!--
		<kp> </kp>
		<kd> 1.0 </kd>
		<stopCfm> </stopCfm>
		<stopErp> </stopErp>
		<cfmDamping> </cfmDamping>
		<fudgeFactor> </fudgeFactor>
		-->
  </gazebo>
  <gazebo reference="hand_middle_inner_joint_mimic">
    <provideFeedback>True</provideFeedback>
    <!--
		<kp> </kp>
		<kd> 1.0 </kd>
		<stopCfm> </stopCfm>
		<stopErp> </stopErp>
		<cfmDamping> </cfmDamping>
		<fudgeFactor> </fudgeFactor>
		-->
  </gazebo>
  <gazebo reference="hand_middle_middle_joint_mimic">
    <provideFeedback>True</provideFeedback>
    <!--
		<kp> </kp>
		<kd> 1.0 </kd>
		<stopCfm> </stopCfm>
		<stopErp> </stopErp>
		<cfmDamping> </cfmDamping>
		<fudgeFactor> </fudgeFactor>
		-->
  </gazebo>
  <gazebo reference="hand_middle_outer_joint_mimic">
    <provideFeedback>True</provideFeedback>
    <!--
		<kp> </kp>
		<kd> 1.0 </kd>
		<stopCfm> </stopCfm>
		<stopErp> </stopErp>
		<cfmDamping> </cfmDamping>
		<fudgeFactor> </fudgeFactor>
		-->
  </gazebo>
  <gazebo reference="hand_ring_inner_joint_mimic">
    <provideFeedback>True</provideFeedback>
    <!--
		<kp> </kp>
		<kd> 1.0 </kd>
		<stopCfm> </stopCfm>
		<stopErp> </stopErp>
		<cfmDamping> </cfmDamping>
		<fudgeFactor> </fudgeFactor>
		-->
  </gazebo>
  <gazebo reference="hand_ring_middle_joint_mimic">
    <provideFeedback>True</provideFeedback>
    <!--
		<kp> </kp>
		<kd> 1.0 </kd>
		<stopCfm> </stopCfm>
		<stopErp> </stopErp>
		<cfmDamping> </cfmDamping>
		<fudgeFactor> </fudgeFactor>
		-->
  </gazebo>
  <gazebo reference="hand_ring_outer_joint_mimic">
    <provideFeedback>True</provideFeedback>
    <!--
		<kp> </kp>
		<kd> 1.0 </kd>
		<stopCfm> </stopCfm>
		<stopErp> </stopErp>
		<cfmDamping> </cfmDamping>
		<fudgeFactor> </fudgeFactor>
		-->
  </gazebo>
  <gazebo reference="hand_little_inner_joint_mimic">
    <provideFeedback>True</provideFeedback>
    <!--
		<kp> </kp>
		<kd> 1.0 </kd>
		<stopCfm> </stopCfm>
		<stopErp> </stopErp>
		<cfmDamping> </cfmDamping>
		<fudgeFactor> </fudgeFactor>
		-->
  </gazebo>
  <gazebo reference="hand_little_middle_joint_mimic">
    <provideFeedback>True</provideFeedback>
    <!--
		<kp> </kp>
		<kd> 1.0 </kd>
		<stopCfm> </stopCfm>
		<stopErp> </stopErp>
		<cfmDamping> </cfmDamping>
		<fudgeFactor> </fudgeFactor>
		-->
  </gazebo>
  <gazebo reference="hand_little_outer_joint_mimic">
    <provideFeedback>True</provideFeedback>
    <!--
		<kp> </kp>
		<kd> 1.0 </kd>
		<stopCfm> </stopCfm>
		<stopErp> </stopErp>
		<cfmDamping> </cfmDamping>
		<fudgeFactor> </fudgeFactor>
		-->
  </gazebo>
  <gazebo>
    <plugin filename="libhwi_switch_gazebo_ros_control.so" name="ros_control">
      <robotNamespace>hand_controller</robotNamespace>
      <filterJointsParam>joint_names</filterJointsParam>
    </plugin>
  </gazebo>
  <joint name="profile_joint" type="fixed">
    <origin rpy="0 0 0" xyz="0 0 0"/>
    <parent link="base_linkz"/>
    <child link="profile_link"/>
  </joint>
  <link name="profile_link">
    <inertial>
      <mass value="0.00001"/>
      <origin xyz="0 0 0"/>
      <inertia ixx="1.0" ixy="0.0" ixz="0.0" iyy="1.0" iyz="0.0" izz="1.0"/>
    </inertial>
    <visual>
      <origin rpy="0 0 0" xyz="0 0 0"/>
      <geometry>
        <mesh filename="package://robotino_description/meshes/pan_tilt.stl"/>
      </geometry>
      <material name="Black"/>
    </visual>
    <collision>
      <origin rpy="0 0 0" xyz="0 0 0"/>
      <geometry>
        <mesh filename="package://robotino_description/meshes/pan_tilt.stl"/>
      </geometry>
    </collision>
  </link>
  <gazebo reference="profile_link">
    <gravity>true</gravity>
    <self_collide>false</self_collide>
    <material>Gazebo/Black</material>
  </gazebo>
  <joint name="base_pan_joint" type="fixed">
    <origin rpy="0.012045 -0.0565489 0.0113182" xyz="0.257201 0.0587815 0.637117"/>
    <parent link="profile_link"/>
    <child link="base_pan_link"/>
  </joint>
  <link name="base_pan_link">
    <inertial>
      <mass value="0.00001"/>
      <origin xyz="0 0 0"/>
      <inertia ixx="1.0" ixy="0.0" ixz="0.0" iyy="1.0" iyz="0.0" izz="1.0"/>
    </inertial>
    <visual>
      <origin rpy="0 0 0" xyz="0 0 0"/>
      <geometry>
        <box size="0.001 0.001 0.001"/>
      </geometry>
      <material name="Black"/>
    </visual>
    <collision>
      <origin rpy="0 0 0" xyz="0 0 0"/>
      <geometry>
        <box size="0.001 0.001 0.001"/>
      </geometry>
    </collision>
  </link>
  <gazebo reference="base_pan_link">
    <gravity>true</gravity>
    <self_collide>false</self_collide>
    <material>Gazebo/Black</material>
  </gazebo>
  <joint name="pan_joint" type="revolute">
    <origin rpy="0 0 0" xyz="0 0 0"/>
    <parent link="base_pan_link"/>
    <child link="pan_link"/>
    <axis xyz="0 0 1"/>
    <calibration rising="0.1"/>
    <limit effort="100" lower="-1.57" upper="1.57" velocity="1.4"/>
  </joint>
  <link name="pan_link">
    <inertial>
      <mass value="0.00001"/>
      <origin xyz="0 0 0"/>
      <inertia ixx="1.0" ixy="0.0" ixz="0.0" iyy="1.0" iyz="0.0" izz="1.0"/>
    </inertial>
  </link>
  <joint name="tilt_joint" type="revolute">
    <origin rpy="1.57 0 0" xyz="0 0 0"/>
    <parent link="pan_link"/>
    <child link="tilt_link"/>
    <axis xyz="0 0 -1"/>
    <calibration rising="0.1"/>
    <limit effort="100" lower="-1.57" upper="1.57" velocity="1.4"/>
  </joint>
  <link name="tilt_link">
    <inertial>
      <mass value="0.00001"/>
      <origin xyz="0 0 0"/>
      <inertia ixx="1.0" ixy="0.0" ixz="0.0" iyy="1.0" iyz="0.0" izz="1.0"/>
    </inertial>
  </link>
  <transmission name="tilt_trans">
    <type>transmission_interface/SimpleTransmission</type>
    <joint name="tilt_joint">
      <!--hardwareInterface>EffortJointInterface</hardwareInterface>
        <hardwareInterface>VelocityJointInterface</hardwareInterface-->
      <hardwareInterface>PositionJointInterface</hardwareInterface>
    </joint>
    <actuator name="tilt_motor">
      <mechanicalReduction>1</mechanicalReduction>
    </actuator>
  </transmission>
  <transmission name="pan_trans">
    <type>transmission_interface/SimpleTransmission</type>
    <joint name="pan_joint">
      <!--hardwareInterface>EffortJointInterface</hardwareInterface>
        <hardwareInterface>VelocityJointInterface</hardwareInterface-->
      <hardwareInterface>PositionJointInterface</hardwareInterface>
    </joint>
    <actuator name="pan_motor">
      <mechanicalReduction>1</mechanicalReduction>
    </actuator>
  </transmission>
  <gazebo reference="tilt_link">
    <gravity>true</gravity>
    <self_collide>false</self_collide>
  </gazebo>
  <gazebo reference="pan_link">
    <gravity>true</gravity>
    <self_collide>false</self_collide>
  </gazebo>
  <joint name="kinect_joint" type="fixed">
    <origin rpy="1.57297 -3.11833 3.10173" xyz="0.0772857 0.117459 -0.0273189"/>
    <parent link="tilt_link"/>
    <child link="kinect_link"/>
  </joint>
  <link name="kinect_link">
    <inertial>
      <mass value="0.00001"/>
      <origin xyz="0 0 0"/>
      <inertia ixx="1.0" ixy="0.0" ixz="0.0" iyy="1.0" iyz="0.0" izz="1.0"/>
    </inertial>
    <visual>
      <origin rpy="0 0 0" xyz="0 0 0"/>
      <geometry>
        <box size="0.035 0.18 0.02"/>
      </geometry>
      <material name="Grey"/>
    </visual>
    <collision>
      <origin rpy="0 0 0" xyz="0 0 0"/>
      <geometry>
        <box size="0.035  0.18 0.02"/>
      </geometry>
    </collision>
  </link>
  <!-- <joint name="${name}_frame_joint" type="fixed"> -->
  <!--   <origin xyz="0 0 0" rpy="${M_PI/2} -${M_PI/2} 0" />  -->
  <!--   <parent link="${name}_link"/> -->
  <!--   <child link="${name}_frame"/> -->
  <!-- </joint> -->
  <!-- <link name="${name}_frame"/> -->
  <!-- gazebo extensions -->
  <gazebo reference="kinect_link">
    <sensor name="kinect_frame_sensor" type="depth">
      <always_on>true</always_on>
      <update_rate>20.0</update_rate>
      <visualize>true</visualize>
      <camera>
        <horizontal_fov>1.08210322222</horizontal_fov>
        <image>
          <format>R8G8B8</format>
          <width>640</width>
          <height>480</height>
        </image>
        <clip>
          <near>0.1</near>
          <far>100</far>
        </clip>
        <noise>
          <type>gaussian</type>
          <mean>0.0</mean>
          <stddev>0.005</stddev>
        </noise>
      </camera>
      <plugin filename="libgazebo_ros_openni_kinect.so" name="kinect_controller">
        <updateRate>20.0</updateRate>
        <cameraName>kinect</cameraName>
        <frameName>kinect_depth_optical_frame</frameName>
        <imageTopicName>rgb/image_raw</imageTopicName>
        <depthImageTopicName>depth/image_raw</depthImageTopicName>
        <!--pointCloudTopicName>depth_registered/points</pointCloudTopicName-->
        <pointCloudTopicName>depth/points</pointCloudTopicName>
        <cameraInfoTopicName>rgb/camera_info</cameraInfoTopicName>
        <depthImageCameraInfoTopicName>depth_registered/camera_info</depthImageCameraInfoTopicName>
        <pointCloudCutoff>0.5</pointCloudCutoff>
        <baseline>0.2</baseline>
        <hackBaseline>0.0</hackBaseline>
        <distortionK1>0.0</distortionK1>
        <distortionK2>0.0</distortionK2>
        <distortionK3>0.0</distortionK3>
        <distortionT1>0.0</distortionT1>
        <distortionT2>0.0</distortionT2>
        <CxPrime>0.0</CxPrime>
        <Cx>0.0</Cx>
        <Cy>0.0</Cy>
        <focalLength>0.0</focalLength>
      </plugin>
    </sensor>
    <material>Gazebo/Black</material>
  </gazebo>
  <gazebo>
    <plugin filename="libhwi_switch_gazebo_ros_control.so" name="ros_control">
      <robotNamespace>pan_tilt_controller</robotNamespace>
      <filterJointsParam>joint_names</filterJointsParam>
    </plugin>
  </gazebo>
</robot>

