<?xml version="1.0"?>
<root xmlns:xacro="http://www.ros.org/wiki/xacro">

  <xacro:macro name="pan_tilt_axis" params="parent *origin">
  
    <joint name="pan_joint" type="revolute">
      <insert_block name="origin" />
      <parent link="${parent}"/>
      <child link="pan_link" />      
      <axis xyz="0 0 1" />
      <calibration rising="0.1"/>
      <limit effort="100" lower="-1.57" upper="1.57" velocity="1.4"/>
    </joint>
    
    <link name="pan_link">
      <inertial>
        <mass value="0.00001" />
        <origin xyz="0 0 0" />
        <inertia ixx="1.0" ixy="0.0" ixz="0.0"
          iyy="1.0" iyz="0.0"
          izz="1.0" />
      </inertial>
    </link>

    <joint name="tilt_joint" type="revolute">
			<origin xyz="0 0 0" rpy="1.57 0 0"/>
      <parent link="pan_link"/>
      <child link="tilt_link" />      
      <axis xyz="0 0 -1" />
      <calibration rising="0.1"/>
      <limit effort="100" lower="-1.57" upper="1.57" velocity="1.4"/>
    </joint>
    
    <link name="tilt_link">
      <inertial>
        <mass value="0.00001" />
        <origin xyz="0 0 0" />
        <inertia ixx="1.0" ixy="0.0" ixz="0.0"
          iyy="1.0" iyz="0.0"
          izz="1.0" />
      </inertial>
    </link>


    <xacro:pan_tilt_transmission />
    <xacro:pan_tilt_gazebo/>
  </xacro:macro>
  
  <xacro:macro name="pan_tilt_transmission">
    <transmission name="tilt_trans">
      <type>transmission_interface/SimpleTransmission</type>
      <joint name="tilt_joint">
        <!--hardwareInterface>EffortJointInterface</hardwareInterface>
        <hardwareInterface>VelocityJointInterface</hardwareInterface-->
        <hardwareInterface>PositionJointInterface</hardwareInterface>
      </joint>
      <actuator name="tilt_motor">
        <mechanicalReduction>1</mechanicalReduction>
      </actuator>
    </transmission>

    <transmission name="pan_trans">
      <type>transmission_interface/SimpleTransmission</type>
      <joint name="pan_joint">
        <!--hardwareInterface>EffortJointInterface</hardwareInterface>
        <hardwareInterface>VelocityJointInterface</hardwareInterface-->
        <hardwareInterface>PositionJointInterface</hardwareInterface>
      </joint>
      <actuator name="pan_motor">
        <mechanicalReduction>1</mechanicalReduction>
      </actuator>
    </transmission>
  </xacro:macro>

  <xacro:macro name="pan_tilt_gazebo">
  <gazebo reference="tilt_link">
    <gravity>true</gravity>
    <self_collide>false</self_collide>
  </gazebo>

  <gazebo reference="pan_link">
    <gravity>true</gravity>
    <self_collide>false</self_collide>
  </gazebo>
  </xacro:macro>

</root>

