<?xml version="1.0"?>
<root xmlns:xacro="http://www.ros.org/wiki/xacro">
  <xacro:macro name="rotatory">

  <joint name="fixed_base_link_base" type="fixed">
      <parent link="base_link"/>
      <child link="base"/>
      <origin xyz="0.0 0.0 0.185" rpy="0 0 -1.0471975511965976" />
  </joint>

  <link name="odomp"> 
    <inertial>
      <mass value="0.01"/>
      <origin xyz="0 0 0"/>
      <inertia ixx="0.001" ixy="0.0" ixz="0.0" iyy="0.001" iyz="0.0" izz="0.001" />
    </inertial>
  </link>

    <gazebo reference="odomp">
        <material>Gazebo/Black</material>
    </gazebo>
        
  <joint name="rotatory" type="continuous">
    <origin xyz="0 0 0" rpy="0 0 0" />
    <parent link="odomp"/>
    <child link="base_link"/>
    <axis xyz="0 0 1" />
  </joint>

  <transmission name="rotatory_trans">
    <type>transmission_interface/SimpleTransmission</type>
    <joint name="rotatory">
      <hardwareInterface>VelocityJointInterface</hardwareInterface>
    </joint>
    <actuator name="rotatory_motor">
      <mechanicalReduction>1</mechanicalReduction>
      <hardwareInterface>VelocityJointInterface</hardwareInterface>
    </actuator>
  </transmission>
     
  </xacro:macro>
</root>

