<?xml version="1.0"?>
<root xmlns:xacro="http://www.ros.org/wiki/xacro">

  <xacro:macro name="tilt_axis" params="parent name *origin">
  
    <joint name="${name}_joint" type="revolute">
      <insert_block name="origin" />
      <parent link="${parent}"/>
      <child link="${name}_link" />      
      <axis xyz="0 1 0" />
      <calibration rising="0.1"/>
      <limit effort="100" lower="-1.57" upper="1.57" velocity="1.4"/>
    </joint>
    
    <link name="${name}_link">
      <inertial>
        <mass value="0.00001" />
        <origin xyz="0 0 0" />
        <inertia ixx="1.0" ixy="0.0" ixz="0.0"
          iyy="1.0" iyz="0.0"
          izz="1.0" />
      </inertial>
    </link>

    <xacro:tilt_transmission name="tilt" />
    <xacro:tilt_gazebo name="tilt" />
  </xacro:macro>
  
  <xacro:macro name="tilt_transmission" params="name">
    <transmission name="${name}_trans">
      <type>transmission_interface/SimpleTransmission</type>
      <joint name="${name}_joint">
        <!--hardwareInterface>EffortJointInterface</hardwareInterface>
        <hardwareInterface>VelocityJointInterface</hardwareInterface-->
        <hardwareInterface>PositionJointInterface</hardwareInterface>
      </joint>
      <actuator name="${name}_motor">
        <mechanicalReduction>1</mechanicalReduction>
      </actuator>
    </transmission>
  </xacro:macro>

  <xacro:macro name="tilt_gazebo" params="name">
  <gazebo reference="${name}_link">
    <gravity>true</gravity>
    <self_collide>false</self_collide>
  </gazebo>
  </xacro:macro>

</root>

